Workbook
Name CANTIDAD_EQUIPOS: 'CONSOLIDADO VTAS'!$B:$B
Name CLIENTE: 'CONSOLIDADO VTAS'!$C:$C
Name DIAS_VTO: 'CONSOLIDADO VTAS'!$T:$T
Name ESTADO_ENTREGA: 'CONSOLIDADO VTAS'!$G:$G
Name FC_SUCRO: 'CONSOLIDADO VTAS'!$E:$E
Name FECHA_ENTREGA: 'CONSOLIDADO VTAS'!$H:$H
Name FECHA_FC: 'CONSOLIDADO VTAS'!$D:$D
Name FECHA_RETIRO_VALORES: 'CONSOLIDADO VTAS'!$R:$R
Name FECHA_VTO_VALORES: 'CONSOLIDADO VTAS'!$S:$S
Name FORMA_PAGO: 'CONSOLIDADO VTAS'!$V:$V
Name IVA: 'CONSOLIDADO VTAS'!$L:$L
Name KGS: 'CONSOLIDADO VTAS'!$I:$I
Name MES: Tabla1[[#Headers],[MES]]
Name OC: 'CONSOLIDADO VTAS'!$X:$X
Name PENDIENTE_DE_COBRO: 'CONSOLIDADO VTAS'!$O:$O
Name PENDIENTE_DE_ENTREGA: 'CONSOLIDADO VTAS'!$N:$N
Name PLAZO_PAGO_DIAS: 'CONSOLIDADO VTAS'!$U:$U
Name PLAZO_VALORES: 'CONSOLIDADO VTAS'!$AR:$AR
Name PRECIO_POR_KILO: 'CONSOLIDADO VTAS'!$J:$J
Name PRODUCTO: 'CONSOLIDADO VTAS'!$F:$F
Name SEMANA_ACREDITACION_PAGO: 'CONSOLIDADO VTAS'!$W:$W
Name SUBTOTAL: 'CONSOLIDADO VTAS'!$K:$K
Name TASA_FINANCIACION_MENSUAL: 'CONSOLIDADO VTAS'!$AP:$AP
Name TOTAL: 'CONSOLIDADO VTAS'!$M:$M
Name VALORES_COBRADOS: 'CONSOLIDADO VTAS'!$Q:$Q
Name VALORES_EN_CARTERA: 'CONSOLIDADO VTAS'!$P:$P

Sheet KPI´S
A1: ZAFRA 25 KPI´S MES
C3: 46143 | D3: =+C3+31 -> 46174 | E3: =+D3+31 -> 46205 | F3: =+E3+31 -> 46236 | G3: =+F3+31 -> 46267 | H3: =+G3+31 -> 46298 | I3: =+H3+31 -> 46329 | J3: =+I3+31 -> 46360 | K3: =+J3+31 -> 46391 | ... N3: =+M3+31 -> 46484 | O3: TOTAL ACUM.
A5: TOTAL BOLSAS Z25 | B5: (Unidades 50Kg) | C5: =+ACUMULADOS!Z2 -> 70186.92 | D5: =+ACUMULADOS!Z4 -> 104239.6 | E5: =+ACUMULADOS!Z7 -> 70284 | F5: =+ACUMULADOS!Z10 -> 0 | G5: =+ACUMULADOS!Z13 -> 0 | H5: =+ACUMULADOS!Z16 -> 0 | I5: =+ACUMULADOS!Z19 -> 0 | J5: =+ACUMULADOS!Z22 -> 0 | K5: =+ACUMULADOS!Z25 -> 0 | L5: =+ACUMULADOS!Z28 -> 0 | M5: =+ACUMULADOS!Z31 -> 0 | N5: =+ACUMULADOS!Z34 -> 0 | O5: =SUM(C5:N5) -> 244710.52
A7: TOTAL TONELADAS | C7: =+C5*0.05 -> 3509.346 | D7: =+D5*0.05 -> 5211.98 | E7: =+E5*0.05 -> 3514.2 | F7: =+F5*0.05 -> 0 | G7: =+G5*0.05 -> 0 | H7: =+H5*0.05 -> 0 | I7: =+I5*0.05 -> 0 | J7: =+J5*0.05 -> 0 | ... N7: =+N5*0.05 -> 0 | O7: =SUM(C7:N7) -> 12235.526
A9: VENTA BRUTA INDUSTRIA | B9: ($ Millones) | C9: =+ACUMULADOS!M2/1000000 -> 2338.6576 | D9: =+ACUMULADOS!M4/1000000 -> 3022.2142 | E9: =+ACUMULADOS!M7/1000000 -> 2010.7204 | F9: =+ACUMULADOS!M10/1000000 -> 0 | G9: =ACUMULADOS!M13/1000000 -> 0 | H9: =+ACUMULADOS!M16/1000000 -> 0 | I9: =+ACUMULADOS!M19/1000000 -> 0 | J9: =+ACUMULADOS!M22/1000000 -> 0 | K9: =ACUMULADOS!M25/1000000 -> 0 | L9: =+ACUMULADOS!M28/1000000 -> 0 | M9: =+ACUMULADOS!M31/1000000 -> 0 | N9: =ACUMULADOS!M34/1000000 -> 0 | O9: =SUM(C9:N9) -> 7371.5922
B10: ($USD Miles) | C10: =+C9/C54*1000 -> 1656.2731 | D10: =+D9/D54*1000 -> 1989.7297 | E10: =+E9/E54*1000 -> 1300.3874 | F10: =+F9/F54*1000 -> 0 | G10: =+G9/G54*1000 -> 0 | H10: =+H9/H54*1000 -> 0 | I10: =+I9/I54*1000 -> 0 | J10: =+J9/J54*1000 -> 0 | ... N10: =+N9/N54*1000 -> 0 | O10: =SUM(C10:N10) -> 4946.3902
A12: PRECIO FOB CDO TUC BOLSA 50 KG | B12: (Bolsa 50kg) | C12: =+ACUMULADOS!AE3 -> 32106.914 | D12: =+ACUMULADOS!AE5 -> 29204.472 | E12: =+ACUMULADOS!AE8 -> #VALUE! | F12: =+ACUMULADOS!AE11 -> #VALUE! | G12: =+ACUMULADOS!AE14 -> #VALUE! | H12: =+ACUMULADOS!AE17 -> #VALUE! | I12: =+ACUMULADOS!AE20 -> #VALUE! | J12: =+ACUMULADOS!AE23 -> #VALUE! | K12: =+ACUMULADOS!AE26 -> #VALUE! | L12: =+ACUMULADOS!AE29 -> #VALUE! | M12: =+ACUMULADOS!AE32 -> #VALUE! | N12: =+ACUMULADOS!AE35 -> #VALUE! | O12: =AVERAGE(C12:N12) -> #VALUE!
A13: PRECIO FOB CDO TUC KG | B13: ($) IVA INC | C13: =+C12/50 -> 642.13829 | D13: =+D12/50 -> 584.08944 | E13: =+E12/50 -> #VALUE! | F13: =+F12/50 -> #VALUE! | G13: =+G12/50 -> #VALUE! | H13: =+H12/50 -> #VALUE! | I13: =+I12/50 -> #VALUE! | J13: =+J12/50 -> #VALUE! | ... O13: =+O12/50 -> #VALUE!
A14: PRECIO FOB CDO TUC KG | B14: ($USD) IVA INC | C14: =+C13/C54 -> 0.45477216 | D14: =+D13/D54 -> 0.38454591 | E14: =+E13/E54 -> #VALUE! | F14: =+F13/F54 -> #VALUE! | G14: =+G13/G54 -> #VALUE! | H14: =+H13/H54 -> #VALUE! | I14: =+I13/I54 -> #VALUE! | J14: =+J13/J54 -> #VALUE! | ... O14: =+O13/O54 -> #VALUE!
A16: PRECIO CACTU COMPARABLE | C16: =+ACUMULADOS!AJ3 -> 34174.432 | D16: =+ACUMULADOS!AJ5 -> 33811.815 | E16: =+ACUMULADOS!AJ8 -> 33759.479 | F16: =+ACUMULADOS!AJ11 -> #DIV/0! | G16: =+ACUMULADOS!AJ14 -> #DIV/0! | H16: =+ACUMULADOS!AJ17 -> #DIV/0! | I16: =+ACUMULADOS!AJ20 -> #DIV/0! | J16: =+ACUMULADOS!AJ23 -> #DIV/0! | K16: =+ACUMULADOS!AJ26 -> #DIV/0! | L16: =+ACUMULADOS!AJ29 -> #DIV/0! | M16: =+ACUMULADOS!AJ32 -> #DIV/0! | N16: =+ACUMULADOS!AJ35 -> #DIV/0! | O16: =AVERAGE(C16:N16) -> #DIV/0!
A17: GAP VS. CACTU | B17: % | C17: =+ACUMULADOS!AO3 -> -0.06634543 | D17: =+ACUMULADOS!AO5 -> -0.13797056 | E17: =+ACUMULADOS!AO8 -> #VALUE! | F17: =+ACUMULADOS!AO11 -> #VALUE! | G17: =+ACUMULADOS!AO14 -> #VALUE! | H17: =+ACUMULADOS!AO17 -> #VALUE! | I17: =+ACUMULADOS!AO20 -> #VALUE! | J17: =+ACUMULADOS!AO23 -> #VALUE! | K17: =+ACUMULADOS!AO26 -> #VALUE! | L17: =+ACUMULADOS!AO29 -> #VALUE! | M17: =+ACUMULADOS!AO32 -> #VALUE! | N17: =+ACUMULADOS!AO35 -> #VALUE! | O17: =AVERAGE(C17:N17) -> #VALUE!
A18: MARGEN IND VS CACTU | B18: ($ Millones) | C18: =+C17*C9 -> -155.15925 | D18: =+D17*D9 -> -416.97659 | E18: =+E17*E9 -> #VALUE! | F18: =+F17*F9 -> #VALUE! | G18: =+G17*G9 -> #VALUE! | H18: =+H17*H9 -> #VALUE! | I18: =+I17*I9 -> #VALUE! | J18: =+J17*J9 -> #VALUE! | ... N18: =+N17*N9 -> #VALUE! | O18: =SUM(C18:N18) -> #VALUE!
A20: PRECIO VENTA PROMEDIO
A21: KG A PLAZO EN CLIENTE | B21: ($) IVA INC | C21: =+C9*1000000/(C5*50) -> 666.40839 | D21: =+D9*1000000/(D5*50) -> 579.85913 | E21: =+E9*1000000/(E5*50) -> 572.17017 | F21: =+F9*1000000/(F5*50) -> #DIV/0! | G21: =+G9*1000000/(G5*50) -> #DIV/0! | H21: =+H9*1000000/(H5*50) -> #DIV/0! | I21: =+I9*1000000/(I5*50) -> #DIV/0! | J21: =+J9*1000000/(J5*50) -> #DIV/0! | ... N21: =+N9*1000000/(N5*50) -> #DIV/0! | O21: =+(O9*1000000)/(O7*1000) -> 602.47448
A22: PRECIO POR KG A PLAZO EN CLIENTE | B22: ($) SIN IVA | C22: =+C21/(1+C63) -> 586.62711 | D22: =+D21/(1+D63) -> 495.5468 | E22: =+E21/(1+E63) -> 521.57718 | F22: =+F21/(1+F63) -> #DIV/0! | G22: =+G21/(1+G63) -> #DIV/0! | H22: =+H21/(1+H63) -> #DIV/0! | I22: =+I21/(1+I63) -> #DIV/0! | J22: =+J21/(1+J63) -> #DIV/0! | ... N22: =+N21/(1+N63) -> #DIV/0! | O22: =+((O9*1000000)/(1+'CONSOLIDADO VTAS'!L881))/(KPI´S!O7*1000) -> 505.33715
A23: PRECIO POR TN A PLAZO EN CLIENTE | B23: (USD) SIN IVA | C23: =+C22/C54*1000 -> 415.45829 | D23: =+D22/D54*1000 -> 326.25225 | E23: =+E22/E54*1000 -> 337.3181 | F23: =+F22/F54*1000 -> #DIV/0! | G23: =+G22/G54*1000 -> #DIV/0! | H23: =+H22/H54*1000 -> #DIV/0! | I23: =+I22/I54*1000 -> #DIV/0! | J23: =+J22/J54*1000 -> #DIV/0! | ... N23: =+N22/N54*1000 -> #DIV/0! | O23: =+O10*1000/(1+'CONSOLIDADO VTAS'!L881)/KPI´S!O7 -> 339.08478
A24: PRECIO VENTA BRUTO BOLSA 50KG | B24: ($) IVA INC | C24: =+C9*1000000/C5 -> 33320.42 | D24: =+D9*1000000/D5 -> 28992.956 | E24: =+E9*1000000/E5 -> 28608.508 | F24: =+F9*1000000/F5 -> #DIV/0! | G24: =+G9*1000000/G5 -> #DIV/0! | H24: =+H9*1000000/H5 -> #DIV/0! | I24: =+I9*1000000/I5 -> #DIV/0! | J24: =+J9*1000000/J5 -> #DIV/0! | ... O24: =+O9*1000000/O5 -> 30123.724
A26: PRECIO BUE 30D
A27: PRECIO FOB BUE A PLAZO | B27: Bolsa 50 KG | C27: =+(C12-C57)*(1+C63) -> 33065.455 | D27: =+(D12-D57)*(1+D63) -> 30662.901 | E27: =+(E12-E57)*(1+E63) -> #VALUE! | F27: =+(F12-F57)*(1+F63) -> #VALUE! | G27: =+(G12-G57)*(1+G63) -> #VALUE! | H27: =+(H12-H57)*(1+H63) -> #VALUE! | I27: =+(I12-I57)*(1+I63) -> #VALUE! | J27: =+(J12-J57)*(1+J63) -> #VALUE! | ... N27: =+(N12-N57)*(1+N63) -> #VALUE!
A28: FINANCIACION A 30D | B28: Bolsa 50 KG | C28: =+C56*C12 -> 923.62357 | D28: =+D56*D12 -> 840.12864 | E28: =+E56*E12 -> #VALUE! | F28: =+F56*F12 -> #VALUE! | G28: =+G56*G12 -> #VALUE! | H28: =+H56*H12 -> #VALUE! | I28: =+I56*I12 -> #VALUE! | J28: =+J56*J12 -> #VALUE! | ... N28: =+N56*N12 -> #VALUE!
A29: PRECIO FOB BUE 30D | B29: Bolsa 50 KG | C29: =SUM(C27:C28) -> 33989.078 | D29: =SUM(D27:D28) -> 31503.029 | E29: =SUM(E27:E28) -> #VALUE! | F29: =SUM(F27:F28) -> #VALUE! | G29: =SUM(G27:G28) -> #VALUE! | H29: =SUM(H27:H28) -> #VALUE! | I29: =SUM(I27:I28) -> #VALUE! | J29: =SUM(J27:J28) -> #VALUE! | ... N29: =SUM(N27:N28) -> #VALUE! | O29: =AVERAGE(C29:I29) -> #VALUE!
A30: PRECIO FOB BUE 30D KG | B30: ($) IVA INC | C30: =+C29/50 -> 679.78157 | D30: =+D29/50 -> 630.06059 | E30: =+E29/50 -> #VALUE! | F30: =+F29/50 -> #VALUE! | G30: =+G29/50 -> #VALUE! | H30: =+H29/50 -> #VALUE! | I30: =+I29/50 -> #VALUE! | J30: =+J29/50 -> #VALUE! | ... N30: =+N29/50 -> #VALUE! | O30: =AVERAGE(C30:I30) -> #VALUE!
A31: LA CORONA FOB BUE 30D KG | B31: ($) SIN IVA | C31: =+C22+(C64/50)-(C57/50) -> 491.44711 | D31: =+D22+(D64/50)-(D57/50) -> 407.4468 | E31: =+E22+(E64/50)-(E57/50) -> 439.57718 | F31: =+F22+(F64/50)-(F57/50) -> #DIV/0! | G31: =+G22+(G64/50)-(G57/50) -> #DIV/0! | H31: =+H22+(H64/50)-(H57/50) -> #DIV/0! | I31: =+I22+(I64/50)-(I57/50) -> #DIV/0! | J31: =+J22+(J64/50)-(J57/50) -> #DIV/0! | ... N31: =+N22+(N64/50)-(N57/50) -> #DIV/0! | O31: =AVERAGE(C31:N31) -> #DIV/0!
A32: PRECIO LEDESMA COMPARABLE | B32: ($) SIN IVA | C32: =+'RESUMEN AVANCE MES'!D9 -> 850 | D32: =+'RESUMEN AVANCE MES'!D20 -> 900 | E32: =+'RESUMEN AVANCE MES'!D31 -> 900 | F32: =+'RESUMEN AVANCE MES'!D42 -> 0 | G32: =+'RESUMEN AVANCE MES'!D53 -> 0 | H32: =+'RESUMEN AVANCE MES'!D64 -> 0 | I32: =+'RESUMEN AVANCE MES'!D75 -> 0 | J32: =+'RESUMEN AVANCE MES'!D86 -> 0 | K32: =+'RESUMEN AVANCE MES'!D97 -> 0 | L32: =+'RESUMEN AVANCE MES'!D108 -> 0 | M32: =+'RESUMEN AVANCE MES'!D119 -> 0 | N32: 870 | O32: =AVERAGE(C32:N32) -> 293.33333
A33: GAP VS. LEDESMA | C33: =+C31/C32-1 -> -0.42182693 | D33: =+D31/D32-1 -> -0.54728134 | E33: =+E31/E32-1 -> -0.51158091 | F33: =+F31/F32-1 -> #DIV/0! | G33: =+G31/G32-1 -> #DIV/0! | H33: =+H31/H32-1 -> #DIV/0! | I33: =+I31/I32-1 -> #DIV/0! | J33: =+J31/J32-1 -> #DIV/0! | ... O33: =+O31/O32-1 -> #DIV/0!
A35: COMPARACION Z25 - Z24
A36: VARIACIÓN VOLUMEN BOLSAS TOTAL | B36: (%) | C36: =C5/'COMPARATIVO ANUAL'!I10-1 -> #DIV/0! | D36: =D5/'COMPARATIVO ANUAL'!I11-1 -> #DIV/0! | E36: =E5/'COMPARATIVO ANUAL'!I12-1 -> #DIV/0! | F36: =F5/'COMPARATIVO ANUAL'!I13-1 -> #DIV/0! | G36: =G5/'COMPARATIVO ANUAL'!I14-1 -> #DIV/0! | H36: =H5/'COMPARATIVO ANUAL'!I15-1 -> #DIV/0! | I36: =I5/'COMPARATIVO ANUAL'!I16-1 -> #DIV/0! | J36: =J5/'COMPARATIVO ANUAL'!I17-1 -> #DIV/0! | K36: =K5/'COMPARATIVO ANUAL'!I18-1 -> #DIV/0! | L36: =L5/'COMPARATIVO ANUAL'!I19-1 -> #DIV/0! | M36: =M5/'COMPARATIVO ANUAL'!I20-1 -> #DIV/0! | N36: =N5/'COMPARATIVO ANUAL'!I21-1 -> #DIV/0! | O36: =+O5/O37-1 -> #DIV/0!
A37: Total BOLSAS Z24 | B37: unidades | C37: =+'COMPARATIVO ANUAL'!I10 -> 0 | D37: =+'COMPARATIVO ANUAL'!I11 -> 0 | E37: =+'COMPARATIVO ANUAL'!I12 -> 0 | F37: =+'COMPARATIVO ANUAL'!I13 -> 0 | G37: =+'COMPARATIVO ANUAL'!I14 -> 0 | H37: =+'COMPARATIVO ANUAL'!I15 -> 0 | I37: =+'COMPARATIVO ANUAL'!I16 -> 0 | J37: =+'COMPARATIVO ANUAL'!I17 -> 0 | K37: =+'COMPARATIVO ANUAL'!I18 -> 0 | L37: =+'COMPARATIVO ANUAL'!I19 -> 0 | M37: =+'COMPARATIVO ANUAL'!I20 -> 0 | N37: =+'COMPARATIVO ANUAL'!I21 -> 0 | O37: =SUM(C37:N37) -> 0
A38: VARIACION PRECIO POR KG SIN IVA
A39: Variacion % en $ | B39: % ($) | C39: =+C22/C42-1 -> 0.29011874 | D39: =+D22/D42-1 -> -0.0064829735 | E39: =+E22/E42-1 -> 0.052449725 | F39: =+F22/F42-1 -> #DIV/0! | G39: =+G22/G42-1 -> #DIV/0! | H39: =+H22/H42-1 -> #DIV/0! | I39: =+I22/I42-1 -> #DIV/0! | J39: =+J22/J42-1 -> #DIV/0! | ... N39: =+N22/N42-1 -> #DIV/0! | O39: =AVERAGE(C39:N39) -> #DIV/0!
A40: Variacion % en USD | B40: % (USD) | C40: =+((C22/C54)/(C42/C61))-1 -> 0.048476576 | D40: =+((D22/D54)/(D42/D61))-1 -> -0.22727548 | E40: =+((E22/E54)/(E42/E61))-1 -> -0.13760382 | F40: =+((F22/F54)/(F42/F61))-1 -> #DIV/0! | G40: =+((G22/G54)/(G42/G61))-1 -> #DIV/0! | H40: =+((H22/H54)/(H42/H61))-1 -> #DIV/0! | I40: =+((I22/I54)/(I42/I61))-1 -> #DIV/0! | J40: =+((J22/J54)/(J42/J61))-1 -> #DIV/0! | ... O40: =+((O22/O54)/(O42/O61))-1 -> -0.22204767
A42: Precio x KG Z24 | B42: ($) SIN IVA | C42: =+'COMPARATIVO ANUAL'!F10 -> 454.70784 | D42: =+'COMPARATIVO ANUAL'!F11 -> 498.78038 | E42: =+'COMPARATIVO ANUAL'!F12 -> 495.58394 | F42: =+'COMPARATIVO ANUAL'!F13 -> 443.34077 | G42: =+'COMPARATIVO ANUAL'!F14 -> 421.68591 | H42: =+'COMPARATIVO ANUAL'!F15 -> 453.84908 | I42: =+'COMPARATIVO ANUAL'!F16 -> 482.29339 | J42: =+'COMPARATIVO ANUAL'!F17 -> 518.40928 | K42: =+'COMPARATIVO ANUAL'!F18 -> 617.7272 | L42: =+'COMPARATIVO ANUAL'!F19 -> 642.76507 | M42: =+'COMPARATIVO ANUAL'!F20 -> 670.58014 | N42: =+'COMPARATIVO ANUAL'!F21 -> 684.09182 | O42: =AVERAGE(C42:N42) -> 531.98457
A43: Precio x TN Z24 | B43: (USD) SIN IVA | C43: =+C42/C61*1000 -> 396.24947 | D43: =+D42/D61*1000 -> 422.2103 | E43: =+E42/E61*1000 -> 391.14054 | F43: =+F42/F61*1000 -> 333.45488 | G43: =+G42/G61*1000 -> 301.22623 | H43: =+H42/H61*1000 -> 316.92869 | I43: =+I42/I61*1000 -> 337.97715 | J43: =+J42/J61*1000 -> 358.05759 | ... O43: =+O42/O61*1000 -> 392.39169
A44: VARIACIÓN PRECIO FOB CONTADO TUC X BOLSA
B45: % ($) | C45: =+C12/C47-1 -> #DIV/0! | D45: =+D12/D47-1 -> #DIV/0! | E45: =+E12/E47-1 -> #VALUE! | F45: =+F12/F47-1 -> #VALUE! | G45: =+G12/G47-1 -> #VALUE! | H45: =+H12/H47-1 -> #VALUE! | I45: =+I12/I47-1 -> #VALUE! | J45: =+J12/J47-1 -> #VALUE! | ... N45: =+N12/N47-1 -> #VALUE! | O45: =AVERAGE(C45:N45) -> #DIV/0!
B46: % (USD) | C46: =+(C12/C54)/(C47/C61)-1 -> #DIV/0! | D46: =+(D12/D54)/(D47/D61)-1 -> #DIV/0! | E46: =+(E12/E54)/(E47/E61)-1 -> #VALUE! | F46: =+(F12/F54)/(F47/F61)-1 -> #VALUE! | G46: =+(G12/G54)/(G47/G61)-1 -> #VALUE! | H46: =+(H12/H54)/(H47/H61)-1 -> #VALUE! | I46: =+(I12/I54)/(I47/I61)-1 -> #VALUE! | J46: =+(J12/J54)/(J47/J61)-1 -> #VALUE! | ... O46: =+(O12/O54)/(O47/O61)-1 -> #VALUE!
A47: Precio FOB CONTADO Z24 | B47: Bolsa 50 KG | C47: =+'COMPARATIVO ANUAL'!L10 -> 0 | D47: =+'COMPARATIVO ANUAL'!L11 -> 0 | E47: =+'COMPARATIVO ANUAL'!L12 -> 0 | F47: =+'COMPARATIVO ANUAL'!L13 -> 0 | G47: =+'COMPARATIVO ANUAL'!L14 -> 0 | H47: =+'COMPARATIVO ANUAL'!L15 -> 0 | I47: =+'COMPARATIVO ANUAL'!L16 -> 0 | J47: =+'COMPARATIVO ANUAL'!I17 -> 0 | K47: =+'COMPARATIVO ANUAL'!L18 -> 0 | L47: =+'COMPARATIVO ANUAL'!L19 -> 0 | M47: =+'COMPARATIVO ANUAL'!L20 -> 0 | N47: =+'COMPARATIVO ANUAL'!L21 -> 0 | O47: =AVERAGE(C47:N47) -> 0
A53: REFERENCIAS | C53: 46143 | D53: =+C53+31 -> 46174 | E53: =+D53+31 -> 46205 | F53: =+E53+31 -> 46236 | G53: =+F53+31 -> 46267 | H53: =+G53+31 -> 46298 | I53: =+H53+31 -> 46329 | J53: =+I53+31 -> 46360 | K53: =+J53+31 -> 46391 | ... N53: =+M53+31 -> 46484 | O53: Promedio
A54: TIPO DE CAMBIO USD | B54: BNA of compra | C54: 1412 | D54: 1518.9069 | E54: 1546.2472 | F54: 1574.0797 | G54: 1602.4131 | H54: 1631.2565 | I54: 1660.6192 | J54: 1685.5284 | K54: 1790 | L54: 1799 | M54: 1810 | N54: 1835 | O54: =AVERAGE(C54:N54) -> 1655.4209
A55: TASA FINANC ANUAL | B55: % | C55: 0.35 | D55: 0.35 | E55: 0.35 | F55: 0.35 | G55: 0.35 | H55: 0.35 | I55: 0.35 | J55: 0.35 | K55: 0.35 | L55: 0.35 | M55: 0.35 | N55: 0.35
...

Sheet RESUMEN AVANCE MES
B1: RESUMEN AVANCE ZAFRA 2026 POR MES
B3: MAYO
B4: BOLSAS | C4: =+ACUMULADOS!Z2 -> 70186.92 | D4: 50000 | E4: OBJETIVO MES
B5: PESOS $ | C5: =+ACUMULADOS!M2 -> 2.3386576e+09
B6: PRECIO FOB CDO | C6: =+ACUMULADOS!AE3 -> 32106.914 | D6: =+ACUMULADOS!AJ3 -> 34174.432 | E6: CACTU COMPARABLE
B7: GAP VS. CACTU | C7: =+ACUMULADOS!AL3 -> -0.060498957
B8: GAP VS LEDESMA BUE30DFF | C8: =+(((C6/1.21/50)+(2700/50/1.21)+(C6*0.048/50/1.21))/D9)-1 -> -0.29318335
B9: PRECIO PROMEDIO KG (SIN IVA) | C9: =+ACUMULADOS!J3 -> 579.27325 | D9: =+'COMPARATIVO PCIOS REFERENCIA'!F8 -> 850 | E9: LEDESMA COMPARABLE
B10: PRECIO PROMEDIO TN USD (SIN IVA) | C10: =+C9/C12*1000 -> 410.25018
B11: VARIACION PRECIO KG ZAFRA 26 VS 25 | C11: =+C9/D11-1 -> 0.27394603 | D11: =+'COMPARATIVO ANUAL'!F10 -> 454.70784 | E11: PRECIO MAY 25
B12: TIPO DE CAMBIO PROMEDIO | C12: =+KPI´S!C54 -> 1412
B14: JUNIO
B15: BOLSAS | C15: =+ACUMULADOS!Z4 -> 104239.6 | D15: 60000 | E15: OBJETIVO MES
B16: PESOS $ | C16: =+ACUMULADOS!M4 -> 3.0222142e+09
B17: PRECIO FOB CDO | C17: =+ACUMULADOS!AE5 -> 29204.472 | D17: =+ACUMULADOS!AJ5 -> 33811.815 | E17: CACTU COMPARABLE
B18: GAP VS. CACTU | C18: =+ACUMULADOS!AL5 -> -0.1362643
B19: GAP VS LEDESMA BUE30DFF | C19: =+(((C17/1.21/50)+(2700/50/1.21)+(C17*0.048/50/1.21))/D20)-1 -> -0.3883143
B20: PRECIO PROMEDIO KG (SIN IVA) | C20: =+ACUMULADOS!J5 -> 483.75911 | D20: =+'COMPARATIVO PCIOS REFERENCIA'!F9 -> 900 | E20: LEDESMA COMPARABLE
B21: PRECIO PROMEDIO TN USD (SIN IVA) | C21: =+C20/C23*1000 -> 318.49161
B22: VARIACION PRECIO KG ZAFRA 26 VS 25 | C22: =+C20/D22-1 -> -0.030116002 | D22: =+'COMPARATIVO ANUAL'!F11 -> 498.78038 | E22: PRECIO JUN 25
B23: TIPO DE CAMBIO PROMEDIO | C23: =+KPI´S!D54 -> 1518.9069
B25: JULIO
B26: BOLSAS | C26: =+ACUMULADOS!Z7 -> 70284 | D26: 60000 | E26: OBJETIVO MES
B27: PESOS $ | C27: =+ACUMULADOS!M7 -> 2.0107204e+09
B28: PRECIO FOB CDO | C28: =+ACUMULADOS!AE8 -> #VALUE! | D28: =+ACUMULADOS!AJ8 -> 33759.479 | E28: CACTU COMPARABLE
B29: GAP VS. CACTU | C29: =+ACUMULADOS!AO8 -> #VALUE!
B30: GAP VS LEDESMA BUE30DFF | C30: =+(((C28/1.21/50)+(+(2525*1.21)/50/1.21)+(C28*0.048/50/1.21))/D31)-1 -> #VALUE!
B31: PRECIO PROMEDIO KG (SIN IVA) | C31: =+ACUMULADOS!J8 -> 472.89726 | D31: =+'COMPARATIVO PCIOS REFERENCIA'!F10 -> 900 | E31: LEDESMA COMPARABLE
B32: PRECIO PROMEDIO TN USD (SIN IVA) | C32: =+C31/C34*1000 -> 305.83548
B33: VARIACION PRECIO KG ZAFRA 26 VS 25 | C33: =+C31/D33-1 -> -0.045777672 | D33: =+'COMPARATIVO ANUAL'!F12 -> 495.58394 | E33: PRECIO JUL 25
B34: TIPO DE CAMBIO PROMEDIO | C34: =+KPI´S!E54 -> 1546.2472
B36: AGOSTO
B37: BOLSAS | C37: =+ACUMULADOS!Z10 -> 0 | D37: 50000 | E37: OBJETIVO MES
B38: PESOS $ | C38: =+ACUMULADOS!M10 -> 0
B39: PRECIO FOB CDO | C39: =+ACUMULADOS!AE8 -> #VALUE! | D39: =+ACUMULADOS!AJ11 -> #DIV/0! | E39: CACTU COMPARABLE
B40: GAP VS. CACTU | C40: =+ACUMULADOS!AL11 -> #DIV/0!
B41: GAP VS LEDESMA BUE30DFF | C41: =+(((C39/1.21/50)+((2525*1.21)/50/1.21)+(C39*0.048/50/1.21))/D42)-1 -> #VALUE!
B42: PRECIO PROMEDIO KG (SIN IVA) | C42: =+ACUMULADOS!J11 -> #DIV/0! | D42: =+'COMPARATIVO PCIOS REFERENCIA'!F11 -> 0 | E42: LEDESMA COMPARABLE
B43: PRECIO PROMEDIO TN USD (SIN IVA) | C43: =+C42/C45*1000 -> #DIV/0!
B44: VARIACION PRECIO KG ZAFRA 26 VS 25 | C44: =+C42/D44-1 -> #DIV/0! | D44: =+'COMPARATIVO ANUAL'!F13 -> 443.34077 | E44: PRECIO AGO 25
...

Sheet CONSOLIDADO VTAS
U2: =TODAY() -> 46181
A3: MES | B3: CANTIDAD EQUIPOS | C3: CLIENTE | D3: FECHA FC | E3: FC SUCRO | F3: PRODUCTO | G3: ESTADO ENTREGA | H3: FECHA Entrega | I3: KGS | J3: PRECIO $/ KG A PLAZO EN CLIENTE ( SIN IVA) | K3: SUBTOTAL | L3: IVA | M3: VENTA TOTAL $ (IVA INC) | N3: PENDIENTE DE ENTREGA | O3: PENDIENTE DE COBRO | P3: VALORES EN CARTERA | Q3: VALORES COBRADOS | R3: FECHA RETIRO VALORES | S3: FECHA VTO VALORES | T3: Dias Vto | U3: PLAZO ENTREGA VALORES | V3: Banco | W3: SEMANA ACREDITACION PAGO | X3: OC | Y3: FECHA OC | Z3: Q Bolsas Equivalentes 50kg | AA3: PRECIO $ BOLSA 50 KG (IVA INC) | AB3: COSTO FLETE $ BOLSA 50 KG (IVA INC) | AC3: PRECIO $ BOLSA50 KG FOB TUCUMAN A PLAZO (IVA INC) | AD3: GASTOS FINANCIEROS $ BOLSA 50 KG (IVA INC) | AE3: PRECIO $ BOLSA 50KG FOB CDO TUC (IVA INC) | AF3: ENVASE | AG3: LOCALIDAD | AH3: PAIS / PROVINCIA | AI3: TIPO OPERACIÓN | AJ3: PRECIO REF $ BOLSA 50 KG CACTU (IVA INC) | AK3: DIF $ PRECIO NETO INDUSTRIA vs Neto TUCUMAN (IVA INC) | AL3: DIF % PRECIO NETO INDUSTRIA vs Neto TUCUMAN (IVA INC) | AM3: TOTAL GANANCIA $ POR OPERACIÓN VS. CACTU (IVA INC) | AN3: VENTA EQUIVALENTE $ CACTU (IVA INC) | AO3: VENTA EQU $ LA CORONA FOB TUC (IVA INC) | AP3: TASA FINANCIACION MENSUAL | AQ3: COSTO FLETE $ POR BOLSA 5O KG (SIN IVA) | AR3: PLAZO PAGO (DIAS) | AS3: REMITO | AT3: CONTROL | AU3: TIPO DE CAMBIO | AV3: VENTA TOTAL USD A PLAZO EN CLIENTE (SIN IVA) | AW3: % IVA | AX3: VENTA TOTAL USD A PLAZO EN CLIENTE (IVA INC) | AY3: PRECIO POR TN USD EN CLIENTE A PLAZO (SIN IVA) | AZ3: COSTO USD FLETE /TN (SIN IVA) | BA3: COSTO FINANCIERO USD POR BOLSA 50KG (IVA INC) | BB3: PRECIO USD TON FOB CORONA | BC3: TIER | BD3: COMENTARIOS2
A4: 46143 | B4: 1 | C4: LEDESMA SAAI | D4: =+Tabla1[[#This Row],[FECHA Entrega]] -> 46168.793 | E4: 700000869 | F4: AZÚCAR CRUDO | G4: ENTREGADO | H4: 46168.793 | I4: =564*50 -> 28200 | J4: =0.315*Tabla1[[#This Row],[TIPO DE CAMBIO]] -> 455.58481 | K4: =+J4*I4 -> 12847492 | L4: =IF(Tabla1[[#This Row],[TIPO OPERACIÓN]]="INDUSTRIA",Tabla1[[#This Row],[SUBTOTAL]]*0.21,IF(Tabla1[[#This Row],[TIPO OPERACIÓN]]="GDES CUENTAS",Tabla1[[#This Row],[SUBTOTAL]]*0.21,IF(Tabla1[[#This Row],[TIPO OPERACIÓN]]="TUC CTADO 2","",IF(Tabla1[[#This Row],[TIPO OPERACIÓN]]="EXPO CHILE","",IF(Tabla1[[#This Row],[TIPO OPERACIÓN]]="TUC CTADO 1",Tabla1[[#This Row],[SUBTOTAL]]*0.21,""))))) -> 2697973.3 | M4: =SUM(K4:L4) -> 15545465 | O4: 0 | P4: 0 | Q4: =+Tabla1[[#This Row],[VENTA TOTAL $ (IVA INC) ]]-Tabla1[[#This Row],[PENDIENTE DE COBRO]] -> 15545465 | R4: =+Tabla1[[#This Row],[FECHA FC]]+Tabla1[[#This Row],[PLAZO ENTREGA VALORES]] -> 46051 | S4: =+Tabla1[[#This Row],[FECHA FC]]+Tabla1[[#This Row],[PLAZO PAGO (DIAS)]] -> 46168.793 | T4: =+S4-$U$2 -> -12.206944 | U4: =+Tabla1[[#This Row],[FECHA OC]]-Tabla1[[#This Row],[FECHA Entrega]] -> -117.79306 | W4: =+Tabla1[[#This Row],[FECHA VTO VALORES]]+7 -> 46175.793 | Y4: 46051 | Z4: =Tabla1[[#This Row],[KGS]]/50 -> 564 | AA4: =IFERROR((IF(Tabla1[[#This Row],[TIPO OPERACIÓN]]="INDUSTRIA",Tabla1[[#This Row],[PRECIO $/ KG A PLAZO EN CLIENTE ( SIN IVA)]]*50*1.21,IF(Tabla1[[#This Row],[TIPO OPERACIÓN]]="TUC CTADO 2",Tabla1[[#This Row],[PRECIO $/ KG A PLAZO EN CLIENTE ( SIN IVA)]]*50,IF(Tabla1[[#This Row],[TIPO OPERACIÓN]]="EXPO CHILE",Tabla1[[#This Row],[PRECIO $/ KG A PLAZO EN CLIENTE ( SIN IVA)]]*50*1,IF(Tabla1[[#This Row],[TIPO OPERACIÓN]]="GDES CUENTAS",Tabla1[[#This Row],[PRECIO $/ KG A PLAZO EN CLIENTE ( SIN IVA)]]*50*1.21,IF(Tabla1[[#This Row],[TIPO OPERACIÓN]]="TUC CTADO 1",Tabla1[[#This Row],[PRECIO $/ KG A PLAZO EN CLIENTE ( SIN IVA)]]*50*1.21,"")))))),"") -> 27562.881 | AB4: =-Tabla1[[#This Row],[COSTO FLETE $ POR BOLSA 5O KG (SIN IVA)]]*1.21-Tabla1[[#This Row],[PRECIO $/ KG A PLAZO EN CLIENTE ( SIN IVA)]]*0.003*1.21*50 -> -0.40864392 | AC4: =SUM(Tabla1[[#This Row],[PRECIO $ BOLSA 50 KG (IVA INC) ]]+Tabla1[[#This Row],[COSTO FLETE $ BOLSA 50 KG (IVA INC)]]) -> 27562.473 | AD4: =-Tabla1[[#This Row],[PRECIO $ BOLSA 50 KG (IVA INC) ]]*(Tabla1[[#This Row],[TASA FINANCIACION MENSUAL]]/365)*Tabla1[[#This Row],[PLAZO ENTREGA VALORES]] -> 257.95826 | AE4: =SUM(Tabla1[[#This Row],[PRECIO $ BOLSA50 KG FOB TUCUMAN A PLAZO (IVA INC)]]+Tabla1[[#This Row],[GASTOS FINANCIEROS $ BOLSA 50 KG (IVA INC)]]) -> 27820.431 | AF4: GRANEL | AG4: RETIRA DE INGENIO | AH4: TUCUMAN | AI4: GDES CUENTAS | AJ4: =IFERROR(IF(Tabla1[[#This Row],[TIPO OPERACIÓN]]="INDUSTRIA",VLOOKUP(Tabla1[[#This Row],[FECHA OC]],'PRECIO CACTU'!A:B,2,FALSE),IF(Tabla1[[#This Row],[TIPO OPERACIÓN]]="GDES CUENTAS",VLOOKUP(Tabla1[[#This Row],[FECHA OC]],'PRECIO CACTU'!A:B,2,FALSE),IF(Tabla1[[#This Row],[TIPO OPERACIÓN]]="EXPO CHILE",VLOOKUP(Tabla1[[#This Row],[FECHA OC]],'PRECIO CACTU'!A:B,2,FALSE)/1.21,IF(Tabla1[[#This Row],[TIPO OPERACIÓN]]="TUC CTADO 2",VLOOKUP(Tabla1[[#This Row],[FECHA OC]],'PRECIO CACTU'!A:B,2,FALSE)/1.21,IF(Tabla1[[#This Row],[TIPO OPERACIÓN]]="TUC CTADO 1",VLOOKUP(Tabla1[[#This Row],[FECHA OC]],'PRECIO CACTU'!A:B,2,FALSE),""))))),"") -> 32515 | AK4: =SUM(Tabla1[[#This Row],[PRECIO $ BOLSA 50KG FOB CDO TUC (IVA INC)]]-Tabla1[[#This Row],[PRECIO REF $ BOLSA 50 KG CACTU (IVA INC)]]) -> -4694.5691 | AL4: =IFERROR(Tabla1[[#This Row],[PRECIO $ BOLSA 50KG FOB CDO TUC (IVA INC)]]/Tabla1[[#This Row],[PRECIO REF $ BOLSA 50 KG CACTU (IVA INC)]]-1,"") -> -0.14438164 | AM4: =+Tabla1[[#This Row],[DIF $ PRECIO NETO INDUSTRIA vs Neto TUCUMAN (IVA INC)]]*Tabla1[[#This Row],[Q Bolsas Equivalentes 50kg]] -> -2647737 | AN4: =Tabla1[[#This Row],[PRECIO REF $ BOLSA 50 KG CACTU (IVA INC)]]*Tabla1[[#This Row],[Q Bolsas Equivalentes 50kg]] -> 18338460 | AO4: =+Tabla1[[#This Row],[PRECIO $ BOLSA 50KG FOB CDO TUC (IVA INC)]]*Tabla1[[#This Row],[Q Bolsas Equivalentes 50kg]] -> 15690723 | AP4: 0.029 | AQ4: -68 | AT4: =+Tabla1[[#This Row],[VENTA TOTAL $ (IVA INC) ]]-(SUM(Tabla1[[#This Row],[PENDIENTE DE ENTREGA]:[VALORES COBRADOS]])) -> 0 | AU4: =VLOOKUP(Tabla1[[#This Row],[FECHA OC]],'TIPO DE CAMBIO'!A:B,2,TRUE) -> 1446.301 | AV4: =+Tabla1[[#This Row],[SUBTOTAL]]/Tabla1[[#This Row],[TIPO DE CAMBIO]] -> 8883 | AX4: =IFERROR(Tabla1[[#This Row],[VENTA TOTAL USD A PLAZO EN CLIENTE (SIN IVA)]]*(1+Tabla1[[#This Row],[% IVA ]]),"") -> 8883 | AY4: =+Tabla1[[#This Row],[VENTA TOTAL USD A PLAZO EN CLIENTE (SIN IVA)]]/Tabla1[[#This Row],[KGS]]*1000 -> 315 | AZ4: 0 | BA4: =+Tabla1[[#This Row],[GASTOS FINANCIEROS $ BOLSA 50 KG (IVA INC)]]*20/Tabla1[[#This Row],[TIPO DE CAMBIO]] -> 3.5671449 | BB4: =+Tabla1[[#This Row],[PRECIO POR TN USD EN CLIENTE A PLAZO (SIN IVA)]]+Tabla1[[#This Row],[COSTO USD FLETE /TN (SIN IVA)]]+Tabla1[[#This Row],[COSTO FINANCIERO USD POR BOLSA 50KG (IVA INC)]] -> 318.56714 | BC4: 5
A5: 46143 | B5: 1 | C5: LEDESMA SAAI | D5: =+Tabla1[[#This Row],[FECHA Entrega]] -> 46168.938 | E5: 700000869 | F5: AZÚCAR CRUDO | G5: ENTREGADO | H5: 46168.938 | I5: =600*50 -> 30000 | J5: =0.315*Tabla1[[#This Row],[TIPO DE CAMBIO]] -> 455.58481 | K5: =+J5*I5 -> 13667544 | L5: =IF(Tabla1[[#This Row],[TIPO OPERACIÓN]]="INDUSTRIA",Tabla1[[#This Row],[SUBTOTAL]]*0.21,IF(Tabla1[[#This Row],[TIPO OPERACIÓN]]="GDES CUENTAS",Tabla1[[#This Row],[SUBTOTAL]]*0.21,IF(Tabla1[[#This Row],[TIPO OPERACIÓN]]="TUC CTADO 2","",IF(Tabla1[[#This Row],[TIPO OPERACIÓN]]="EXPO CHILE","",IF(Tabla1[[#This Row],[TIPO OPERACIÓN]]="TUC CTADO 1",Tabla1[[#This Row],[SUBTOTAL]]*0.21,""))))) -> 2870184.3 | M5: =SUM(K5:L5) -> 16537729 | O5: 0 | P5: 0 | Q5: =+Tabla1[[#This Row],[VENTA TOTAL $ (IVA INC) ]]-Tabla1[[#This Row],[PENDIENTE DE COBRO]] -> 16537729 | R5: =+Tabla1[[#This Row],[FECHA FC]]+Tabla1[[#This Row],[PLAZO ENTREGA VALORES]] -> 46051 | S5: =+Tabla1[[#This Row],[FECHA FC]]+Tabla1[[#This Row],[PLAZO PAGO (DIAS)]] -> 46168.938 | T5: =+S5-$U$2 -> -12.061806 | U5: =+Tabla1[[#This Row],[FECHA OC]]-Tabla1[[#This Row],[FECHA Entrega]] -> -117.93819 | W5: =+Tabla1[[#This Row],[FECHA VTO VALORES]]+7 -> 46175.938 | Y5: 46051 | Z5: =Tabla1[[#This Row],[KGS]]/50 -> 600 | AA5: =IFERROR((IF(Tabla1[[#This Row],[TIPO OPERACIÓN]]="INDUSTRIA",Tabla1[[#This Row],[PRECIO $/ KG A PLAZO EN CLIENTE ( SIN IVA)]]*50*1.21,IF(Tabla1[[#This Row],[TIPO OPERACIÓN]]="TUC CTADO 2",Tabla1[[#This Row],[PRECIO $/ KG A PLAZO EN CLIENTE ( SIN IVA)]]*50,IF(Tabla1[[#This Row],[TIPO OPERACIÓN]]="EXPO CHILE",Tabla1[[#This Row],[PRECIO $/ KG A PLAZO EN CLIENTE ( SIN IVA)]]*50*1,IF(Tabla1[[#This Row],[TIPO OPERACIÓN]]="GDES CUENTAS",Tabla1[[#This Row],[PRECIO $/ KG A PLAZO EN CLIENTE ( SIN IVA)]]*50*1.21,IF(Tabla1[[#This Row],[TIPO OPERACIÓN]]="TUC CTADO 1",Tabla1[[#This Row],[PRECIO $/ KG A PLAZO EN CLIENTE ( SIN IVA)]]*50*1.21,"")))))),"") -> 27562.881 | AB5: =-Tabla1[[#This Row],[COSTO FLETE $ POR BOLSA 5O KG (SIN IVA)]]*1.21-Tabla1[[#This Row],[PRECIO $/ KG A PLAZO EN CLIENTE ( SIN IVA)]]*0.003*1.21*50 -> -0.40864392 | AC5: =SUM(Tabla1[[#This Row],[PRECIO $ BOLSA 50 KG (IVA INC) ]]+Tabla1[[#This Row],[COSTO FLETE $ BOLSA 50 KG (IVA INC)]]) -> 27562.473 | AD5: =-Tabla1[[#This Row],[PRECIO $ BOLSA 50 KG (IVA INC) ]]*(Tabla1[[#This Row],[TASA FINANCIACION MENSUAL]]/365)*Tabla1[[#This Row],[PLAZO ENTREGA VALORES]] -> 258.2761 | AE5: =SUM(Tabla1[[#This Row],[PRECIO $ BOLSA50 KG FOB TUCUMAN A PLAZO (IVA INC)]]+Tabla1[[#This Row],[GASTOS FINANCIEROS $ BOLSA 50 KG (IVA INC)]]) -> 27820.749 | AF5: GRANEL | AG5: RETIRA DE INGENIO | AH5: TUCUMAN | AI5: GDES CUENTAS | AJ5: =IFERROR(IF(Tabla1[[#This Row],[TIPO OPERACIÓN]]="INDUSTRIA",VLOOKUP(Tabla1[[#This Row],[FECHA OC]],'PRECIO CACTU'!A:B,2,FALSE),IF(Tabla1[[#This Row],[TIPO OPERACIÓN]]="GDES CUENTAS",VLOOKUP(Tabla1[[#This Row],[FECHA OC]],'PRECIO CACTU'!A:B,2,FALSE),IF(Tabla1[[#This Row],[TIPO OPERACIÓN]]="EXPO CHILE",VLOOKUP(Tabla1[[#This Row],[FECHA OC]],'PRECIO CACTU'!A:B,2,FALSE)/1.21,IF(Tabla1[[#This Row],[TIPO OPERACIÓN]]="TUC CTADO 2",VLOOKUP(Tabla1[[#This Row],[FECHA OC]],'PRECIO CACTU'!A:B,2,FALSE)/1.21,IF(Tabla1[[#This Row],[TIPO OPERACIÓN]]="TUC CTADO 1",VLOOKUP(Tabla1[[#This Row],[FECHA OC]],'PRECIO CACTU'!A:B,2,FALSE),""))))),"") -> 32515 | AK5: =SUM(Tabla1[[#This Row],[PRECIO $ BOLSA 50KG FOB CDO TUC (IVA INC)]]-Tabla1[[#This Row],[PRECIO REF $ BOLSA 50 KG CACTU (IVA INC)]]) -> -4694.2512 | AL5: =IFERROR(Tabla1[[#This Row],[PRECIO $ BOLSA 50KG FOB CDO TUC (IVA INC)]]/Tabla1[[#This Row],[PRECIO REF $ BOLSA 50 KG CACTU (IVA INC)]]-1,"") -> -0.14437187 | AM5: =+Tabla1[[#This Row],[DIF $ PRECIO NETO INDUSTRIA vs Neto TUCUMAN (IVA INC)]]*Tabla1[[#This Row],[Q Bolsas Equivalentes 50kg]] -> -2816550.7 | AN5: =Tabla1[[#This Row],[PRECIO REF $ BOLSA 50 KG CACTU (IVA INC)]]*Tabla1[[#This Row],[Q Bolsas Equivalentes 50kg]] -> 19509000 | AO5: =+Tabla1[[#This Row],[PRECIO $ BOLSA 50KG FOB CDO TUC (IVA INC)]]*Tabla1[[#This Row],[Q Bolsas Equivalentes 50kg]] -> 16692449 | AP5: 0.029 | AQ5: -68 | AT5: =+Tabla1[[#This Row],[VENTA TOTAL $ (IVA INC) ]]-(SUM(Tabla1[[#This Row],[PENDIENTE DE ENTREGA]:[VALORES COBRADOS]])) -> 0 | AU5: =VLOOKUP(Tabla1[[#This Row],[FECHA OC]],'TIPO DE CAMBIO'!A:B,2,TRUE) -> 1446.301 | AV5: =+Tabla1[[#This Row],[SUBTOTAL]]/Tabla1[[#This Row],[TIPO DE CAMBIO]] -> 9450 | AX5: =IFERROR(Tabla1[[#This Row],[VENTA TOTAL USD A PLAZO EN CLIENTE (SIN IVA)]]*(1+Tabla1[[#This Row],[% IVA ]]),"") -> 9450 | AY5: =+Tabla1[[#This Row],[VENTA TOTAL USD A PLAZO EN CLIENTE (SIN IVA)]]/Tabla1[[#This Row],[KGS]]*1000 -> 315 | AZ5: 0 | BA5: =+Tabla1[[#This Row],[GASTOS FINANCIEROS $ BOLSA 50 KG (IVA INC)]]*20/Tabla1[[#This Row],[TIPO DE CAMBIO]] -> 3.5715401 | BB5: =+Tabla1[[#This Row],[PRECIO POR TN USD EN CLIENTE A PLAZO (SIN IVA)]]+Tabla1[[#This Row],[COSTO USD FLETE /TN (SIN IVA)]]+Tabla1[[#This Row],[COSTO FINANCIERO USD POR BOLSA 50KG (IVA INC)]] -> 318.57154 | BC5: 5
A6: 46143 | B6: 1 | C6: LEDESMA SAAI | D6: =+Tabla1[[#This Row],[FECHA Entrega]] -> 46168.951 | E6: 700000869 | F6: AZÚCAR CRUDO | G6: ENTREGADO | H6: 46168.951 | I6: =579*50 -> 28950 | J6: =0.315*Tabla1[[#This Row],[TIPO DE CAMBIO]] -> 455.58481 | K6: =+J6*I6 -> 13189180 | L6: =IF(Tabla1[[#This Row],[TIPO OPERACIÓN]]="INDUSTRIA",Tabla1[[#This Row],[SUBTOTAL]]*0.21,IF(Tabla1[[#This Row],[TIPO OPERACIÓN]]="GDES CUENTAS",Tabla1[[#This Row],[SUBTOTAL]]*0.21,IF(Tabla1[[#This Row],[TIPO OPERACIÓN]]="TUC CTADO 2","",IF(Tabla1[[#This Row],[TIPO OPERACIÓN]]="EXPO CHILE","",IF(Tabla1[[#This Row],[TIPO OPERACIÓN]]="TUC CTADO 1",Tabla1[[#This Row],[SUBTOTAL]]*0.21,""))))) -> 2769727.9 | M6: =SUM(K6:L6) -> 15958908 | O6: 0 | P6: 0 | Q6: =+Tabla1[[#This Row],[VENTA TOTAL $ (IVA INC) ]]-Tabla1[[#This Row],[PENDIENTE DE COBRO]] -> 15958908 | R6: =+Tabla1[[#This Row],[FECHA FC]]+Tabla1[[#This Row],[PLAZO ENTREGA VALORES]] -> 46051 | S6: =+Tabla1[[#This Row],[FECHA FC]]+Tabla1[[#This Row],[PLAZO PAGO (DIAS)]] -> 46168.951 | T6: =+S6-$U$2 -> -12.049306 | U6: =+Tabla1[[#This Row],[FECHA OC]]-Tabla1[[#This Row],[FECHA Entrega]] -> -117.95069 | W6: =+Tabla1[[#This Row],[FECHA VTO VALORES]]+7 -> 46175.951 | Y6: 46051 | Z6: =Tabla1[[#This Row],[KGS]]/50 -> 579 | AA6: =IFERROR((IF(Tabla1[[#This Row],[TIPO OPERACIÓN]]="INDUSTRIA",Tabla1[[#This Row],[PRECIO $/ KG A PLAZO EN CLIENTE ( SIN IVA)]]*50*1.21,IF(Tabla1[[#This Row],[TIPO OPERACIÓN]]="TUC CTADO 2",Tabla1[[#This Row],[PRECIO $/ KG A PLAZO EN CLIENTE ( SIN IVA)]]*50,IF(Tabla1[[#This Row],[TIPO OPERACIÓN]]="EXPO CHILE",Tabla1[[#This Row],[PRECIO $/ KG A PLAZO EN CLIENTE ( SIN IVA)]]*50*1,IF(Tabla1[[#This Row],[TIPO OPERACIÓN]]="GDES CUENTAS",Tabla1[[#This Row],[PRECIO $/ KG A PLAZO EN CLIENTE ( SIN IVA)]]*50*1.21,IF(Tabla1[[#This Row],[TIPO OPERACIÓN]]="TUC CTADO 1",Tabla1[[#This Row],[PRECIO $/ KG A PLAZO EN CLIENTE ( SIN IVA)]]*50*1.21,"")))))),"") -> 27562.881 | AB6: =-Tabla1[[#This Row],[COSTO FLETE $ POR BOLSA 5O KG (SIN IVA)]]*1.21-Tabla1[[#This Row],[PRECIO $/ KG A PLAZO EN CLIENTE ( SIN IVA)]]*0.003*1.21*50 -> -0.40864392 | AC6: =SUM(Tabla1[[#This Row],[PRECIO $ BOLSA 50 KG (IVA INC) ]]+Tabla1[[#This Row],[COSTO FLETE $ BOLSA 50 KG (IVA INC)]]) -> 27562.473 | AD6: =-Tabla1[[#This Row],[PRECIO $ BOLSA 50 KG (IVA INC) ]]*(Tabla1[[#This Row],[TASA FINANCIACION MENSUAL]]/365)*Tabla1[[#This Row],[PLAZO ENTREGA VALORES]] -> 258.30348 | AE6: =SUM(Tabla1[[#This Row],[PRECIO $ BOLSA50 KG FOB TUCUMAN A PLAZO (IVA INC)]]+Tabla1[[#This Row],[GASTOS FINANCIEROS $ BOLSA 50 KG (IVA INC)]]) -> 27820.776 | AF6: GRANEL | AG6: RETIRA DE INGENIO | AH6: TUCUMAN | AI6: GDES CUENTAS | AJ6: =IFERROR(IF(Tabla1[[#This Row],[TIPO OPERACIÓN]]="INDUSTRIA",VLOOKUP(Tabla1[[#This Row],[FECHA OC]],'PRECIO CACTU'!A:B,2,FALSE),IF(Tabla1[[#This Row],[TIPO OPERACIÓN]]="GDES CUENTAS",VLOOKUP(Tabla1[[#This Row],[FECHA OC]],'PRECIO CACTU'!A:B,2,FALSE),IF(Tabla1[[#This Row],[TIPO OPERACIÓN]]="EXPO CHILE",VLOOKUP(Tabla1[[#This Row],[FECHA OC]],'PRECIO CACTU'!A:B,2,FALSE)/1.21,IF(Tabla1[[#This Row],[TIPO OPERACIÓN]]="TUC CTADO 2",VLOOKUP(Tabla1[[#This Row],[FECHA OC]],'PRECIO CACTU'!A:B,2,FALSE)/1.21,IF(Tabla1[[#This Row],[TIPO OPERACIÓN]]="TUC CTADO 1",VLOOKUP(Tabla1[[#This Row],[FECHA OC]],'PRECIO CACTU'!A:B,2,FALSE),""))))),"") -> 32515 | AK6: =SUM(Tabla1[[#This Row],[PRECIO $ BOLSA 50KG FOB CDO TUC (IVA INC)]]-Tabla1[[#This Row],[PRECIO REF $ BOLSA 50 KG CACTU (IVA INC)]]) -> -4694.2239 | AL6: =IFERROR(Tabla1[[#This Row],[PRECIO $ BOLSA 50KG FOB CDO TUC (IVA INC)]]/Tabla1[[#This Row],[PRECIO REF $ BOLSA 50 KG CACTU (IVA INC)]]-1,"") -> -0.14437102 | AM6: =+Tabla1[[#This Row],[DIF $ PRECIO NETO INDUSTRIA vs Neto TUCUMAN (IVA INC)]]*Tabla1[[#This Row],[Q Bolsas Equivalentes 50kg]] -> -2717955.6 | AN6: =Tabla1[[#This Row],[PRECIO REF $ BOLSA 50 KG CACTU (IVA INC)]]*Tabla1[[#This Row],[Q Bolsas Equivalentes 50kg]] -> 18826185 | AO6: =+Tabla1[[#This Row],[PRECIO $ BOLSA 50KG FOB CDO TUC (IVA INC)]]*Tabla1[[#This Row],[Q Bolsas Equivalentes 50kg]] -> 16108229 | AP6: 0.029 | AQ6: -68 | AS6: 0008-00005536 | AT6: =+Tabla1[[#This Row],[VENTA TOTAL $ (IVA INC) ]]-(SUM(Tabla1[[#This Row],[PENDIENTE DE ENTREGA]:[VALORES COBRADOS]])) -> 0 | AU6: =VLOOKUP(Tabla1[[#This Row],[FECHA OC]],'TIPO DE CAMBIO'!A:B,2,TRUE) -> 1446.301 | AV6: =+Tabla1[[#This Row],[SUBTOTAL]]/Tabla1[[#This Row],[TIPO DE CAMBIO]] -> 9119.25 | AX6: =IFERROR(Tabla1[[#This Row],[VENTA TOTAL USD A PLAZO EN CLIENTE (SIN IVA)]]*(1+Tabla1[[#This Row],[% IVA ]]),"") -> 9119.25 | AY6: =+Tabla1[[#This Row],[VENTA TOTAL USD A PLAZO EN CLIENTE (SIN IVA)]]/Tabla1[[#This Row],[KGS]]*1000 -> 315 | AZ6: 0 | BA6: =+Tabla1[[#This Row],[GASTOS FINANCIEROS $ BOLSA 50 KG (IVA INC)]]*20/Tabla1[[#This Row],[TIPO DE CAMBIO]] -> 3.5719187 | BB6: =+Tabla1[[#This Row],[PRECIO POR TN USD EN CLIENTE A PLAZO (SIN IVA)]]+Tabla1[[#This Row],[COSTO USD FLETE /TN (SIN IVA)]]+Tabla1[[#This Row],[COSTO FINANCIERO USD POR BOLSA 50KG (IVA INC)]] -> 318.57192 | BC6: 5
A7: 46143 | B7: 1 | C7: LEDESMA SAAI | D7: =+Tabla1[[#This Row],[FECHA Entrega]] -> 46170.651 | E7: 700000869 | F7: AZÚCAR CRUDO | G7: ENTREGADO | H7: 46170.651 | I7: =588*50 -> 29400 | J7: =0.315*Tabla1[[#This Row],[TIPO DE CAMBIO]] -> 455.58481 | K7: =+J7*I7 -> 13394194 | L7: =IF(Tabla1[[#This Row],[TIPO OPERACIÓN]]="INDUSTRIA",Tabla1[[#This Row],[SUBTOTAL]]*0.21,IF(Tabla1[[#This Row],[TIPO OPERACIÓN]]="GDES CUENTAS",Tabla1[[#This Row],[SUBTOTAL]]*0.21,IF(Tabla1[[#This Row],[TIPO OPERACIÓN]]="TUC CTADO 2","",IF(Tabla1[[#This Row],[TIPO OPERACIÓN]]="EXPO CHILE","",IF(Tabla1[[#This Row],[TIPO OPERACIÓN]]="TUC CTADO 1",Tabla1[[#This Row],[SUBTOTAL]]*0.21,""))))) -> 2812780.6 | M7: =SUM(K7:L7) -> 16206974 | O7: 0 | P7: 0 | Q7: =+Tabla1[[#This Row],[VENTA TOTAL $ (IVA INC) ]]-Tabla1[[#This Row],[PENDIENTE DE COBRO]] -> 16206974 | R7: =+Tabla1[[#This Row],[FECHA FC]]+Tabla1[[#This Row],[PLAZO ENTREGA VALORES]] -> 46051 | S7: =+Tabla1[[#This Row],[FECHA FC]]+Tabla1[[#This Row],[PLAZO PAGO (DIAS)]] -> 46170.651 | T7: =+S7-$U$2 -> -10.348611 | U7: =+Tabla1[[#This Row],[FECHA OC]]-Tabla1[[#This Row],[FECHA Entrega]] -> -119.65139 | W7: =+Tabla1[[#This Row],[FECHA VTO VALORES]]+7 -> 46177.651 | Y7: 46051 | Z7: =Tabla1[[#This Row],[KGS]]/50 -> 588 | AA7: =IFERROR((IF(Tabla1[[#This Row],[TIPO OPERACIÓN]]="INDUSTRIA",Tabla1[[#This Row],[PRECIO $/ KG A PLAZO EN CLIENTE ( SIN IVA)]]*50*1.21,IF(Tabla1[[#This Row],[TIPO OPERACIÓN]]="TUC CTADO 2",Tabla1[[#This Row],[PRECIO $/ KG A PLAZO EN CLIENTE ( SIN IVA)]]*50,IF(Tabla1[[#This Row],[TIPO OPERACIÓN]]="EXPO CHILE",Tabla1[[#This Row],[PRECIO $/ KG A PLAZO EN CLIENTE ( SIN IVA)]]*50*1,IF(Tabla1[[#This Row],[TIPO OPERACIÓN]]="GDES CUENTAS",Tabla1[[#This Row],[PRECIO $/ KG A PLAZO EN CLIENTE ( SIN IVA)]]*50*1.21,IF(Tabla1[[#This Row],[TIPO OPERACIÓN]]="TUC CTADO 1",Tabla1[[#This Row],[PRECIO $/ KG A PLAZO EN CLIENTE ( SIN IVA)]]*50*1.21,"")))))),"") -> 27562.881 | AB7: =-Tabla1[[#This Row],[COSTO FLETE $ POR BOLSA 5O KG (SIN IVA)]]*1.21-Tabla1[[#This Row],[PRECIO $/ KG A PLAZO EN CLIENTE ( SIN IVA)]]*0.003*1.21*50 -> -0.40864392 | AC7: =SUM(Tabla1[[#This Row],[PRECIO $ BOLSA 50 KG (IVA INC) ]]+Tabla1[[#This Row],[COSTO FLETE $ BOLSA 50 KG (IVA INC)]]) -> 27562.473 | AD7: =-Tabla1[[#This Row],[PRECIO $ BOLSA 50 KG (IVA INC) ]]*(Tabla1[[#This Row],[TASA FINANCIACION MENSUAL]]/365)*Tabla1[[#This Row],[PLAZO ENTREGA VALORES]] -> 262.02787 | AE7: =SUM(Tabla1[[#This Row],[PRECIO $ BOLSA50 KG FOB TUCUMAN A PLAZO (IVA INC)]]+Tabla1[[#This Row],[GASTOS FINANCIEROS $ BOLSA 50 KG (IVA INC)]]) -> 27824.501 | AF7: GRANEL | AG7: RETIRA DE INGENIO | AH7: TUCUMAN | AI7: GDES CUENTAS | AJ7: =IFERROR(IF(Tabla1[[#This Row],[TIPO OPERACIÓN]]="INDUSTRIA",VLOOKUP(Tabla1[[#This Row],[FECHA OC]],'PRECIO CACTU'!A:B,2,FALSE),IF(Tabla1[[#This Row],[TIPO OPERACIÓN]]="GDES CUENTAS",VLOOKUP(Tabla1[[#This Row],[FECHA OC]],'PRECIO CACTU'!A:B,2,FALSE),IF(Tabla1[[#This Row],[TIPO OPERACIÓN]]="EXPO CHILE",VLOOKUP(Tabla1[[#This Row],[FECHA OC]],'PRECIO CACTU'!A:B,2,FALSE)/1.21,IF(Tabla1[[#This Row],[TIPO OPERACIÓN]]="TUC CTADO 2",VLOOKUP(Tabla1[[#This Row],[FECHA OC]],'PRECIO CACTU'!A:B,2,FALSE)/1.21,IF(Tabla1[[#This Row],[TIPO OPERACIÓN]]="TUC CTADO 1",VLOOKUP(Tabla1[[#This Row],[FECHA OC]],'PRECIO CACTU'!A:B,2,FALSE),""))))),"") -> 32515 | AK7: =SUM(Tabla1[[#This Row],[PRECIO $ BOLSA 50KG FOB CDO TUC (IVA INC)]]-Tabla1[[#This Row],[PRECIO REF $ BOLSA 50 KG CACTU (IVA INC)]]) -> -4690.4995 | AL7: =IFERROR(Tabla1[[#This Row],[PRECIO $ BOLSA 50KG FOB CDO TUC (IVA INC)]]/Tabla1[[#This Row],[PRECIO REF $ BOLSA 50 KG CACTU (IVA INC)]]-1,"") -> -0.14425648 | AM7: =+Tabla1[[#This Row],[DIF $ PRECIO NETO INDUSTRIA vs Neto TUCUMAN (IVA INC)]]*Tabla1[[#This Row],[Q Bolsas Equivalentes 50kg]] -> -2758013.7 | AN7: =Tabla1[[#This Row],[PRECIO REF $ BOLSA 50 KG CACTU (IVA INC)]]*Tabla1[[#This Row],[Q Bolsas Equivalentes 50kg]] -> 19118820 | AO7: =+Tabla1[[#This Row],[PRECIO $ BOLSA 50KG FOB CDO TUC (IVA INC)]]*Tabla1[[#This Row],[Q Bolsas Equivalentes 50kg]] -> 16360806 | AP7: 0.029 | AQ7: -68 | AS7: 0008-00005540 | AT7: =+Tabla1[[#This Row],[VENTA TOTAL $ (IVA INC) ]]-(SUM(Tabla1[[#This Row],[PENDIENTE DE ENTREGA]:[VALORES COBRADOS]])) -> 0 | AU7: =VLOOKUP(Tabla1[[#This Row],[FECHA OC]],'TIPO DE CAMBIO'!A:B,2,TRUE) -> 1446.301 | AV7: =+Tabla1[[#This Row],[SUBTOTAL]]/Tabla1[[#This Row],[TIPO DE CAMBIO]] -> 9261 | AX7: =IFERROR(Tabla1[[#This Row],[VENTA TOTAL USD A PLAZO EN CLIENTE (SIN IVA)]]*(1+Tabla1[[#This Row],[% IVA ]]),"") -> 9261 | AY7: =+Tabla1[[#This Row],[VENTA TOTAL USD A PLAZO EN CLIENTE (SIN IVA)]]/Tabla1[[#This Row],[KGS]]*1000 -> 315 | AZ7: 0 | BA7: =+Tabla1[[#This Row],[GASTOS FINANCIEROS $ BOLSA 50 KG (IVA INC)]]*20/Tabla1[[#This Row],[TIPO DE CAMBIO]] -> 3.623421 | BB7: =+Tabla1[[#This Row],[PRECIO POR TN USD EN CLIENTE A PLAZO (SIN IVA)]]+Tabla1[[#This Row],[COSTO USD FLETE /TN (SIN IVA)]]+Tabla1[[#This Row],[COSTO FINANCIERO USD POR BOLSA 50KG (IVA INC)]] -> 318.62342 | BC7: 5
A8: 46143 | B8: 1 | C8: LEDESMA SAAI | D8: =+Tabla1[[#This Row],[FECHA Entrega]] -> 46170.655 | E8: 700000869 | F8: AZÚCAR CRUDO | G8: ENTREGADO | H8: 46170.655 | I8: =581*50 -> 29050 | J8: =0.315*Tabla1[[#This Row],[TIPO DE CAMBIO]] -> 455.58481 | K8: =+J8*I8 -> 13234739 | L8: =IF(Tabla1[[#This Row],[TIPO OPERACIÓN]]="INDUSTRIA",Tabla1[[#This Row],[SUBTOTAL]]*0.21,IF(Tabla1[[#This Row],[TIPO OPERACIÓN]]="GDES CUENTAS",Tabla1[[#This Row],[SUBTOTAL]]*0.21,IF(Tabla1[[#This Row],[TIPO OPERACIÓN]]="TUC CTADO 2","",IF(Tabla1[[#This Row],[TIPO OPERACIÓN]]="EXPO CHILE","",IF(Tabla1[[#This Row],[TIPO OPERACIÓN]]="TUC CTADO 1",Tabla1[[#This Row],[SUBTOTAL]]*0.21,""))))) -> 2779295.2 | M8: =SUM(K8:L8) -> 16014034 | O8: 0 | P8: 0 | Q8: =+Tabla1[[#This Row],[VENTA TOTAL $ (IVA INC) ]]-Tabla1[[#This Row],[PENDIENTE DE COBRO]] -> 16014034 | R8: =+Tabla1[[#This Row],[FECHA FC]]+Tabla1[[#This Row],[PLAZO ENTREGA VALORES]] -> 46051 | S8: =+Tabla1[[#This Row],[FECHA FC]]+Tabla1[[#This Row],[PLAZO PAGO (DIAS)]] -> 46170.655 | T8: =+S8-$U$2 -> -10.345139 | U8: =+Tabla1[[#This Row],[FECHA OC]]-Tabla1[[#This Row],[FECHA Entrega]] -> -119.65486 | W8: =+Tabla1[[#This Row],[FECHA VTO VALORES]]+7 -> 46177.655 | Y8: 46051 | Z8: =Tabla1[[#This Row],[KGS]]/50 -> 581 | AA8: =IFERROR((IF(Tabla1[[#This Row],[TIPO OPERACIÓN]]="INDUSTRIA",Tabla1[[#This Row],[PRECIO $/ KG A PLAZO EN CLIENTE ( SIN IVA)]]*50*1.21,IF(Tabla1[[#This Row],[TIPO OPERACIÓN]]="TUC CTADO 2",Tabla1[[#This Row],[PRECIO $/ KG A PLAZO EN CLIENTE ( SIN IVA)]]*50,IF(Tabla1[[#This Row],[TIPO OPERACIÓN]]="EXPO CHILE",Tabla1[[#This Row],[PRECIO $/ KG A PLAZO EN CLIENTE ( SIN IVA)]]*50*1,IF(Tabla1[[#This Row],[TIPO OPERACIÓN]]="GDES CUENTAS",Tabla1[[#This Row],[PRECIO $/ KG A PLAZO EN CLIENTE ( SIN IVA)]]*50*1.21,IF(Tabla1[[#This Row],[TIPO OPERACIÓN]]="TUC CTADO 1",Tabla1[[#This Row],[PRECIO $/ KG A PLAZO EN CLIENTE ( SIN IVA)]]*50*1.21,"")))))),"") -> 27562.881 | AB8: =-Tabla1[[#This Row],[COSTO FLETE $ POR BOLSA 5O KG (SIN IVA)]]*1.21-Tabla1[[#This Row],[PRECIO $/ KG A PLAZO EN CLIENTE ( SIN IVA)]]*0.003*1.21*50 -> -0.40864392 | AC8: =SUM(Tabla1[[#This Row],[PRECIO $ BOLSA 50 KG (IVA INC) ]]+Tabla1[[#This Row],[COSTO FLETE $ BOLSA 50 KG (IVA INC)]]) -> 27562.473 | AD8: =-Tabla1[[#This Row],[PRECIO $ BOLSA 50 KG (IVA INC) ]]*(Tabla1[[#This Row],[TASA FINANCIACION MENSUAL]]/365)*Tabla1[[#This Row],[PLAZO ENTREGA VALORES]] -> 262.03548 | AE8: =SUM(Tabla1[[#This Row],[PRECIO $ BOLSA50 KG FOB TUCUMAN A PLAZO (IVA INC)]]+Tabla1[[#This Row],[GASTOS FINANCIEROS $ BOLSA 50 KG (IVA INC)]]) -> 27824.508 | AF8: GRANEL | AG8: RETIRA DE INGENIO | AH8: TUCUMAN | AI8: GDES CUENTAS | AJ8: =IFERROR(IF(Tabla1[[#This Row],[TIPO OPERACIÓN]]="INDUSTRIA",VLOOKUP(Tabla1[[#This Row],[FECHA OC]],'PRECIO CACTU'!A:B,2,FALSE),IF(Tabla1[[#This Row],[TIPO OPERACIÓN]]="GDES CUENTAS",VLOOKUP(Tabla1[[#This Row],[FECHA OC]],'PRECIO CACTU'!A:B,2,FALSE),IF(Tabla1[[#This Row],[TIPO OPERACIÓN]]="EXPO CHILE",VLOOKUP(Tabla1[[#This Row],[FECHA OC]],'PRECIO CACTU'!A:B,2,FALSE)/1.21,IF(Tabla1[[#This Row],[TIPO OPERACIÓN]]="TUC CTADO 2",VLOOKUP(Tabla1[[#This Row],[FECHA OC]],'PRECIO CACTU'!A:B,2,FALSE)/1.21,IF(Tabla1[[#This Row],[TIPO OPERACIÓN]]="TUC CTADO 1",VLOOKUP(Tabla1[[#This Row],[FECHA OC]],'PRECIO CACTU'!A:B,2,FALSE),""))))),"") -> 32515 | AK8: =SUM(Tabla1[[#This Row],[PRECIO $ BOLSA 50KG FOB CDO TUC (IVA INC)]]-Tabla1[[#This Row],[PRECIO REF $ BOLSA 50 KG CACTU (IVA INC)]]) -> -4690.4919 | AL8: =IFERROR(Tabla1[[#This Row],[PRECIO $ BOLSA 50KG FOB CDO TUC (IVA INC)]]/Tabla1[[#This Row],[PRECIO REF $ BOLSA 50 KG CACTU (IVA INC)]]-1,"") -> -0.14425625 | AM8: =+Tabla1[[#This Row],[DIF $ PRECIO NETO INDUSTRIA vs Neto TUCUMAN (IVA INC)]]*Tabla1[[#This Row],[Q Bolsas Equivalentes 50kg]] -> -2725175.8 | AN8: =Tabla1[[#This Row],[PRECIO REF $ BOLSA 50 KG CACTU (IVA INC)]]*Tabla1[[#This Row],[Q Bolsas Equivalentes 50kg]] -> 18891215 | AO8: =+Tabla1[[#This Row],[PRECIO $ BOLSA 50KG FOB CDO TUC (IVA INC)]]*Tabla1[[#This Row],[Q Bolsas Equivalentes 50kg]] -> 16166039 | AP8: 0.029 | AQ8: -68 | AS8: 0008-00005542 | AT8: =+Tabla1[[#This Row],[VENTA TOTAL $ (IVA INC) ]]-(SUM(Tabla1[[#This Row],[PENDIENTE DE ENTREGA]:[VALORES COBRADOS]])) -> 0 | AU8: =VLOOKUP(Tabla1[[#This Row],[FECHA OC]],'TIPO DE CAMBIO'!A:B,2,TRUE) -> 1446.301 | AV8: =+Tabla1[[#This Row],[SUBTOTAL]]/Tabla1[[#This Row],[TIPO DE CAMBIO]] -> 9150.75 | AX8: =IFERROR(Tabla1[[#This Row],[VENTA TOTAL USD A PLAZO EN CLIENTE (SIN IVA)]]*(1+Tabla1[[#This Row],[% IVA ]]),"") -> 9150.75 | AY8: =+Tabla1[[#This Row],[VENTA TOTAL USD A PLAZO EN CLIENTE (SIN IVA)]]/Tabla1[[#This Row],[KGS]]*1000 -> 315 | AZ8: 0 | BA8: =+Tabla1[[#This Row],[GASTOS FINANCIEROS $ BOLSA 50 KG (IVA INC)]]*20/Tabla1[[#This Row],[TIPO DE CAMBIO]] -> 3.6235262 | BB8: =+Tabla1[[#This Row],[PRECIO POR TN USD EN CLIENTE A PLAZO (SIN IVA)]]+Tabla1[[#This Row],[COSTO USD FLETE /TN (SIN IVA)]]+Tabla1[[#This Row],[COSTO FINANCIERO USD POR BOLSA 50KG (IVA INC)]] -> 318.62353 | BC8: 5
A9: 46143 | B9: 1 | C9: LEDESMA SAAI | D9: =+Tabla1[[#This Row],[FECHA Entrega]] -> 46170.758 | E9: 700000869 | F9: AZÚCAR CRUDO | G9: ENTREGADO | H9: 46170.758 | I9: =586*50 -> 29300 | J9: =0.315*Tabla1[[#This Row],[TIPO DE CAMBIO]] -> 455.58481 | K9: =+J9*I9 -> 13348635 | L9: =IF(Tabla1[[#This Row],[TIPO OPERACIÓN]]="INDUSTRIA",Tabla1[[#This Row],[SUBTOTAL]]*0.21,IF(Tabla1[[#This Row],[TIPO OPERACIÓN]]="GDES CUENTAS",Tabla1[[#This Row],[SUBTOTAL]]*0.21,IF(Tabla1[[#This Row],[TIPO OPERACIÓN]]="TUC CTADO 2","",IF(Tabla1[[#This Row],[TIPO OPERACIÓN]]="EXPO CHILE","",IF(Tabla1[[#This Row],[TIPO OPERACIÓN]]="TUC CTADO 1",Tabla1[[#This Row],[SUBTOTAL]]*0.21,""))))) -> 2803213.4 | M9: =SUM(K9:L9) -> 16151848 | O9: 0 | P9: 0 | Q9: =+Tabla1[[#This Row],[VENTA TOTAL $ (IVA INC) ]]-Tabla1[[#This Row],[PENDIENTE DE COBRO]] -> 16151848 | R9: =+Tabla1[[#This Row],[FECHA FC]]+Tabla1[[#This Row],[PLAZO ENTREGA VALORES]] -> 46051 | S9: =+Tabla1[[#This Row],[FECHA FC]]+Tabla1[[#This Row],[PLAZO PAGO (DIAS)]] -> 46170.758 | T9: =+S9-$U$2 -> -10.242361 | U9: =+Tabla1[[#This Row],[FECHA OC]]-Tabla1[[#This Row],[FECHA Entrega]] -> -119.75764 | W9: =+Tabla1[[#This Row],[FECHA VTO VALORES]]+7 -> 46177.758 | Y9: 46051 | Z9: =Tabla1[[#This Row],[KGS]]/50 -> 586 | AA9: =IFERROR((IF(Tabla1[[#This Row],[TIPO OPERACIÓN]]="INDUSTRIA",Tabla1[[#This Row],[PRECIO $/ KG A PLAZO EN CLIENTE ( SIN IVA)]]*50*1.21,IF(Tabla1[[#This Row],[TIPO OPERACIÓN]]="TUC CTADO 2",Tabla1[[#This Row],[PRECIO $/ KG A PLAZO EN CLIENTE ( SIN IVA)]]*50,IF(Tabla1[[#This Row],[TIPO OPERACIÓN]]="EXPO CHILE",Tabla1[[#This Row],[PRECIO $/ KG A PLAZO EN CLIENTE ( SIN IVA)]]*50*1,IF(Tabla1[[#This Row],[TIPO OPERACIÓN]]="GDES CUENTAS",Tabla1[[#This Row],[PRECIO $/ KG A PLAZO EN CLIENTE ( SIN IVA)]]*50*1.21,IF(Tabla1[[#This Row],[TIPO OPERACIÓN]]="TUC CTADO 1",Tabla1[[#This Row],[PRECIO $/ KG A PLAZO EN CLIENTE ( SIN IVA)]]*50*1.21,"")))))),"") -> 27562.881 | AB9: =-Tabla1[[#This Row],[COSTO FLETE $ POR BOLSA 5O KG (SIN IVA)]]*1.21-Tabla1[[#This Row],[PRECIO $/ KG A PLAZO EN CLIENTE ( SIN IVA)]]*0.003*1.21*50 -> -0.40864392 | AC9: =SUM(Tabla1[[#This Row],[PRECIO $ BOLSA 50 KG (IVA INC) ]]+Tabla1[[#This Row],[COSTO FLETE $ BOLSA 50 KG (IVA INC)]]) -> 27562.473 | AD9: =-Tabla1[[#This Row],[PRECIO $ BOLSA 50 KG (IVA INC) ]]*(Tabla1[[#This Row],[TASA FINANCIACION MENSUAL]]/365)*Tabla1[[#This Row],[PLAZO ENTREGA VALORES]] -> 262.26055 | AE9: =SUM(Tabla1[[#This Row],[PRECIO $ BOLSA50 KG FOB TUCUMAN A PLAZO (IVA INC)]]+Tabla1[[#This Row],[GASTOS FINANCIEROS $ BOLSA 50 KG (IVA INC)]]) -> 27824.733 | AF9: GRANEL | AG9: RETIRA DE INGENIO | AH9: TUCUMAN | AI9: GDES CUENTAS | AJ9: =IFERROR(IF(Tabla1[[#This Row],[TIPO OPERACIÓN]]="INDUSTRIA",VLOOKUP(Tabla1[[#This Row],[FECHA OC]],'PRECIO CACTU'!A:B,2,FALSE),IF(Tabla1[[#This Row],[TIPO OPERACIÓN]]="GDES CUENTAS",VLOOKUP(Tabla1[[#This Row],[FECHA OC]],'PRECIO CACTU'!A:B,2,FALSE),IF(Tabla1[[#This Row],[TIPO OPERACIÓN]]="EXPO CHILE",VLOOKUP(Tabla1[[#This Row],[FECHA OC]],'PRECIO CACTU'!A:B,2,FALSE)/1.21,IF(Tabla1[[#This Row],[TIPO OPERACIÓN]]="TUC CTADO 2",VLOOKUP(Tabla1[[#This Row],[FECHA OC]],'PRECIO CACTU'!A:B,2,FALSE)/1.21,IF(Tabla1[[#This Row],[TIPO OPERACIÓN]]="TUC CTADO 1",VLOOKUP(Tabla1[[#This Row],[FECHA OC]],'PRECIO CACTU'!A:B,2,FALSE),""))))),"") -> 32515 | AK9: =SUM(Tabla1[[#This Row],[PRECIO $ BOLSA 50KG FOB CDO TUC (IVA INC)]]-Tabla1[[#This Row],[PRECIO REF $ BOLSA 50 KG CACTU (IVA INC)]]) -> -4690.2668 | AL9: =IFERROR(Tabla1[[#This Row],[PRECIO $ BOLSA 50KG FOB CDO TUC (IVA INC)]]/Tabla1[[#This Row],[PRECIO REF $ BOLSA 50 KG CACTU (IVA INC)]]-1,"") -> -0.14424932 | AM9: =+Tabla1[[#This Row],[DIF $ PRECIO NETO INDUSTRIA vs Neto TUCUMAN (IVA INC)]]*Tabla1[[#This Row],[Q Bolsas Equivalentes 50kg]] -> -2748496.3 | AN9: =Tabla1[[#This Row],[PRECIO REF $ BOLSA 50 KG CACTU (IVA INC)]]*Tabla1[[#This Row],[Q Bolsas Equivalentes 50kg]] -> 19053790 | AO9: =+Tabla1[[#This Row],[PRECIO $ BOLSA 50KG FOB CDO TUC (IVA INC)]]*Tabla1[[#This Row],[Q Bolsas Equivalentes 50kg]] -> 16305294 | AP9: 0.029 | AQ9: -68 | AS9: 0008-00005544 | AT9: =+Tabla1[[#This Row],[VENTA TOTAL $ (IVA INC) ]]-(SUM(Tabla1[[#This Row],[PENDIENTE DE ENTREGA]:[VALORES COBRADOS]])) -> 0 | AU9: =VLOOKUP(Tabla1[[#This Row],[FECHA OC]],'TIPO DE CAMBIO'!A:B,2,TRUE) -> 1446.301 | AV9: =+Tabla1[[#This Row],[SUBTOTAL]]/Tabla1[[#This Row],[TIPO DE CAMBIO]] -> 9229.5 | AX9: =IFERROR(Tabla1[[#This Row],[VENTA TOTAL USD A PLAZO EN CLIENTE (SIN IVA)]]*(1+Tabla1[[#This Row],[% IVA ]]),"") -> 9229.5 | AY9: =+Tabla1[[#This Row],[VENTA TOTAL USD A PLAZO EN CLIENTE (SIN IVA)]]/Tabla1[[#This Row],[KGS]]*1000 -> 315 | AZ9: 0 | BA9: =+Tabla1[[#This Row],[GASTOS FINANCIEROS $ BOLSA 50 KG (IVA INC)]]*20/Tabla1[[#This Row],[TIPO DE CAMBIO]] -> 3.6266386 | BB9: =+Tabla1[[#This Row],[PRECIO POR TN USD EN CLIENTE A PLAZO (SIN IVA)]]+Tabla1[[#This Row],[COSTO USD FLETE /TN (SIN IVA)]]+Tabla1[[#This Row],[COSTO FINANCIERO USD POR BOLSA 50KG (IVA INC)]] -> 318.62664 | BC9: 5
A10: 46143 | B10: 1 | C10: LEDESMA SAAI | D10: =+Tabla1[[#This Row],[FECHA Entrega]] -> 46170.808 | E10: 700000869 | F10: AZÚCAR CRUDO | G10: ENTREGADO | H10: 46170.808 | I10: =728*50 -> 36400 | J10: =0.315*Tabla1[[#This Row],[TIPO DE CAMBIO]] -> 455.58481 | K10: =+J10*I10 -> 16583287 | L10: =IF(Tabla1[[#This Row],[TIPO OPERACIÓN]]="INDUSTRIA",Tabla1[[#This Row],[SUBTOTAL]]*0.21,IF(Tabla1[[#This Row],[TIPO OPERACIÓN]]="GDES CUENTAS",Tabla1[[#This Row],[SUBTOTAL]]*0.21,IF(Tabla1[[#This Row],[TIPO OPERACIÓN]]="TUC CTADO 2","",IF(Tabla1[[#This Row],[TIPO OPERACIÓN]]="EXPO CHILE","",IF(Tabla1[[#This Row],[TIPO OPERACIÓN]]="TUC CTADO 1",Tabla1[[#This Row],[SUBTOTAL]]*0.21,""))))) -> 3482490.3 | M10: =SUM(K10:L10) -> 20065778 | O10: 0 | P10: 0 | Q10: =+Tabla1[[#This Row],[VENTA TOTAL $ (IVA INC) ]]-Tabla1[[#This Row],[PENDIENTE DE COBRO]] -> 20065778 | R10: =+Tabla1[[#This Row],[FECHA FC]]+Tabla1[[#This Row],[PLAZO ENTREGA VALORES]] -> 46051 | S10: =+Tabla1[[#This Row],[FECHA FC]]+Tabla1[[#This Row],[PLAZO PAGO (DIAS)]] -> 46170.808 | T10: =+S10-$U$2 -> -10.191667 | U10: =+Tabla1[[#This Row],[FECHA OC]]-Tabla1[[#This Row],[FECHA Entrega]] -> -119.80833 | W10: =+Tabla1[[#This Row],[FECHA VTO VALORES]]+7 -> 46177.808 | Y10: 46051 | Z10: =Tabla1[[#This Row],[KGS]]/50 -> 728 | AA10: =IFERROR((IF(Tabla1[[#This Row],[TIPO OPERACIÓN]]="INDUSTRIA",Tabla1[[#This Row],[PRECIO $/ KG A PLAZO EN CLIENTE ( SIN IVA)]]*50*1.21,IF(Tabla1[[#This Row],[TIPO OPERACIÓN]]="TUC CTADO 2",Tabla1[[#This Row],[PRECIO $/ KG A PLAZO EN CLIENTE ( SIN IVA)]]*50,IF(Tabla1[[#This Row],[TIPO OPERACIÓN]]="EXPO CHILE",Tabla1[[#This Row],[PRECIO $/ KG A PLAZO EN CLIENTE ( SIN IVA)]]*50*1,IF(Tabla1[[#This Row],[TIPO OPERACIÓN]]="GDES CUENTAS",Tabla1[[#This Row],[PRECIO $/ KG A PLAZO EN CLIENTE ( SIN IVA)]]*50*1.21,IF(Tabla1[[#This Row],[TIPO OPERACIÓN]]="TUC CTADO 1",Tabla1[[#This Row],[PRECIO $/ KG A PLAZO EN CLIENTE ( SIN IVA)]]*50*1.21,"")))))),"") -> 27562.881 | AB10: =-Tabla1[[#This Row],[COSTO FLETE $ POR BOLSA 5O KG (SIN IVA)]]*1.21-Tabla1[[#This Row],[PRECIO $/ KG A PLAZO EN CLIENTE ( SIN IVA)]]*0.003*1.21*50 -> -0.40864392 | AC10: =SUM(Tabla1[[#This Row],[PRECIO $ BOLSA 50 KG (IVA INC) ]]+Tabla1[[#This Row],[COSTO FLETE $ BOLSA 50 KG (IVA INC)]]) -> 27562.473 | AD10: =-Tabla1[[#This Row],[PRECIO $ BOLSA 50 KG (IVA INC) ]]*(Tabla1[[#This Row],[TASA FINANCIACION MENSUAL]]/365)*Tabla1[[#This Row],[PLAZO ENTREGA VALORES]] -> 262.37157 | AE10: =SUM(Tabla1[[#This Row],[PRECIO $ BOLSA50 KG FOB TUCUMAN A PLAZO (IVA INC)]]+Tabla1[[#This Row],[GASTOS FINANCIEROS $ BOLSA 50 KG (IVA INC)]]) -> 27824.844 | AF10: GRANEL | AG10: RETIRA DE INGENIO | AH10: TUCUMAN | AI10: GDES CUENTAS | AJ10: =IFERROR(IF(Tabla1[[#This Row],[TIPO OPERACIÓN]]="INDUSTRIA",VLOOKUP(Tabla1[[#This Row],[FECHA OC]],'PRECIO CACTU'!A:B,2,FALSE),IF(Tabla1[[#This Row],[TIPO OPERACIÓN]]="GDES CUENTAS",VLOOKUP(Tabla1[[#This Row],[FECHA OC]],'PRECIO CACTU'!A:B,2,FALSE),IF(Tabla1[[#This Row],[TIPO OPERACIÓN]]="EXPO CHILE",VLOOKUP(Tabla1[[#This Row],[FECHA OC]],'PRECIO CACTU'!A:B,2,FALSE)/1.21,IF(Tabla1[[#This Row],[TIPO OPERACIÓN]]="TUC CTADO 2",VLOOKUP(Tabla1[[#This Row],[FECHA OC]],'PRECIO CACTU'!A:B,2,FALSE)/1.21,IF(Tabla1[[#This Row],[TIPO OPERACIÓN]]="TUC CTADO 1",VLOOKUP(Tabla1[[#This Row],[FECHA OC]],'PRECIO CACTU'!A:B,2,FALSE),""))))),"") -> 32515 | AK10: =SUM(Tabla1[[#This Row],[PRECIO $ BOLSA 50KG FOB CDO TUC (IVA INC)]]-Tabla1[[#This Row],[PRECIO REF $ BOLSA 50 KG CACTU (IVA INC)]]) -> -4690.1558 | AL10: =IFERROR(Tabla1[[#This Row],[PRECIO $ BOLSA 50KG FOB CDO TUC (IVA INC)]]/Tabla1[[#This Row],[PRECIO REF $ BOLSA 50 KG CACTU (IVA INC)]]-1,"") -> -0.14424591 | AM10: =+Tabla1[[#This Row],[DIF $ PRECIO NETO INDUSTRIA vs Neto TUCUMAN (IVA INC)]]*Tabla1[[#This Row],[Q Bolsas Equivalentes 50kg]] -> -3414433.4 | AN10: =Tabla1[[#This Row],[PRECIO REF $ BOLSA 50 KG CACTU (IVA INC)]]*Tabla1[[#This Row],[Q Bolsas Equivalentes 50kg]] -> 23670920 | AO10: =+Tabla1[[#This Row],[PRECIO $ BOLSA 50KG FOB CDO TUC (IVA INC)]]*Tabla1[[#This Row],[Q Bolsas Equivalentes 50kg]] -> 20256487 | AP10: 0.029 | AQ10: -68 | AS10: 0008-00005546 | AT10: =+Tabla1[[#This Row],[VENTA TOTAL $ (IVA INC) ]]-(SUM(Tabla1[[#This Row],[PENDIENTE DE ENTREGA]:[VALORES COBRADOS]])) -> 0 | AU10: =VLOOKUP(Tabla1[[#This Row],[FECHA OC]],'TIPO DE CAMBIO'!A:B,2,TRUE) -> 1446.301 | AV10: =+Tabla1[[#This Row],[SUBTOTAL]]/Tabla1[[#This Row],[TIPO DE CAMBIO]] -> 11466 | AX10: =IFERROR(Tabla1[[#This Row],[VENTA TOTAL USD A PLAZO EN CLIENTE (SIN IVA)]]*(1+Tabla1[[#This Row],[% IVA ]]),"") -> 11466 | AY10: =+Tabla1[[#This Row],[VENTA TOTAL USD A PLAZO EN CLIENTE (SIN IVA)]]/Tabla1[[#This Row],[KGS]]*1000 -> 315 | AZ10: 0 | BA10: =+Tabla1[[#This Row],[GASTOS FINANCIEROS $ BOLSA 50 KG (IVA INC)]]*20/Tabla1[[#This Row],[TIPO DE CAMBIO]] -> 3.6281738 | BB10: =+Tabla1[[#This Row],[PRECIO POR TN USD EN CLIENTE A PLAZO (SIN IVA)]]+Tabla1[[#This Row],[COSTO USD FLETE /TN (SIN IVA)]]+Tabla1[[#This Row],[COSTO FINANCIERO USD POR BOLSA 50KG (IVA INC)]] -> 318.62817 | BC10: 5
A11: 46143 | B11: 1 | C11: LEDESMA SAAI | D11: =+Tabla1[[#This Row],[FECHA Entrega]] -> 46172.361 | E11: 700000869 | F11: AZÚCAR CRUDO | G11: ENTREGADO | H11: 46172.361 | I11: =732*50 -> 36600 | J11: =0.315*Tabla1[[#This Row],[TIPO DE CAMBIO]] -> 455.58481 | K11: =+J11*I11 -> 16674404 | L11: =IF(Tabla1[[#This Row],[TIPO OPERACIÓN]]="INDUSTRIA",Tabla1[[#This Row],[SUBTOTAL]]*0.21,IF(Tabla1[[#This Row],[TIPO OPERACIÓN]]="GDES CUENTAS",Tabla1[[#This Row],[SUBTOTAL]]*0.21,IF(Tabla1[[#This Row],[TIPO OPERACIÓN]]="TUC CTADO 2","",IF(Tabla1[[#This Row],[TIPO OPERACIÓN]]="EXPO CHILE","",IF(Tabla1[[#This Row],[TIPO OPERACIÓN]]="TUC CTADO 1",Tabla1[[#This Row],[SUBTOTAL]]*0.21,""))))) -> 3501624.9 | M11: =SUM(K11:L11) -> 20176029 | O11: 0 | P11: 0 | Q11: =+Tabla1[[#This Row],[VENTA TOTAL $ (IVA INC) ]]-Tabla1[[#This Row],[PENDIENTE DE COBRO]] -> 20176029 | R11: =+Tabla1[[#This Row],[FECHA FC]]+Tabla1[[#This Row],[PLAZO ENTREGA VALORES]] -> 46051 | S11: =+Tabla1[[#This Row],[FECHA FC]]+Tabla1[[#This Row],[PLAZO PAGO (DIAS)]] -> 46172.361 | T11: =+S11-$U$2 -> -8.6388889 | U11: =+Tabla1[[#This Row],[FECHA OC]]-Tabla1[[#This Row],[FECHA Entrega]] -> -121.36111 | W11: =+Tabla1[[#This Row],[FECHA VTO VALORES]]+7 -> 46179.361 | Y11: 46051 | Z11: =Tabla1[[#This Row],[KGS]]/50 -> 732 | AA11: =IFERROR((IF(Tabla1[[#This Row],[TIPO OPERACIÓN]]="INDUSTRIA",Tabla1[[#This Row],[PRECIO $/ KG A PLAZO EN CLIENTE ( SIN IVA)]]*50*1.21,IF(Tabla1[[#This Row],[TIPO OPERACIÓN]]="TUC CTADO 2",Tabla1[[#This Row],[PRECIO $/ KG A PLAZO EN CLIENTE ( SIN IVA)]]*50,IF(Tabla1[[#This Row],[TIPO OPERACIÓN]]="EXPO CHILE",Tabla1[[#This Row],[PRECIO $/ KG A PLAZO EN CLIENTE ( SIN IVA)]]*50*1,IF(Tabla1[[#This Row],[TIPO OPERACIÓN]]="GDES CUENTAS",Tabla1[[#This Row],[PRECIO $/ KG A PLAZO EN CLIENTE ( SIN IVA)]]*50*1.21,IF(Tabla1[[#This Row],[TIPO OPERACIÓN]]="TUC CTADO 1",Tabla1[[#This Row],[PRECIO $/ KG A PLAZO EN CLIENTE ( SIN IVA)]]*50*1.21,"")))))),"") -> 27562.881 | AB11: =-Tabla1[[#This Row],[COSTO FLETE $ POR BOLSA 5O KG (SIN IVA)]]*1.21-Tabla1[[#This Row],[PRECIO $/ KG A PLAZO EN CLIENTE ( SIN IVA)]]*0.003*1.21*50 -> -0.40864392 | AC11: =SUM(Tabla1[[#This Row],[PRECIO $ BOLSA 50 KG (IVA INC) ]]+Tabla1[[#This Row],[COSTO FLETE $ BOLSA 50 KG (IVA INC)]]) -> 27562.473 | AD11: =-Tabla1[[#This Row],[PRECIO $ BOLSA 50 KG (IVA INC) ]]*(Tabla1[[#This Row],[TASA FINANCIACION MENSUAL]]/365)*Tabla1[[#This Row],[PLAZO ENTREGA VALORES]] -> 265.77204 | AE11: =SUM(Tabla1[[#This Row],[PRECIO $ BOLSA50 KG FOB TUCUMAN A PLAZO (IVA INC)]]+Tabla1[[#This Row],[GASTOS FINANCIEROS $ BOLSA 50 KG (IVA INC)]]) -> 27828.245 | AF11: GRANEL | AG11: RETIRA DE INGENIO | AH11: TUCUMAN | AI11: GDES CUENTAS | AJ11: =IFERROR(IF(Tabla1[[#This Row],[TIPO OPERACIÓN]]="INDUSTRIA",VLOOKUP(Tabla1[[#This Row],[FECHA OC]],'PRECIO CACTU'!A:B,2,FALSE),IF(Tabla1[[#This Row],[TIPO OPERACIÓN]]="GDES CUENTAS",VLOOKUP(Tabla1[[#This Row],[FECHA OC]],'PRECIO CACTU'!A:B,2,FALSE),IF(Tabla1[[#This Row],[TIPO OPERACIÓN]]="EXPO CHILE",VLOOKUP(Tabla1[[#This Row],[FECHA OC]],'PRECIO CACTU'!A:B,2,FALSE)/1.21,IF(Tabla1[[#This Row],[TIPO OPERACIÓN]]="TUC CTADO 2",VLOOKUP(Tabla1[[#This Row],[FECHA OC]],'PRECIO CACTU'!A:B,2,FALSE)/1.21,IF(Tabla1[[#This Row],[TIPO OPERACIÓN]]="TUC CTADO 1",VLOOKUP(Tabla1[[#This Row],[FECHA OC]],'PRECIO CACTU'!A:B,2,FALSE),""))))),"") -> 32515 | AK11: =SUM(Tabla1[[#This Row],[PRECIO $ BOLSA 50KG FOB CDO TUC (IVA INC)]]-Tabla1[[#This Row],[PRECIO REF $ BOLSA 50 KG CACTU (IVA INC)]]) -> -4686.7553 | AL11: =IFERROR(Tabla1[[#This Row],[PRECIO $ BOLSA 50KG FOB CDO TUC (IVA INC)]]/Tabla1[[#This Row],[PRECIO REF $ BOLSA 50 KG CACTU (IVA INC)]]-1,"") -> -0.14414133 | AM11: =+Tabla1[[#This Row],[DIF $ PRECIO NETO INDUSTRIA vs Neto TUCUMAN (IVA INC)]]*Tabla1[[#This Row],[Q Bolsas Equivalentes 50kg]] -> -3430704.9 | AN11: =Tabla1[[#This Row],[PRECIO REF $ BOLSA 50 KG CACTU (IVA INC)]]*Tabla1[[#This Row],[Q Bolsas Equivalentes 50kg]] -> 23800980 | AO11: =+Tabla1[[#This Row],[PRECIO $ BOLSA 50KG FOB CDO TUC (IVA INC)]]*Tabla1[[#This Row],[Q Bolsas Equivalentes 50kg]] -> 20370275 | AP11: 0.029 | AQ11: -68 | AS11: 0008-00005549 | AT11: =+Tabla1[[#This Row],[VENTA TOTAL $ (IVA INC) ]]-(SUM(Tabla1[[#This Row],[PENDIENTE DE ENTREGA]:[VALORES COBRADOS]])) -> 0 | AU11: =VLOOKUP(Tabla1[[#This Row],[FECHA OC]],'TIPO DE CAMBIO'!A:B,2,TRUE) -> 1446.301 | AV11: =+Tabla1[[#This Row],[SUBTOTAL]]/Tabla1[[#This Row],[TIPO DE CAMBIO]] -> 11529 | AX11: =IFERROR(Tabla1[[#This Row],[VENTA TOTAL USD A PLAZO EN CLIENTE (SIN IVA)]]*(1+Tabla1[[#This Row],[% IVA ]]),"") -> 11529 | AY11: =+Tabla1[[#This Row],[VENTA TOTAL USD A PLAZO EN CLIENTE (SIN IVA)]]/Tabla1[[#This Row],[KGS]]*1000 -> 315 | AZ11: 0 | BA11: =+Tabla1[[#This Row],[GASTOS FINANCIEROS $ BOLSA 50 KG (IVA INC)]]*20/Tabla1[[#This Row],[TIPO DE CAMBIO]] -> 3.6751968 | BB11: =+Tabla1[[#This Row],[PRECIO POR TN USD EN CLIENTE A PLAZO (SIN IVA)]]+Tabla1[[#This Row],[COSTO USD FLETE /TN (SIN IVA)]]+Tabla1[[#This Row],[COSTO FINANCIERO USD POR BOLSA 50KG (IVA INC)]] -> 318.6752 | BC11: 5
