Workbook
Name _1_Excel_BuiltIn__FilterDatabase_3_1_1_1_1_1_1_1: "$#REF!.#REF!#REF!:#REF!#REF!"
Name _2Excel_BuiltIn__FilterDatabase_3_1_1_1_1_1_1_1: "$#REF!.#REF!#REF!:#REF!#REF!"
Name Excel_BuiltIn__FilterDatabase_1_1: #REF!
Name Excel_BuiltIn__FilterDatabase_1_1: #REF!
Name Excel_BuiltIn__FilterDatabase_1_1: #REF!
Name Excel_BuiltIn__FilterDatabase_1_1: #REF!
Name Excel_BuiltIn__FilterDatabase_1_1: #REF!
Name Excel_BuiltIn__FilterDatabase_1_1_1: "$#REF!.$AI$1:$AI$65536"
Name Excel_BuiltIn__FilterDatabase_1_1_1_1: "$#REF!.$B$1:$AH$9"
Name Excel_BuiltIn__FilterDatabase_1_1_1_1_1: "$#REF!.$B$1:$P$1"
Name Excel_BuiltIn__FilterDatabase_1_1_1_1_1_1: "$#REF!.$B$1:$E$1"
Name Excel_BuiltIn__FilterDatabase_1_2: "$#REF!.$B$1:$P$1"
Name Excel_BuiltIn__FilterDatabase_2_1: #REF!
Name Excel_BuiltIn__FilterDatabase_2_1: #REF!
Name Excel_BuiltIn__FilterDatabase_2_1: #REF!
Name Excel_BuiltIn__FilterDatabase_2_1: #REF!
Name Excel_BuiltIn__FilterDatabase_2_1: #REF!
Name Excel_BuiltIn__FilterDatabase_2_1_1: "$#REF!.$N$1:$O$1"
Name Excel_BuiltIn__FilterDatabase_3_1: #REF!
Name Excel_BuiltIn__FilterDatabase_3_1: #REF!
Name Excel_BuiltIn__FilterDatabase_3_1: #REF!
Name Excel_BuiltIn__FilterDatabase_3_1: #REF!
Name Excel_BuiltIn__FilterDatabase_3_1: #REF!
Name Excel_BuiltIn__FilterDatabase_3_1_1: "$#REF!.$#REF!$#REF!:$#REF!$#REF!"
Name Excel_BuiltIn__FilterDatabase_3_1_1_1: "$#REF!.#REF!#REF!:#REF!#REF!"
Name Excel_BuiltIn__FilterDatabase_3_1_1_1_1: "$#REF!.$B$1:$P$1"
Name Excel_BuiltIn__FilterDatabase_3_1_1_1_1_1: "$#REF!.#REF!#REF!:#REF!#REF!"
Name Excel_BuiltIn__FilterDatabase_3_1_1_1_1_1_1: "$#REF!.$B$1:$P$1"
Name Excel_BuiltIn__FilterDatabase_4: "$#REF!.$B$1:$E$1"
Name Excel_BuiltIn_Print_Area_2_1: #REF!
Name Excel_BuiltIn_Print_Area_2_1: #REF!
Name Excel_BuiltIn_Print_Area_2_1: #REF!
Name Excel_BuiltIn_Print_Area_2_1: #REF!
Name Excel_BuiltIn_Print_Area_2_1: #REF!
Name Excel_BuiltIn_Print_Area_3: "$#REF!.$B$1:$P$1"
Name Excel_BuiltIn_Print_Area_7: #REF!
Name Excel_BuiltIn_Print_Area_7: #REF!
Name Excel_BuiltIn_Print_Area_7: #REF!
Name Excel_BuiltIn_Print_Area_7: #REF!
Name Excel_BuiltIn_Print_Area_7: #REF!

Sheet 1°Q 01 V1 CAMPO
W2: Cat. | X2: Basico | Y2: No Rem | Z2: Basico Conf. | AA2: Escalafon | AB2: escalafon NR | AC2: Escalafon Conf.
Q4: =+X4 -> 17212.41 | R4: =+Q4*155% -> 26679.235 | T4: =+R4+S4 -> 26679.235 | U4: =+U114 -> 296 | V4: =+Y4/X4*100 -> 138.91891 | W4: Q01 | X4: 17212.41 | Y4: =+Z4-X4 -> 23911.292 | Z4: 41123.702 | AA4: =+X4*0.3 -> 5163.723 | AB4: =+Y4*0.3 -> 7173.3876 | AC4: =+AA4+AB4 -> 12337.111
U5: =+Q4*218.75% -> 37652.147 | W5: Q02 | X5: 18004.12 | Y5: =+Z5-X5 -> 25011.121 | Z5: 43015.241 | AA5: =+X5*0.3 -> 5401.236 | AB5: =+Y5*0.3 -> 7503.3363 | AC5: =+AA5+AB5 -> 12904.572
Q6: =+Q4+R4 -> 43891.645 | R6: =+T4+Q4 -> 43891.645 | W6: Q03 | X6: 18329.51 | Y6: =+Z6-X6 -> 25463.165 | Z6: 43792.675 | AA6: =+X6*0.3 -> 5498.853 | AB6: =+Y6*0.3 -> 7638.9495 | AC6: =+AA6+AB6 -> 13137.802
R7: =+R6/Q6 -> 1 | W7: Q04 | X7: 19002.42 | Y7: =+Z7-X7 -> 26397.964 | Z7: 45400.384 | AA7: =+X7*0.3 -> 5700.726 | AB7: =+Y7*0.3 -> 7919.3891 | AC7: =+AA7+AB7 -> 13620.115
W8: Q05 | X8: 19415.57 | Y8: =+Z8-X8 -> 26971.888 | Z8: 46387.458 | AA8: =+X8*0.3 -> 5824.671 | AB8: =+Y8*0.3 -> 8091.5664 | AC8: =+AA8+AB8 -> 13916.237
W9: Q06 | X9: 20104.08 | Y9: =+Z9-X9 -> 27928.38 | Z9: 48032.46 | AA9: =+X9*0.3 -> 6031.224 | AB9: =+Y9*0.3 -> 8378.5141 | AC9: =+AA9+AB9 -> 14409.738
W10: Q07 | X10: 20964.69 | Y10: =+Z10-X10 -> 29123.932 | Z10: 50088.622 | AA10: =+X10*0.3 -> 6289.407 | AB10: =+Y10*0.3 -> 8737.1797 | AC10: =+AA10+AB10 -> 15026.587
W11: Q08 | X11: 21549.89 | Y11: =+Z11-X11 -> 29936.867 | Z11: 51486.757 | AA11: =+X11*0.3 -> 6464.967 | AB11: =+Y11*0.3 -> 8981.06 | AC11: =+AA11+AB11 -> 15446.027 | CC11: TOPE
A12: La Corona | CC12: =3645898/2 -> 1822949
X14: =+Y4/X4 -> 1.3891891 | BM14: 24365.48 | BS14: 1022 | BT14: 1023 | BU14: 1025 | BV14: 1026 | CL14: REINTMED | CO14: AYUMED
K15: LIQ | N15: 46037 | T15: 1003 | V15: 1061 | W15: 1009 | Y15: 1030 | Z15: 1072 | AB15: 1065 | AC15: 1066 | AD15: 1073 | AE15: 1304 | AH15: 1041 | AI15: 1007 | AK15: 1018 | AL15: 1019 | AM15: 1022 | AN15: 1023 | AO15: 1025 | AP15: 1026 | AQ15: 1108 | AR15: 1109 | AS15: 1110 | AT15: 1201 | AV15: 30 | AX15: 30 | AY15: 30 | AZ15: 0.01 | BF15: 1.5 | BG15: 2 | BM15: 19290.416 | BS15: 67.134 | BT15: 52.674 | BU15: 1.6226 | BV15: 2.5053 | BW15: 3.1374 | CC15: 0.11 | CD15: 0.03 | CE15: 0.03 | CG15: 0.03 | CL15: 1201 | CM15: 1220 | CN15: 2803 | CP15: 2895 | CQ15: 2896
A16: LEG SIS | B16: Leg. | C16: Sector | D16: Empleado | E16: sind | F16: OS FOTIA | G16: OSPAT | H16: Edad + 60 | I16: Pensión s/ Rem | J16: Pensión s/ No Rem | K16: Cat. I | L16: Cat. II | M16: Dif de Cat. | N16: Antigüedad | O16: Años reconocidos | P16: Escalafon | Q16: Básico Rem | R16: Basico No Rem | S16: Titulo | T16: Jornales | U16: Jornales a liq | V16: Dias de Enfermedad | W16: Feriado | X16: Feriado Trabajado | Y16: ART | Z16: Retiro Anticipado | AA16: HS Simples | AB16: Faltas c/ aviso | AC16: Faltas s/ aviso | AD16: Llegada tarde | AE16: Dias de Susp | AF16: Lic c/ Goce | AG16: Lic s/ Goce | AH16: Altura | AI16: Destajo | AJ16: Donacion de sangre | AK16: HS 50% | AL16: HS 100% | AM16: Dest.P/Bls $ 67.134 | AN16: Dest.P/Bls. $ 52.674 | AO16: Dest.P/Bls $ 1,6226 | AP16: Dest.P/Bls $ 2.5053 | AQ16: Dest.P/Bls $3.1374 | AR16: Presentismo | AS16: Premio Asist. | AT16: Reint de Mec | AU16: Total Jornales | AV16: Sueldo Basico | AW16: Dias de Enfermedad | AX16: Feriado | AY16: Feriado Trabajado | AZ16: ART | BA16: Retiro Anticipado | BB16: HS Simples | BC16: Faltas c/ aviso | BD16: Faltas s/ aviso | BE16: Llegada tarde | BF16: Dias de Susp | BG16: Lic c/ Goce | BH16: Lic s/ Goce | BI16: Destajo | BJ16: Altura | BK16: Donacion de Sangre | BL16: Escalafon | BM16: Titulo | BN16: Presentismo | BO16: Dedicación (clc) | BP16: Dif. De Cat. | BQ16: HS 50% | BR16: HS 100% | BS16: Dest.P/Bls $ 67.134 | BT16: Dest.P/Bls. $ 52.674 | BU16: Dest.P/Bls $ 1,6226 | BV16: Dest.P/Bls $ 2.5053 | BW16: Dest.P/Bls $3.1374 | BX16: 1200 - Dif + VsX/ Importe Concepto | BY16: Ajuste 1ra. Qna. | BZ16: Ajuste 2da. Qna. | CA16: NR > 60 | CB16: Bruto Total | CC16: Jubilación | CD16: Ley 19.032 | CE16: Obra social | CF16: Sindicato | CG16: Adic. De O.S. | CH16: Club Azucarera Arg | CI16: No Remunerativo | CJ16: O.S. NR | CK16: Sindicato NR | CL16: Reintegro de Medicamentos | CM16: Tickey Canasta | CN16: Fotia Ayuda Medica | CO16: Feia Ayuda Medica | CP16: Socorro Social Cuota | CQ16: Socorro Social Ap | CR16: Dif+VsX | CS16: Embargos | CT16: Pensiones | CU16: Club Azucarera | CV16: Fotia Ayuda Econ. | CW16: Colecta | CX16: Coleta II | CY16: Anticipos | CZ16: Pensión s/ Rem | DA16: Pensión s/ No Rem | DB16: Neto | DC16: Neto | DD16: Sistema | DE16: Diferencia
A18: =500000+B18 -> 509831 | B18: 9831 | C18: CAMPO | D18: ABREGU CRISTIAN ARIEL | E18: FOTIA | F18: 0 | J18: 0.25 | K18: Q02 | O18: 0 | P18: =+VLOOKUP(K18,$W$4:$AC$11,5,0) -> 5401.236 | Q18: =+VLOOKUP(K18,$W$4:$Z$11,2,0) -> 18004.12 | R18: =+VLOOKUP(K18,$W$4:$Y$11,3,0) -> 25011.121 | T18: 1 | U18: =+T18 -> 1 | V18: 0 | W18: 0 | X18: 0 | Y18: 0 | Z18: 0 | AA18: 0 | AB18: 0 | AC18: 0 | AD18: 0 | AE18: 0 | AF18: 0 | AG18: 0 | AH18: 0 | AI18: 0 | AJ18: 0 | AK18: 0 | AL18: 0 | AM18: 0 | AN18: 0 | AO18: 0 | AP18: 0 | AQ18: 0 | AR18: 0 | AS18: 0 | AT18: 0 | AU18: =+U18+V18+W18+Y18-Z18-AB18-AC18-AD18-AE18+AF18-AG18+AJ18 -> 1 | AV18: =+Q18*U18 -> 18004.12 | AW18: =+Q18*V18 -> 0 | AX18: =+Q18*W18 -> 0 | AY18: =+Q18*X18 -> 0 | AZ18: =+(Q18*1.0833*Y18)+((P18*O18)/25*Y18) -> 0 | BA18: =-Q18/8*Z18 -> 0 | BB18: =+Q18/8*AA18 -> 0 | BC18: =-Q18*AB18 -> 0 | BD18: =-Q18*AC18 -> 0 | BE18: =-Q18/8*AD18 -> 0 | BF18: =-Q18*AE18 -> 0 | BG18: =+Q18*AF18 -> 0 | BH18: =-Q18*AG18 -> 0 | BI18: =+Q18*AI18 -> 0 | BJ18: =+Q18*AH18 -> 0 | BK18: =+Q18*AJ18 -> 0 | BL18: =+(P18*O18)/25*(U18+V18+W18-Z18-AB18-AC18-AD18-AE18+AF18-AG18) -> 0 | BM18: =+$BM$15/25*(U18+V18+Y18+AF18+AH18+AI18)*0 -> 0 | BP18: =+M18*(AU18+AH18+AI18) -> 0 | BS18: =+$BS$15*AM18 -> 0 | BT18: =+$BT$15*AN18 -> 0 | BU18: =+$BU$15*AO18 -> 0 | BV18: =+$BV$15*AP18 -> 0 | CA18: =+IF(H18>59,+SUM(AV18:BX18)*138.92%,0) -> 0 | CB18: =SUM(AV18:CA18) -> 18004.12 | CE18: =-MIN(CB18,$CC$12)*$CD$15 -> -540.1236 | CF18: =-IF(E18="FOTIA",(CB18-AZ18)*1%,(CB18-AZ18)*1.5%) -> -180.0412 | CI18: =+IF(H18>59,0,(CB18*138.92%)) -> 25011.324 | CJ18: =-MIN(CI18,$CC$12)*$CD$15 -> -750.33971 | CK18: =-IF(E18="FOTIA",(CI18-BE18)*1%,(CI18-BE18)*1.5%) -> -250.11324 | CL18: 0 | CN18: 0 | CZ18: =-SUM(CB18+CC18+CD18+CE18+CF18)*I18 -> 0 | DA18: =-SUM(CB18+CC18+CD18+CE18+CF18+CI18+CJ18+CK18)*J18 -> -10323.706 | DB18: =SUM(CB18:DA18) -> 30971.119 | DC18: =ROUND(DB18,0) -> 30971 | DE18: =+DD18-DC18 -> -30971
A19: =500000+B19 -> 509850 | B19: 9850 | C19: CAMPO | D19: ALEGRE FRANCO RODRIGO | E19: FOTIA | F19: 0 | K19: Q02 | O19: 0 | P19: =+VLOOKUP(K19,$W$4:$AC$11,5,0) -> 5401.236 | Q19: =+VLOOKUP(K19,$W$4:$Z$11,2,0) -> 18004.12 | R19: =+VLOOKUP(K19,$W$4:$Y$11,3,0) -> 25011.121 | T19: 0 | U19: =+T19 -> 0 | V19: 0 | W19: 0 | X19: 0 | Y19: 0 | Z19: 0 | AA19: 0 | AB19: 0 | AC19: 0 | AD19: 0 | AE19: 0 | AF19: 0 | AG19: 0 | AH19: 0 | AI19: 0 | AJ19: 0 | AK19: 0 | AL19: 0 | AM19: 0 | AN19: 0 | AO19: 0 | AP19: 0 | AQ19: 0 | AR19: 0 | AS19: 0 | AT19: 0 | AU19: =+U19+V19+W19+Y19-Z19-AB19-AC19-AD19-AE19+AF19-AG19+AJ19 -> 0 | AV19: =+Q19*U19 -> 0 | AW19: =+Q19*V19 -> 0 | AX19: =+Q19*W19 -> 0 | AY19: =+Q19*X19 -> 0 | AZ19: =+(Q19*1.0833*Y19)+((P19*O19)/25*Y19) -> 0 | BA19: =-Q19/8*Z19 -> 0 | BB19: =+Q19/8*AA19 -> 0 | BC19: =-Q19*AB19 -> 0 | BD19: =-Q19*AC19 -> 0 | BE19: =-Q19/8*AD19 -> 0 | BF19: =-Q19*AE19 -> 0 | BG19: =+Q19*AF19 -> 0 | BH19: =-Q19*AG19 -> 0 | BI19: =+Q19*AI19 -> 0 | BJ19: =+Q19*AH19 -> 0 | BK19: =+Q19*AJ19 -> 0 | BL19: =+(P19*O19)/25*(U19+V19+W19-Z19-AB19-AC19-AD19-AE19+AF19-AG19) -> 0 | BM19: =+$BM$15/25*(U19+V19+Y19+AF19+AH19+AI19)*0 -> 0 | BP19: =+M19*(AU19+AH19+AI19) -> 0 | BS19: =+$BS$15*AM19 -> 0 | BT19: =+$BT$15*AN19 -> 0 | BU19: =+$BU$15*AO19 -> 0 | BV19: =+$BV$15*AP19 -> 0 | CA19: =+IF(H19>59,+SUM(AV19:BX19)*138.92%,0) -> 0 | CB19: =SUM(AV19:CA19) -> 0 | CE19: =-MIN(CB19,$CC$12)*$CD$15 -> 0 | CF19: =-IF(E19="FOTIA",(CB19-AZ19)*1%,(CB19-AZ19)*1.5%) -> 0 | CI19: =+IF(H19>59,0,(CB19*138.92%)) -> 0 | CJ19: =-MIN(CI19,$CC$12)*$CD$15 -> 0 | CK19: =-IF(E19="FOTIA",(CI19-BE19)*1%,(CI19-BE19)*1.5%) -> 0 | CL19: 0 | CN19: 0 | CZ19: =-SUM(CB19+CC19+CD19+CE19+CF19)*I19 -> 0 | DA19: =-SUM(CB19+CC19+CD19+CE19+CF19+CI19+CJ19+CK19)*J19 -> 0 | DB19: =SUM(CB19:DA19) -> 0 | DC19: =ROUND(DB19,0) -> 0 | DE19: =+DD19-DC19 -> 0
A20: =500000+B20 -> 509743 | B20: 9743 | C20: CAMPO | D20: ALEMAN FELIX OMAR | E20: FOTIA | F20: 0 | H20: 63 | K20: Q06 | O20: 3 | P20: =+VLOOKUP(K20,$W$4:$AC$11,5,0) -> 6031.224 | Q20: =+VLOOKUP(K20,$W$4:$Z$11,2,0) -> 20104.08 | R20: =+VLOOKUP(K20,$W$4:$Y$11,3,0) -> 27928.38 | T20: 0 | U20: =+T20 -> 0 | V20: 0 | W20: 0 | X20: 0 | Y20: 0 | Z20: 0 | AA20: 0 | AB20: 0 | AC20: 0 | AD20: 0 | AE20: 0 | AF20: 0 | AG20: 0 | AH20: 0 | AI20: 0 | AJ20: 0 | AK20: 0 | AL20: 0 | AM20: 0 | AN20: 0 | AO20: 0 | AP20: 0 | AQ20: 0 | AR20: 0 | AS20: 0 | AT20: 0 | AU20: =+U20+V20+W20+Y20-Z20-AB20-AC20-AD20-AE20+AF20-AG20+AJ20 -> 0 | AV20: =+Q20*U20 -> 0 | AW20: =+Q20*V20 -> 0 | AX20: =+Q20*W20 -> 0 | AY20: =+Q20*X20 -> 0 | AZ20: =+(Q20*1.0833*Y20)+((P20*O20)/25*Y20) -> 0 | BA20: =-Q20/8*Z20 -> 0 | BB20: =+Q20/8*AA20 -> 0 | BC20: =-Q20*AB20 -> 0 | BD20: =-Q20*AC20 -> 0 | BE20: =-Q20/8*AD20 -> 0 | BF20: =-Q20*AE20 -> 0 | BG20: =+Q20*AF20 -> 0 | BH20: =-Q20*AG20 -> 0 | BI20: =+Q20*AI20 -> 0 | BJ20: =+Q20*AH20 -> 0 | BK20: =+Q20*AJ20 -> 0 | BL20: =+(P20*O20)/25*(U20+V20+W20-Z20-AB20-AC20-AD20-AE20+AF20-AG20) -> 0 | BM20: =+$BM$15/25*(U20+V20+Y20+AF20+AH20+AI20)*0 -> 0 | BP20: =+M20*(AU20+AH20+AI20) -> 0 | BS20: =+$BS$15*AM20 -> 0 | BT20: =+$BT$15*AN20 -> 0 | BU20: =+$BU$15*AO20 -> 0 | BV20: =+$BV$15*AP20 -> 0 | CA20: =+IF(H20>59,+SUM(AV20:BX20)*138.92%,0) -> 0 | CB20: =SUM(AV20:CA20) -> 0 | CE20: =-MIN(CB20,$CC$12)*$CD$15 -> 0 | CF20: =-IF(E20="FOTIA",(CB20-AZ20)*1%,(CB20-AZ20)*1.5%) -> 0 | CI20: =+IF(H20>59,0,(CB20*138.92%)) -> 0 | CJ20: =-MIN(CI20,$CC$12)*$CD$15 -> 0 | CK20: =-IF(E20="FOTIA",(CI20-BE20)*1%,(CI20-BE20)*1.5%) -> 0 | CL20: 0 | CN20: 0 | CZ20: =-SUM(CB20+CC20+CD20+CE20+CF20)*I20 -> 0 | DA20: =-SUM(CB20+CC20+CD20+CE20+CF20+CI20+CJ20+CK20)*J20 -> 0 | DB20: =SUM(CB20:DA20) -> 0 | DC20: =ROUND(DB20,0) -> 0 | DE20: =+DD20-DC20 -> 0
A21: =500000+B21 -> 509759 | B21: 9759 | C21: CAMPO | D21: ARAGON ADRIAN ALEJANDRO | E21: FOTIA | F21: 0 | K21: Q04 | O21: 3 | P21: =+VLOOKUP(K21,$W$4:$AC$11,5,0) -> 5700.726 | Q21: =+VLOOKUP(K21,$W$4:$Z$11,2,0) -> 19002.42 | R21: =+VLOOKUP(K21,$W$4:$Y$11,3,0) -> 26397.964 | T21: 6 | U21: =+T21 -> 6 | V21: 0 | W21: 0 | X21: 0 | Y21: 0 | Z21: 0 | AA21: 0 | AB21: 0 | AC21: 0 | AD21: 0 | AE21: 0 | AF21: 0 | AG21: 0 | AH21: 0 | AI21: 0 | AJ21: 0 | AK21: 0 | AL21: 0 | AM21: 0 | AN21: 0 | AO21: 0 | AP21: 0 | AQ21: 0 | AR21: 0 | AS21: 0 | AT21: 0 | AU21: =+U21+V21+W21+Y21-Z21-AB21-AC21-AD21-AE21+AF21-AG21+AJ21 -> 6 | AV21: =+Q21*U21 -> 114014.52 | AW21: =+Q21*V21 -> 0 | AX21: =+Q21*W21 -> 0 | AY21: =+Q21*X21 -> 0 | AZ21: =+(Q21*1.0833*Y21)+((P21*O21)/25*Y21) -> 0 | BA21: =-Q21/8*Z21 -> 0 | BB21: =+Q21/8*AA21 -> 0 | BC21: =-Q21*AB21 -> 0 | BD21: =-Q21*AC21 -> 0 | BE21: =-Q21/8*AD21 -> 0 | BF21: =-Q21*AE21 -> 0 | BG21: =+Q21*AF21 -> 0 | BH21: =-Q21*AG21 -> 0 | BI21: =+Q21*AI21 -> 0 | BJ21: =+Q21*AH21 -> 0 | BK21: =+Q21*AJ21 -> 0 | BL21: =+(P21*O21)/25*(U21+V21+W21-Z21-AB21-AC21-AD21-AE21+AF21-AG21) -> 4104.5227 | BM21: =+$BM$15/25*(U21+V21+Y21+AF21+AH21+AI21)*0 -> 0 | BP21: =+M21*(AU21+AH21+AI21) -> 0 | BS21: =+$BS$15*AM21 -> 0 | BT21: =+$BT$15*AN21 -> 0 | BU21: =+$BU$15*AO21 -> 0 | BV21: =+$BV$15*AP21 -> 0 | CA21: =+IF(H21>59,+SUM(AV21:BX21)*138.92%,0) -> 0 | CB21: =SUM(AV21:CA21) -> 118119.04 | CE21: =-MIN(CB21,$CC$12)*$CD$15 -> -3543.5713 | CF21: =-IF(E21="FOTIA",(CB21-AZ21)*1%,(CB21-AZ21)*1.5%) -> -1181.1904 | CI21: =+IF(H21>59,0,(CB21*138.92%)) -> 164090.97 | CJ21: =-MIN(CI21,$CC$12)*$CD$15 -> -4922.7292 | CK21: =-IF(E21="FOTIA",(CI21-BE21)*1%,(CI21-BE21)*1.5%) -> -1640.9097 | CL21: 0 | CN21: 0 | CZ21: =-SUM(CB21+CC21+CD21+CE21+CF21)*I21 -> 0 | DA21: =-SUM(CB21+CC21+CD21+CE21+CF21+CI21+CJ21+CK21)*J21 -> 0 | DB21: =SUM(CB21:DA21) -> 270921.62 | DC21: =ROUND(DB21,0) -> 270922 | DE21: =+DD21-DC21 -> -270922
A22: =500000+B22 -> 509746 | B22: 9746 | C22: CAMPO | D22: ARAGON JOSE ADRIAN | E22: FOTIA | F22: 0 | K22: Q04 | O22: 2 | P22: =+VLOOKUP(K22,$W$4:$AC$11,5,0) -> 5700.726 | Q22: =+VLOOKUP(K22,$W$4:$Z$11,2,0) -> 19002.42 | R22: =+VLOOKUP(K22,$W$4:$Y$11,3,0) -> 26397.964 | T22: 6 | U22: =+T22 -> 6 | V22: 0 | W22: 1 | X22: 0 | Y22: 0 | Z22: 0 | AA22: 0 | AB22: 0 | AC22: 0 | AD22: 0 | AE22: 0 | AF22: 0 | AG22: 0 | AH22: 0 | AI22: 0 | AJ22: 0 | AK22: 0 | AL22: 0 | AM22: 0 | AN22: 0 | AO22: 0 | AP22: 0 | AQ22: 0 | AR22: 0 | AS22: 0 | AT22: 0 | AU22: =+U22+V22+W22+Y22-Z22-AB22-AC22-AD22-AE22+AF22-AG22+AJ22 -> 7 | AV22: =+Q22*U22 -> 114014.52 | AW22: =+Q22*V22 -> 0 | AX22: =+Q22*W22 -> 19002.42 | AY22: =+Q22*X22 -> 0 | AZ22: =+(Q22*1.0833*Y22)+((P22*O22)/25*Y22) -> 0 | BA22: =-Q22/8*Z22 -> 0 | BB22: =+Q22/8*AA22 -> 0 | BC22: =-Q22*AB22 -> 0 | BD22: =-Q22*AC22 -> 0 | BE22: =-Q22/8*AD22 -> 0 | BF22: =-Q22*AE22 -> 0 | BG22: =+Q22*AF22 -> 0 | BH22: =-Q22*AG22 -> 0 | BI22: =+Q22*AI22 -> 0 | BJ22: =+Q22*AH22 -> 0 | BK22: =+Q22*AJ22 -> 0 | BL22: =+(P22*O22)/25*(U22+V22+W22-Z22-AB22-AC22-AD22-AE22+AF22-AG22) -> 3192.4066 | BM22: =+$BM$15/25*(U22+V22+Y22+AF22+AH22+AI22)*0 -> 0 | BP22: =+M22*(AU22+AH22+AI22) -> 0 | BS22: =+$BS$15*AM22 -> 0 | BT22: =+$BT$15*AN22 -> 0 | BU22: =+$BU$15*AO22 -> 0 | BV22: =+$BV$15*AP22 -> 0 | CA22: =+IF(H22>59,+SUM(AV22:BX22)*138.92%,0) -> 0 | CB22: =SUM(AV22:CA22) -> 136209.35 | CE22: =-MIN(CB22,$CC$12)*$CD$15 -> -4086.2804 | CF22: =-IF(E22="FOTIA",(CB22-AZ22)*1%,(CB22-AZ22)*1.5%) -> -1362.0935 | CI22: =+IF(H22>59,0,(CB22*138.92%)) -> 189222.02 | CJ22: =-MIN(CI22,$CC$12)*$CD$15 -> -5676.6607 | CK22: =-IF(E22="FOTIA",(CI22-BE22)*1%,(CI22-BE22)*1.5%) -> -1892.2202 | CL22: 0 | CN22: 0 | CZ22: =-SUM(CB22+CC22+CD22+CE22+CF22)*I22 -> 0 | DA22: =-SUM(CB22+CC22+CD22+CE22+CF22+CI22+CJ22+CK22)*J22 -> 0 | DB22: =SUM(CB22:DA22) -> 312414.12 | DC22: =ROUND(DB22,0) -> 312414 | DE22: =+DD22-DC22 -> -312414
A23: =500000+B23 -> 509639 | B23: 9639 | C23: CAMPO | D23: ARAGON VICTOR DANIEL | E23: FEIA | F23: 3 | K23: Q04 | O23: 10 | P23: =+VLOOKUP(K23,$W$4:$AC$11,5,0) -> 5700.726 | Q23: =+VLOOKUP(K23,$W$4:$Z$11,2,0) -> 19002.42 | R23: =+VLOOKUP(K23,$W$4:$Y$11,3,0) -> 26397.964 | T23: 0 | U23: =+T23 -> 0 | V23: 0 | W23: 0 | X23: 0 | Y23: 0 | Z23: 0 | AA23: 0 | AB23: 0 | AC23: 0 | AD23: 0 | AE23: 0 | AF23: 0 | AG23: 0 | AH23: 0 | AI23: 0 | AJ23: 0 | AK23: 0 | AL23: 0 | AM23: 0 | AN23: 0 | AO23: 0 | AP23: 0 | AQ23: 0 | AR23: 0 | AS23: 0 | AT23: 0 | AU23: =+U23+V23+W23+Y23-Z23-AB23-AC23-AD23-AE23+AF23-AG23+AJ23 -> 0 | AV23: =+Q23*U23 -> 0 | AW23: =+Q23*V23 -> 0 | AX23: =+Q23*W23 -> 0 | AY23: =+Q23*X23 -> 0 | AZ23: =+(Q23*1.0833*Y23)+((P23*O23)/25*Y23) -> 0 | BA23: =-Q23/8*Z23 -> 0 | BB23: =+Q23/8*AA23 -> 0 | BC23: =-Q23*AB23 -> 0 | BD23: =-Q23*AC23 -> 0 | BE23: =-Q23/8*AD23 -> 0 | BF23: =-Q23*AE23 -> 0 | BG23: =+Q23*AF23 -> 0 | BH23: =-Q23*AG23 -> 0 | BI23: =+Q23*AI23 -> 0 | BJ23: =+Q23*AH23 -> 0 | BK23: =+Q23*AJ23 -> 0 | BL23: =+(P23*O23)/25*(U23+V23+W23-Z23-AB23-AC23-AD23-AE23+AF23-AG23) -> 0 | BM23: =+$BM$15/25*(U23+V23+Y23+AF23+AH23+AI23)*0 -> 0 | BP23: =+M23*(AU23+AH23+AI23) -> 0 | BS23: =+$BS$15*AM23 -> 0 | BT23: =+$BT$15*AN23 -> 0 | BU23: =+$BU$15*AO23 -> 0 | BV23: =+$BV$15*AP23 -> 0 | CA23: =+IF(H23>59,+SUM(AV23:BX23)*138.92%,0) -> 0 | CB23: =SUM(AV23:CA23) -> 0 | CE23: =-MIN(CB23,$CC$12)*$CD$15 -> 0 | CF23: =-IF(E23="FOTIA",(CB23-AZ23)*1%,(CB23-AZ23)*1.5%) -> 0 | CI23: =+IF(H23>59,0,(CB23*138.92%)) -> 0 | CJ23: =-MIN(CI23,$CC$12)*$CD$15 -> 0 | CK23: =-IF(E23="FOTIA",(CI23-BE23)*1%,(CI23-BE23)*1.5%) -> 0 | CL23: 0 | CN23: 0 | CZ23: =-SUM(CB23+CC23+CD23+CE23+CF23)*I23 -> 0 | DA23: =-SUM(CB23+CC23+CD23+CE23+CF23+CI23+CJ23+CK23)*J23 -> 0 | DB23: =SUM(CB23:DA23) -> 0 | DC23: =ROUND(DB23,0) -> 0 | DE23: =+DD23-DC23 -> 0
A24: =500000+B24 -> 509652 | B24: 9652 | C24: CAMPO | D24: ARAUJO RODRIGO SEBASTIAN | E24: FEIA | F24: 3 | K24: Q04 | O24: 7 | P24: =+VLOOKUP(K24,$W$4:$AC$11,5,0) -> 5700.726 | Q24: =+VLOOKUP(K24,$W$4:$Z$11,2,0) -> 19002.42 | R24: =+VLOOKUP(K24,$W$4:$Y$11,3,0) -> 26397.964 | T24: 6 | U24: =+T24 -> 6 | V24: 0 | W24: 1 | X24: 0 | Y24: 0 | Z24: 0 | AA24: 0 | AB24: 0 | AC24: 0 | AD24: 0 | AE24: 0 | AF24: 0 | AG24: 0 | AH24: 0 | AI24: 0 | AJ24: 0 | AK24: 0 | AL24: 0 | AM24: 0 | AN24: 0 | AO24: 0 | AP24: 0 | AQ24: 0 | AR24: 0 | AS24: 0 | AT24: 0 | AU24: =+U24+V24+W24+Y24-Z24-AB24-AC24-AD24-AE24+AF24-AG24+AJ24 -> 7 | AV24: =+Q24*U24 -> 114014.52 | AW24: =+Q24*V24 -> 0 | AX24: =+Q24*W24 -> 19002.42 | AY24: =+Q24*X24 -> 0 | AZ24: =+(Q24*1.0833*Y24)+((P24*O24)/25*Y24) -> 0 | BA24: =-Q24/8*Z24 -> 0 | BB24: =+Q24/8*AA24 -> 0 | BC24: =-Q24*AB24 -> 0 | BD24: =-Q24*AC24 -> 0 | BE24: =-Q24/8*AD24 -> 0 | BF24: =-Q24*AE24 -> 0 | BG24: =+Q24*AF24 -> 0 | BH24: =-Q24*AG24 -> 0 | BI24: =+Q24*AI24 -> 0 | BJ24: =+Q24*AH24 -> 0 | BK24: =+Q24*AJ24 -> 0 | BL24: =+(P24*O24)/25*(U24+V24+W24-Z24-AB24-AC24-AD24-AE24+AF24-AG24) -> 11173.423 | BM24: =+$BM$15/25*(U24+V24+Y24+AF24+AH24+AI24)*0 -> 0 | BP24: =+M24*(AU24+AH24+AI24) -> 0 | BS24: =+$BS$15*AM24 -> 0 | BT24: =+$BT$15*AN24 -> 0 | BU24: =+$BU$15*AO24 -> 0 | BV24: =+$BV$15*AP24 -> 0 | CA24: =+IF(H24>59,+SUM(AV24:BX24)*138.92%,0) -> 0 | CB24: =SUM(AV24:CA24) -> 144190.36 | CE24: =-MIN(CB24,$CC$12)*$CD$15 -> -4325.7109 | CF24: =-IF(E24="FOTIA",(CB24-AZ24)*1%,(CB24-AZ24)*1.5%) -> -2162.8554 | CI24: =+IF(H24>59,0,(CB24*138.92%)) -> 200309.25 | CJ24: =-MIN(CI24,$CC$12)*$CD$15 -> -6009.2776 | CK24: =-IF(E24="FOTIA",(CI24-BE24)*1%,(CI24-BE24)*1.5%) -> -3004.6388 | CL24: 0 | CN24: 0 | CZ24: =-SUM(CB24+CC24+CD24+CE24+CF24)*I24 -> 0 | DA24: =-SUM(CB24+CC24+CD24+CE24+CF24+CI24+CJ24+CK24)*J24 -> 0 | DB24: =SUM(CB24:DA24) -> 328997.13 | DC24: =ROUND(DB24,0) -> 328997 | DE24: =+DD24-DC24 -> -328997
A25: =500000+B25 -> 509833 | B25: 9833 | C25: CAMPO | D25: ARCE MARIO ALBERTO | E25: FOTIA | F25: 0 | K25: Q02 | O25: 0 | P25: =+VLOOKUP(K25,$W$4:$AC$11,5,0) -> 5401.236 | Q25: =+VLOOKUP(K25,$W$4:$Z$11,2,0) -> 18004.12 | R25: =+VLOOKUP(K25,$W$4:$Y$11,3,0) -> 25011.121 | T25: 11 | U25: =+T25 -> 11 | V25: 0 | W25: 1 | X25: 0 | Y25: 0 | Z25: 0 | AA25: 0 | AB25: 0 | AC25: 0 | AD25: 0 | AE25: 0 | AF25: 0 | AG25: 0 | AH25: 0 | AI25: 0 | AJ25: 0 | AK25: 0 | AL25: 0 | AM25: 0 | AN25: 0 | AO25: 0 | AP25: 0 | AQ25: 0 | AR25: 0 | AS25: 0 | AT25: 0 | AU25: =+U25+V25+W25+Y25-Z25-AB25-AC25-AD25-AE25+AF25-AG25+AJ25 -> 12 | AV25: =+Q25*U25 -> 198045.32 | AW25: =+Q25*V25 -> 0 | AX25: =+Q25*W25 -> 18004.12 | AY25: =+Q25*X25 -> 0 | AZ25: =+(Q25*1.0833*Y25)+((P25*O25)/25*Y25) -> 0 | BA25: =-Q25/8*Z25 -> 0 | BB25: =+Q25/8*AA25 -> 0 | BC25: =-Q25*AB25 -> 0 | BD25: =-Q25*AC25 -> 0 | BE25: =-Q25/8*AD25 -> 0 | BF25: =-Q25*AE25 -> 0 | BG25: =+Q25*AF25 -> 0 | BH25: =-Q25*AG25 -> 0 | BI25: =+Q25*AI25 -> 0 | BJ25: =+Q25*AH25 -> 0 | BK25: =+Q25*AJ25 -> 0 | BL25: =+(P25*O25)/25*(U25+V25+W25-Z25-AB25-AC25-AD25-AE25+AF25-AG25) -> 0 | BM25: =+$BM$15/25*(U25+V25+Y25+AF25+AH25+AI25)*0 -> 0 | BP25: =+M25*(AU25+AH25+AI25) -> 0 | BS25: =+$BS$15*AM25 -> 0 | BT25: =+$BT$15*AN25 -> 0 | BU25: =+$BU$15*AO25 -> 0 | BV25: =+$BV$15*AP25 -> 0 | CA25: =+IF(H25>59,+SUM(AV25:BX25)*138.92%,0) -> 0 | CB25: =SUM(AV25:CA25) -> 216049.44 | CE25: =-MIN(CB25,$CC$12)*$CD$15 -> -6481.4832 | CF25: =-IF(E25="FOTIA",(CB25-AZ25)*1%,(CB25-AZ25)*1.5%) -> -2160.4944 | CI25: =+IF(H25>59,0,(CB25*138.92%)) -> 300135.88 | CJ25: =-MIN(CI25,$CC$12)*$CD$15 -> -9004.0765 | CK25: =-IF(E25="FOTIA",(CI25-BE25)*1%,(CI25-BE25)*1.5%) -> -3001.3588 | CL25: 0 | CN25: 0 | CZ25: =-SUM(CB25+CC25+CD25+CE25+CF25)*I25 -> 0 | DA25: =-SUM(CB25+CC25+CD25+CE25+CF25+CI25+CJ25+CK25)*J25 -> 0 | DB25: =SUM(CB25:DA25) -> 495537.91 | DC25: =ROUND(DB25,0) -> 495538 | DE25: =+DD25-DC25 -> -495538
A26: =500000+B26 -> 509812 | B26: 9812 | C26: CAMPO | D26: ARGAÑARAZ FRANCO IVAN | E26: FOTIA | F26: 0 | K26: Q02 | O26: 0 | P26: =+VLOOKUP(K26,$W$4:$AC$11,5,0) -> 5401.236 | Q26: =+VLOOKUP(K26,$W$4:$Z$11,2,0) -> 18004.12 | R26: =+VLOOKUP(K26,$W$4:$Y$11,3,0) -> 25011.121 | T26: 7 | U26: =+T26 -> 7 | V26: 0 | W26: 0 | X26: 0 | Y26: 0 | Z26: 0 | AA26: 0 | AB26: 0 | AC26: 0 | AD26: 0 | AE26: 0 | AF26: 0 | AG26: 0 | AH26: 0 | AI26: 0 | AJ26: 0 | AK26: 0 | AL26: 0 | AM26: 0 | AN26: 0 | AO26: 0 | AP26: 0 | AQ26: 0 | AR26: 0 | AS26: 0 | AT26: 0 | AU26: =+U26+V26+W26+Y26-Z26-AB26-AC26-AD26-AE26+AF26-AG26+AJ26 -> 7 | AV26: =+Q26*U26 -> 126028.84 | AW26: =+Q26*V26 -> 0 | AX26: =+Q26*W26 -> 0 | AY26: =+Q26*X26 -> 0 | AZ26: =+(Q26*1.0833*Y26)+((P26*O26)/25*Y26) -> 0 | BA26: =-Q26/8*Z26 -> 0 | BB26: =+Q26/8*AA26 -> 0 | BC26: =-Q26*AB26 -> 0 | BD26: =-Q26*AC26 -> 0 | BE26: =-Q26/8*AD26 -> 0 | BF26: =-Q26*AE26 -> 0 | BG26: =+Q26*AF26 -> 0 | BH26: =-Q26*AG26 -> 0 | BI26: =+Q26*AI26 -> 0 | BJ26: =+Q26*AH26 -> 0 | BK26: =+Q26*AJ26 -> 0 | BL26: =+(P26*O26)/25*(U26+V26+W26-Z26-AB26-AC26-AD26-AE26+AF26-AG26) -> 0 | BM26: =+$BM$15/25*(U26+V26+Y26+AF26+AH26+AI26)*0 -> 0 | BP26: =+M26*(AU26+AH26+AI26) -> 0 | BS26: =+$BS$15*AM26 -> 0 | BT26: =+$BT$15*AN26 -> 0 | BU26: =+$BU$15*AO26 -> 0 | BV26: =+$BV$15*AP26 -> 0 | CA26: =+IF(H26>59,+SUM(AV26:BX26)*138.92%,0) -> 0 | CB26: =SUM(AV26:CA26) -> 126028.84 | CE26: =-MIN(CB26,$CC$12)*$CD$15 -> -3780.8652 | CF26: =-IF(E26="FOTIA",(CB26-AZ26)*1%,(CB26-AZ26)*1.5%) -> -1260.2884 | CI26: =+IF(H26>59,0,(CB26*138.92%)) -> 175079.26 | CJ26: =-MIN(CI26,$CC$12)*$CD$15 -> -5252.3779 | CK26: =-IF(E26="FOTIA",(CI26-BE26)*1%,(CI26-BE26)*1.5%) -> -1750.7926 | CL26: 0 | CN26: 0 | CZ26: =-SUM(CB26+CC26+CD26+CE26+CF26)*I26 -> 0 | DA26: =-SUM(CB26+CC26+CD26+CE26+CF26+CI26+CJ26+CK26)*J26 -> 0 | DB26: =SUM(CB26:DA26) -> 289063.78 | DC26: =ROUND(DB26,0) -> 289064 | DE26: =+DD26-DC26 -> -289064
A27: =500000+B27 -> 509832 | B27: 9832 | C27: CAMPO | D27: ARGAÑARAZ RODRIGO ALBERTO | E27: FOTIA | F27: 0 | K27: Q02 | O27: 0 | P27: =+VLOOKUP(K27,$W$4:$AC$11,5,0) -> 5401.236 | Q27: =+VLOOKUP(K27,$W$4:$Z$11,2,0) -> 18004.12 | R27: =+VLOOKUP(K27,$W$4:$Y$11,3,0) -> 25011.121 | T27: 11 | U27: =+T27 -> 11 | V27: 0 | W27: 1 | X27: 0 | Y27: 0 | Z27: 0 | AA27: 0 | AB27: 0 | AC27: 0 | AD27: 0 | AE27: 0 | AF27: 0 | AG27: 0 | AH27: 0 | AI27: 0 | AJ27: 0 | AK27: 0 | AL27: 0 | AM27: 0 | AN27: 0 | AO27: 0 | AP27: 0 | AQ27: 0 | AR27: 0 | AS27: 0 | AT27: 0 | AU27: =+U27+V27+W27+Y27-Z27-AB27-AC27-AD27-AE27+AF27-AG27+AJ27 -> 12 | AV27: =+Q27*U27 -> 198045.32 | AW27: =+Q27*V27 -> 0 | AX27: =+Q27*W27 -> 18004.12 | AY27: =+Q27*X27 -> 0 | AZ27: =+(Q27*1.0833*Y27)+((P27*O27)/25*Y27) -> 0 | BA27: =-Q27/8*Z27 -> 0 | BB27: =+Q27/8*AA27 -> 0 | BC27: =-Q27*AB27 -> 0 | BD27: =-Q27*AC27 -> 0 | BE27: =-Q27/8*AD27 -> 0 | BF27: =-Q27*AE27 -> 0 | BG27: =+Q27*AF27 -> 0 | BH27: =-Q27*AG27 -> 0 | BI27: =+Q27*AI27 -> 0 | BJ27: =+Q27*AH27 -> 0 | BK27: =+Q27*AJ27 -> 0 | BL27: =+(P27*O27)/25*(U27+V27+W27-Z27-AB27-AC27-AD27-AE27+AF27-AG27) -> 0 | BM27: =+$BM$15/25*(U27+V27+Y27+AF27+AH27+AI27)*0 -> 0 | BP27: =+M27*(AU27+AH27+AI27) -> 0 | BS27: =+$BS$15*AM27 -> 0 | BT27: =+$BT$15*AN27 -> 0 | BU27: =+$BU$15*AO27 -> 0 | BV27: =+$BV$15*AP27 -> 0 | CA27: =+IF(H27>59,+SUM(AV27:BX27)*138.92%,0) -> 0 | CB27: =SUM(AV27:CA27) -> 216049.44 | CE27: =-MIN(CB27,$CC$12)*$CD$15 -> -6481.4832 | CF27: =-IF(E27="FOTIA",(CB27-AZ27)*1%,(CB27-AZ27)*1.5%) -> -2160.4944 | CI27: =+IF(H27>59,0,(CB27*138.92%)) -> 300135.88 | CJ27: =-MIN(CI27,$CC$12)*$CD$15 -> -9004.0765 | CK27: =-IF(E27="FOTIA",(CI27-BE27)*1%,(CI27-BE27)*1.5%) -> -3001.3588 | CL27: 0 | CN27: 0 | CZ27: =-SUM(CB27+CC27+CD27+CE27+CF27)*I27 -> 0 | DA27: =-SUM(CB27+CC27+CD27+CE27+CF27+CI27+CJ27+CK27)*J27 -> 0 | DB27: =SUM(CB27:DA27) -> 495537.91 | DC27: =ROUND(DB27,0) -> 495538 | DE27: =+DD27-DC27 -> -495538
A28: =500000+B28 -> 509653 | B28: 9653 | C28: CAMPO | D28: ARGAÑARAZ SERGIO VICTOR | E28: FEIA | F28: 3 | K28: Q04 | O28: 7 | P28: =+VLOOKUP(K28,$W$4:$AC$11,5,0) -> 5700.726 | Q28: =+VLOOKUP(K28,$W$4:$Z$11,2,0) -> 19002.42 | R28: =+VLOOKUP(K28,$W$4:$Y$11,3,0) -> 26397.964 | T28: 0 | U28: =+T28 -> 0 | V28: 0 | W28: 0 | X28: 0 | Y28: 0 | Z28: 0 | AA28: 0 | AB28: 0 | AC28: 0 | AD28: 0 | AE28: 0 | AF28: 0 | AG28: 0 | AH28: 0 | AI28: 0 | AJ28: 0 | AK28: 0 | AL28: 0 | AM28: 0 | AN28: 0 | AO28: 0 | AP28: 0 | AQ28: 0 | AR28: 0 | AS28: 0 | AT28: 0 | AU28: =+U28+V28+W28+Y28-Z28-AB28-AC28-AD28-AE28+AF28-AG28+AJ28 -> 0 | AV28: =+Q28*U28 -> 0 | AW28: =+Q28*V28 -> 0 | AX28: =+Q28*W28 -> 0 | AY28: =+Q28*X28 -> 0 | AZ28: =+(Q28*1.0833*Y28)+((P28*O28)/25*Y28) -> 0 | BA28: =-Q28/8*Z28 -> 0 | BB28: =+Q28/8*AA28 -> 0 | BC28: =-Q28*AB28 -> 0 | BD28: =-Q28*AC28 -> 0 | BE28: =-Q28/8*AD28 -> 0 | BF28: =-Q28*AE28 -> 0 | BG28: =+Q28*AF28 -> 0 | BH28: =-Q28*AG28 -> 0 | BI28: =+Q28*AI28 -> 0 | BJ28: =+Q28*AH28 -> 0 | BK28: =+Q28*AJ28 -> 0 | BL28: =+(P28*O28)/25*(U28+V28+W28-Z28-AB28-AC28-AD28-AE28+AF28-AG28) -> 0 | BM28: =+$BM$15/25*(U28+V28+Y28+AF28+AH28+AI28)*0 -> 0 | BP28: =+M28*(AU28+AH28+AI28) -> 0 | BS28: =+$BS$15*AM28 -> 0 | BT28: =+$BT$15*AN28 -> 0 | BU28: =+$BU$15*AO28 -> 0 | BV28: =+$BV$15*AP28 -> 0 | CA28: =+IF(H28>59,+SUM(AV28:BX28)*138.92%,0) -> 0 | CB28: =SUM(AV28:CA28) -> 0 | CE28: =-MIN(CB28,$CC$12)*$CD$15 -> 0 | CF28: =-IF(E28="FOTIA",(CB28-AZ28)*1%,(CB28-AZ28)*1.5%) -> 0 | CI28: =+IF(H28>59,0,(CB28*138.92%)) -> 0 | CJ28: =-MIN(CI28,$CC$12)*$CD$15 -> 0 | CK28: =-IF(E28="FOTIA",(CI28-BE28)*1%,(CI28-BE28)*1.5%) -> 0 | CL28: 0 | CN28: 0 | CZ28: =-SUM(CB28+CC28+CD28+CE28+CF28)*I28 -> 0 | DA28: =-SUM(CB28+CC28+CD28+CE28+CF28+CI28+CJ28+CK28)*J28 -> 0 | DB28: =SUM(CB28:DA28) -> 0 | DC28: =ROUND(DB28,0) -> 0 | DE28: =+DD28-DC28 -> 0
A29: =500000+B29 -> 509643 | B29: 9643 | C29: CAMPO | D29: ARIAS HORACIO OSCAR | E29: FEIA | F29: 3 | I29: 0.2 | K29: Q04 | O29: 9 | P29: =+VLOOKUP(K29,$W$4:$AC$11,5,0) -> 5700.726 | Q29: =+VLOOKUP(K29,$W$4:$Z$11,2,0) -> 19002.42 | R29: =+VLOOKUP(K29,$W$4:$Y$11,3,0) -> 26397.964 | T29: 0 | U29: =+T29 -> 0 | V29: 0 | W29: 0 | X29: 0 | Y29: 0 | Z29: 0 | AA29: 0 | AB29: 0 | AC29: 0 | AD29: 0 | AE29: 0 | AF29: 0 | AG29: 0 | AH29: 0 | AI29: 0 | AJ29: 0 | AK29: 0 | AL29: 0 | AM29: 0 | AN29: 0 | AO29: 0 | AP29: 0 | AQ29: 0 | AR29: 0 | AS29: 0 | AT29: 0 | AU29: =+U29+V29+W29+Y29-Z29-AB29-AC29-AD29-AE29+AF29-AG29+AJ29 -> 0 | AV29: =+Q29*U29 -> 0 | AW29: =+Q29*V29 -> 0 | AX29: =+Q29*W29 -> 0 | AY29: =+Q29*X29 -> 0 | AZ29: =+(Q29*1.0833*Y29)+((P29*O29)/25*Y29) -> 0 | BA29: =-Q29/8*Z29 -> 0 | BB29: =+Q29/8*AA29 -> 0 | BC29: =-Q29*AB29 -> 0 | BD29: =-Q29*AC29 -> 0 | BE29: =-Q29/8*AD29 -> 0 | BF29: =-Q29*AE29 -> 0 | BG29: =+Q29*AF29 -> 0 | BH29: =-Q29*AG29 -> 0 | BI29: =+Q29*AI29 -> 0 | BJ29: =+Q29*AH29 -> 0 | BK29: =+Q29*AJ29 -> 0 | BL29: =+(P29*O29)/25*(U29+V29+W29-Z29-AB29-AC29-AD29-AE29+AF29-AG29) -> 0 | BM29: =+$BM$15/25*(U29+V29+Y29+AF29+AH29+AI29)*0 -> 0 | BP29: =+M29*(AU29+AH29+AI29) -> 0 | BS29: =+$BS$15*AM29 -> 0 | BT29: =+$BT$15*AN29 -> 0 | BU29: =+$BU$15*AO29 -> 0 | BV29: =+$BV$15*AP29 -> 0 | CA29: =+IF(H29>59,+SUM(AV29:BX29)*138.92%,0) -> 0 | CB29: =SUM(AV29:CA29) -> 0 | CE29: =-MIN(CB29,$CC$12)*$CD$15 -> 0 | CF29: =-IF(E29="FOTIA",(CB29-AZ29)*1%,(CB29-AZ29)*1.5%) -> 0 | CI29: =+IF(H29>59,0,(CB29*138.92%)) -> 0 | CJ29: =-MIN(CI29,$CC$12)*$CD$15 -> 0 | CK29: =-IF(E29="FOTIA",(CI29-BE29)*1%,(CI29-BE29)*1.5%) -> 0 | CL29: 0 | CN29: 0 | CZ29: =-SUM(CB29+CC29+CD29+CE29+CF29)*I29 -> 0 | DA29: =-SUM(CB29+CC29+CD29+CE29+CF29+CI29+CJ29+CK29)*J29 -> 0 | DB29: =SUM(CB29:DA29) -> 0 | DC29: =ROUND(DB29,0) -> 0 | DE29: =+DD29-DC29 -> 0
A30: =500000+B30 -> 509654 | B30: 9654 | C30: CAMPO | D30: ARIAS SEGUNDO FRANCISCO | E30: FEIA | F30: 0 | K30: Q04 | O30: 0 | P30: =+VLOOKUP(K30,$W$4:$AC$11,5,0) -> 5700.726 | Q30: =+VLOOKUP(K30,$W$4:$Z$11,2,0) -> 19002.42 | R30: =+VLOOKUP(K30,$W$4:$Y$11,3,0) -> 26397.964 | T30: 0 | U30: =+T30 -> 0 | V30: 0 | W30: 0 | X30: 0 | Y30: 0 | Z30: 0 | AA30: 0 | AB30: 0 | AC30: 0 | AD30: 0 | AE30: 0 | AF30: 0 | AG30: 0 | AH30: 0 | AI30: 0 | AJ30: 0 | AK30: 0 | AL30: 0 | AM30: 0 | AN30: 0 | AO30: 0 | AP30: 0 | AQ30: 0 | AR30: 0 | AS30: 0 | AT30: 0 | AU30: =+U30+V30+W30+Y30-Z30-AB30-AC30-AD30-AE30+AF30-AG30+AJ30 -> 0 | AV30: =+Q30*U30 -> 0 | AW30: =+Q30*V30 -> 0 | AX30: =+Q30*W30 -> 0 | AY30: =+Q30*X30 -> 0 | AZ30: =+(Q30*1.0833*Y30)+((P30*O30)/25*Y30) -> 0 | BA30: =-Q30/8*Z30 -> 0 | BB30: =+Q30/8*AA30 -> 0 | BC30: =-Q30*AB30 -> 0 | BD30: =-Q30*AC30 -> 0 | BE30: =-Q30/8*AD30 -> 0 | BF30: =-Q30*AE30 -> 0 | BG30: =+Q30*AF30 -> 0 | BH30: =-Q30*AG30 -> 0 | BI30: =+Q30*AI30 -> 0 | BJ30: =+Q30*AH30 -> 0 | BK30: =+Q30*AJ30 -> 0 | BL30: =+(P30*O30)/25*(U30+V30+W30-Z30-AB30-AC30-AD30-AE30+AF30-AG30) -> 0 | BM30: =+$BM$15/25*(U30+V30+Y30+AF30+AH30+AI30)*0 -> 0 | BP30: =+M30*(AU30+AH30+AI30) -> 0 | BS30: =+$BS$15*AM30 -> 0 | BT30: =+$BT$15*AN30 -> 0 | BU30: =+$BU$15*AO30 -> 0 | BV30: =+$BV$15*AP30 -> 0 | CA30: =+IF(H30>59,+SUM(AV30:BX30)*138.92%,0) -> 0 | CB30: =SUM(AV30:CA30) -> 0 | CE30: =-MIN(CB30,$CC$12)*$CD$15 -> 0 | CF30: =-IF(E30="FOTIA",(CB30-AZ30)*1%,(CB30-AZ30)*1.5%) -> 0 | CI30: =+IF(H30>59,0,(CB30*138.92%)) -> 0 | CJ30: =-MIN(CI30,$CC$12)*$CD$15 -> 0 | CK30: =-IF(E30="FOTIA",(CI30-BE30)*1%,(CI30-BE30)*1.5%) -> 0 | CL30: 0 | CN30: 0 | CZ30: =-SUM(CB30+CC30+CD30+CE30+CF30)*I30 -> 0 | DA30: =-SUM(CB30+CC30+CD30+CE30+CF30+CI30+CJ30+CK30)*J30 -> 0 | DB30: =SUM(CB30:DA30) -> 0 | DC30: =ROUND(DB30,0) -> 0 | DE30: =+DD30-DC30 -> 0
A31: =500000+B31 -> 509656 | B31: 9656 | C31: CAMPO | D31: BARRAZA RUBEN DAVID | E31: FEIA | F31: 0 | K31: Q04 | O31: 0 | P31: =+VLOOKUP(K31,$W$4:$AC$11,5,0) -> 5700.726 | Q31: =+VLOOKUP(K31,$W$4:$Z$11,2,0) -> 19002.42 | R31: =+VLOOKUP(K31,$W$4:$Y$11,3,0) -> 26397.964 | T31: 0 | U31: =+T31 -> 0 | V31: 0 | W31: 0 | X31: 0 | Y31: 0 | Z31: 0 | AA31: 0 | AB31: 0 | AC31: 0 | AD31: 0 | AE31: 0 | AF31: 0 | AG31: 0 | AH31: 0 | AI31: 0 | AJ31: 0 | AK31: 0 | AL31: 0 | AM31: 0 | AN31: 0 | AO31: 0 | AP31: 0 | AQ31: 0 | AR31: 0 | AS31: 0 | AT31: 0 | AU31: =+U31+V31+W31+Y31-Z31-AB31-AC31-AD31-AE31+AF31-AG31+AJ31 -> 0 | AV31: =+Q31*U31 -> 0 | AW31: =+Q31*V31 -> 0 | AX31: =+Q31*W31 -> 0 | AY31: =+Q31*X31 -> 0 | AZ31: =+(Q31*1.0833*Y31)+((P31*O31)/25*Y31) -> 0 | BA31: =-Q31/8*Z31 -> 0 | BB31: =+Q31/8*AA31 -> 0 | BC31: =-Q31*AB31 -> 0 | BD31: =-Q31*AC31 -> 0 | BE31: =-Q31/8*AD31 -> 0 | BF31: =-Q31*AE31 -> 0 | BG31: =+Q31*AF31 -> 0 | BH31: =-Q31*AG31 -> 0 | BI31: =+Q31*AI31 -> 0 | BJ31: =+Q31*AH31 -> 0 | BK31: =+Q31*AJ31 -> 0 | BL31: =+(P31*O31)/25*(U31+V31+W31-Z31-AB31-AC31-AD31-AE31+AF31-AG31) -> 0 | BM31: =+$BM$15/25*(U31+V31+Y31+AF31+AH31+AI31)*0 -> 0 | BP31: =+M31*(AU31+AH31+AI31) -> 0 | BS31: =+$BS$15*AM31 -> 0 | BT31: =+$BT$15*AN31 -> 0 | BU31: =+$BU$15*AO31 -> 0 | BV31: =+$BV$15*AP31 -> 0 | CA31: =+IF(H31>59,+SUM(AV31:BX31)*138.92%,0) -> 0 | CB31: =SUM(AV31:CA31) -> 0 | CE31: =-MIN(CB31,$CC$12)*$CD$15 -> 0 | CF31: =-IF(E31="FOTIA",(CB31-AZ31)*1%,(CB31-AZ31)*1.5%) -> 0 | CI31: =+IF(H31>59,0,(CB31*138.92%)) -> 0 | CJ31: =-MIN(CI31,$CC$12)*$CD$15 -> 0 | CK31: =-IF(E31="FOTIA",(CI31-BE31)*1%,(CI31-BE31)*1.5%) -> 0 | CL31: 0 | CN31: 0 | CZ31: =-SUM(CB31+CC31+CD31+CE31+CF31)*I31 -> 0 | DA31: =-SUM(CB31+CC31+CD31+CE31+CF31+CI31+CJ31+CK31)*J31 -> 0 | DB31: =SUM(CB31:DA31) -> 0 | DC31: =ROUND(DB31,0) -> 0 | DE31: =+DD31-DC31 -> 0
A32: =500000+B32 -> 509645 | B32: 9645 | C32: CAMPO | D32: BELMONTE CESAR ANTONIO | E32: FEIA | F32: 3 | K32: Q04 | O32: 10 | P32: =+VLOOKUP(K32,$W$4:$AC$11,5,0) -> 5700.726 | Q32: =+VLOOKUP(K32,$W$4:$Z$11,2,0) -> 19002.42 | R32: =+VLOOKUP(K32,$W$4:$Y$11,3,0) -> 26397.964 | T32: 12 | U32: =+T32 -> 12 | V32: 0 | W32: 1 | X32: 0 | Y32: 0 | Z32: 0 | AA32: 0 | AB32: 0 | AC32: 0 | AD32: 0 | AE32: 0 | AF32: 0 | AG32: 0 | AH32: 0 | AI32: 0 | AJ32: 0 | AK32: 0 | AL32: 0 | AM32: 0 | AN32: 0 | AO32: 0 | AP32: 0 | AQ32: 0 | AR32: 0 | AS32: 0 | AT32: 0 | AU32: =+U32+V32+W32+Y32-Z32-AB32-AC32-AD32-AE32+AF32-AG32+AJ32 -> 13 | AV32: =+Q32*U32 -> 228029.04 | AW32: =+Q32*V32 -> 0 | AX32: =+Q32*W32 -> 19002.42 | AY32: =+Q32*X32 -> 0 | AZ32: =+(Q32*1.0833*Y32)+((P32*O32)/25*Y32) -> 0 | BA32: =-Q32/8*Z32 -> 0 | BB32: =+Q32/8*AA32 -> 0 | BC32: =-Q32*AB32 -> 0 | BD32: =-Q32*AC32 -> 0 | BE32: =-Q32/8*AD32 -> 0 | BF32: =-Q32*AE32 -> 0 | BG32: =+Q32*AF32 -> 0 | BH32: =-Q32*AG32 -> 0 | BI32: =+Q32*AI32 -> 0 | BJ32: =+Q32*AH32 -> 0 | BK32: =+Q32*AJ32 -> 0 | BL32: =+(P32*O32)/25*(U32+V32+W32-Z32-AB32-AC32-AD32-AE32+AF32-AG32) -> 29643.775 | BM32: =+$BM$15/25*(U32+V32+Y32+AF32+AH32+AI32)*0 -> 0 | BP32: =+M32*(AU32+AH32+AI32) -> 0 | BS32: =+$BS$15*AM32 -> 0 | BT32: =+$BT$15*AN32 -> 0 | BU32: =+$BU$15*AO32 -> 0 | BV32: =+$BV$15*AP32 -> 0 | CA32: =+IF(H32>59,+SUM(AV32:BX32)*138.92%,0) -> 0 | CB32: =SUM(AV32:CA32) -> 276675.24 | CE32: =-MIN(CB32,$CC$12)*$CD$15 -> -8300.2571 | CF32: =-IF(E32="FOTIA",(CB32-AZ32)*1%,(CB32-AZ32)*1.5%) -> -4150.1285 | CI32: =+IF(H32>59,0,(CB32*138.92%)) -> 384357.24 | CJ32: =-MIN(CI32,$CC$12)*$CD$15 -> -11530.717 | CK32: =-IF(E32="FOTIA",(CI32-BE32)*1%,(CI32-BE32)*1.5%) -> -5765.3586 | CL32: 0 | CN32: 0 | CZ32: =-SUM(CB32+CC32+CD32+CE32+CF32)*I32 -> 0 | DA32: =-SUM(CB32+CC32+CD32+CE32+CF32+CI32+CJ32+CK32)*J32 -> 0 | DB32: =SUM(CB32:DA32) -> 631286.01 | DC32: =ROUND(DB32,0) -> 631286 | DE32: =+DD32-DC32 -> -631286
A33: =500000+B33 -> 509658 | B33: 9658 | C33: CAMPO | D33: BORQUES VIRGILIO MARIO | E33: FEIA | F33: 3 | K33: Q04 | O33: 5 | P33: =+VLOOKUP(K33,$W$4:$AC$11,5,0) -> 5700.726 | Q33: =+VLOOKUP(K33,$W$4:$Z$11,2,0) -> 19002.42 | R33: =+VLOOKUP(K33,$W$4:$Y$11,3,0) -> 26397.964 | T33: 0 | U33: =+T33 -> 0 | V33: 0 | W33: 0 | X33: 0 | Y33: 0 | Z33: 0 | AA33: 0 | AB33: 0 | AC33: 0 | AD33: 0 | AE33: 0 | AF33: 0 | AG33: 0 | AH33: 0 | AI33: 0 | AJ33: 0 | AK33: 0 | AL33: 0 | AM33: 0 | AN33: 0 | AO33: 0 | AP33: 0 | AQ33: 0 | AR33: 0 | AS33: 0 | AT33: 0 | AU33: =+U33+V33+W33+Y33-Z33-AB33-AC33-AD33-AE33+AF33-AG33+AJ33 -> 0 | AV33: =+Q33*U33 -> 0 | AW33: =+Q33*V33 -> 0 | AX33: =+Q33*W33 -> 0 | AY33: =+Q33*X33 -> 0 | AZ33: =+(Q33*1.0833*Y33)+((P33*O33)/25*Y33) -> 0 | BA33: =-Q33/8*Z33 -> 0 | BB33: =+Q33/8*AA33 -> 0 | BC33: =-Q33*AB33 -> 0 | BD33: =-Q33*AC33 -> 0 | BE33: =-Q33/8*AD33 -> 0 | BF33: =-Q33*AE33 -> 0 | BG33: =+Q33*AF33 -> 0 | BH33: =-Q33*AG33 -> 0 | BI33: =+Q33*AI33 -> 0 | BJ33: =+Q33*AH33 -> 0 | BK33: =+Q33*AJ33 -> 0 | BL33: =+(P33*O33)/25*(U33+V33+W33-Z33-AB33-AC33-AD33-AE33+AF33-AG33) -> 0 | BM33: =+$BM$15/25*(U33+V33+Y33+AF33+AH33+AI33)*0 -> 0 | BP33: =+M33*(AU33+AH33+AI33) -> 0 | BS33: =+$BS$15*AM33 -> 0 | BT33: =+$BT$15*AN33 -> 0 | BU33: =+$BU$15*AO33 -> 0 | BV33: =+$BV$15*AP33 -> 0 | CA33: =+IF(H33>59,+SUM(AV33:BX33)*138.92%,0) -> 0 | CB33: =SUM(AV33:CA33) -> 0 | CE33: =-MIN(CB33,$CC$12)*$CD$15 -> 0 | CF33: =-IF(E33="FOTIA",(CB33-AZ33)*1%,(CB33-AZ33)*1.5%) -> 0 | CI33: =+IF(H33>59,0,(CB33*138.92%)) -> 0 | CJ33: =-MIN(CI33,$CC$12)*$CD$15 -> 0 | CK33: =-IF(E33="FOTIA",(CI33-BE33)*1%,(CI33-BE33)*1.5%) -> 0 | CL33: 0 | CN33: 0 | CZ33: =-SUM(CB33+CC33+CD33+CE33+CF33)*I33 -> 0 | DA33: =-SUM(CB33+CC33+CD33+CE33+CF33+CI33+CJ33+CK33)*J33 -> 0 | DB33: =SUM(CB33:DA33) -> 0 | DC33: =ROUND(DB33,0) -> 0 | DE33: =+DD33-DC33 -> 0
A34: =500000+B34 -> 509659 | B34: 9659 | C34: CAMPO | D34: BORQUEZ JOSE ALBERTO | E34: FEIA | F34: 3 | K34: Q04 | O34: 7 | P34: =+VLOOKUP(K34,$W$4:$AC$11,5,0) -> 5700.726 | Q34: =+VLOOKUP(K34,$W$4:$Z$11,2,0) -> 19002.42 | R34: =+VLOOKUP(K34,$W$4:$Y$11,3,0) -> 26397.964 | T34: 0 | U34: =+T34 -> 0 | V34: 0 | W34: 0 | X34: 0 | Y34: 0 | Z34: 0 | AA34: 0 | AB34: 0 | AC34: 0 | AD34: 0 | AE34: 0 | AF34: 0 | AG34: 0 | AH34: 0 | AI34: 0 | AJ34: 0 | AK34: 0 | AL34: 0 | AM34: 0 | AN34: 0 | AO34: 0 | AP34: 0 | AQ34: 0 | AR34: 0 | AS34: 0 | AT34: 0 | AU34: =+U34+V34+W34+Y34-Z34-AB34-AC34-AD34-AE34+AF34-AG34+AJ34 -> 0 | AV34: =+Q34*U34 -> 0 | AW34: =+Q34*V34 -> 0 | AX34: =+Q34*W34 -> 0 | AY34: =+Q34*X34 -> 0 | AZ34: =+(Q34*1.0833*Y34)+((P34*O34)/25*Y34) -> 0 | BA34: =-Q34/8*Z34 -> 0 | BB34: =+Q34/8*AA34 -> 0 | BC34: =-Q34*AB34 -> 0 | BD34: =-Q34*AC34 -> 0 | BE34: =-Q34/8*AD34 -> 0 | BF34: =-Q34*AE34 -> 0 | BG34: =+Q34*AF34 -> 0 | BH34: =-Q34*AG34 -> 0 | BI34: =+Q34*AI34 -> 0 | BJ34: =+Q34*AH34 -> 0 | BK34: =+Q34*AJ34 -> 0 | BL34: =+(P34*O34)/25*(U34+V34+W34-Z34-AB34-AC34-AD34-AE34+AF34-AG34) -> 0 | BM34: =+$BM$15/25*(U34+V34+Y34+AF34+AH34+AI34)*0 -> 0 | BP34: =+M34*(AU34+AH34+AI34) -> 0 | BS34: =+$BS$15*AM34 -> 0 | BT34: =+$BT$15*AN34 -> 0 | BU34: =+$BU$15*AO34 -> 0 | BV34: =+$BV$15*AP34 -> 0 | CA34: =+IF(H34>59,+SUM(AV34:BX34)*138.92%,0) -> 0 | CB34: =SUM(AV34:CA34) -> 0 | CE34: =-MIN(CB34,$CC$12)*$CD$15 -> 0 | CF34: =-IF(E34="FOTIA",(CB34-AZ34)*1%,(CB34-AZ34)*1.5%) -> 0 | CI34: =+IF(H34>59,0,(CB34*138.92%)) -> 0 | CJ34: =-MIN(CI34,$CC$12)*$CD$15 -> 0 | CK34: =-IF(E34="FOTIA",(CI34-BE34)*1%,(CI34-BE34)*1.5%) -> 0 | CL34: 0 | CN34: 0 | CZ34: =-SUM(CB34+CC34+CD34+CE34+CF34)*I34 -> 0 | DA34: =-SUM(CB34+CC34+CD34+CE34+CF34+CI34+CJ34+CK34)*J34 -> 0 | DB34: =SUM(CB34:DA34) -> 0 | DC34: =ROUND(DB34,0) -> 0 | DE34: =+DD34-DC34 -> 0
A35: =500000+B35 -> 509856 | B35: 9856 | C35: CAMPO | D35: BULACIO MIGUEL ALBERTO | E35: FEIA | F35: 0 | K35: Q04 | O35: 0 | P35: =+VLOOKUP(K35,$W$4:$AC$11,5,0) -> 5700.726 | Q35: =+VLOOKUP(K35,$W$4:$Z$11,2,0) -> 19002.42 | R35: =+VLOOKUP(K35,$W$4:$Y$11,3,0) -> 26397.964 | T35: 6 | U35: =+T35 -> 6 | V35: 0 | W35: 1 | X35: 0 | Y35: 0 | Z35: 0 | AA35: 0 | AB35: 0 | AC35: 0 | AD35: 0 | AE35: 0 | AF35: 0 | AG35: 0 | AH35: 0 | AI35: 0 | AJ35: 0 | AK35: 0 | AL35: 0 | AM35: 0 | AN35: 0 | AO35: 0 | AP35: 0 | AQ35: 0 | AR35: 0 | AS35: 0 | AT35: 0 | AU35: =+U35+V35+W35+Y35-Z35-AB35-AC35-AD35-AE35+AF35-AG35+AJ35 -> 7 | AV35: =+Q35*U35 -> 114014.52 | AW35: =+Q35*V35 -> 0 | AX35: =+Q35*W35 -> 19002.42 | AY35: =+Q35*X35 -> 0 | AZ35: =+(Q35*1.0833*Y35)+((P35*O35)/25*Y35) -> 0 | BA35: =-Q35/8*Z35 -> 0 | BB35: =+Q35/8*AA35 -> 0 | BC35: =-Q35*AB35 -> 0 | BD35: =-Q35*AC35 -> 0 | BE35: =-Q35/8*AD35 -> 0 | BF35: =-Q35*AE35 -> 0 | BG35: =+Q35*AF35 -> 0 | BH35: =-Q35*AG35 -> 0 | BI35: =+Q35*AI35 -> 0 | BJ35: =+Q35*AH35 -> 0 | BK35: =+Q35*AJ35 -> 0 | BL35: =+(P35*O35)/25*(U35+V35+W35-Z35-AB35-AC35-AD35-AE35+AF35-AG35) -> 0 | BM35: =+$BM$15/25*(U35+V35+Y35+AF35+AH35+AI35)*0 -> 0 | BP35: =+M35*(AU35+AH35+AI35) -> 0 | BS35: =+$BS$15*AM35 -> 0 | BT35: =+$BT$15*AN35 -> 0 | BU35: =+$BU$15*AO35 -> 0 | BV35: =+$BV$15*AP35 -> 0 | CA35: =+IF(H35>59,+SUM(AV35:BX35)*138.92%,0) -> 0 | CB35: =SUM(AV35:CA35) -> 133016.94 | CE35: =-MIN(CB35,$CC$12)*$CD$15 -> -3990.5082 | CF35: =-IF(E35="FOTIA",(CB35-AZ35)*1%,(CB35-AZ35)*1.5%) -> -1995.2541 | CI35: =+IF(H35>59,0,(CB35*138.92%)) -> 184787.13 | CJ35: =-MIN(CI35,$CC$12)*$CD$15 -> -5543.614 | CK35: =-IF(E35="FOTIA",(CI35-BE35)*1%,(CI35-BE35)*1.5%) -> -2771.807 | CL35: 0 | CN35: 0 | CZ35: =-SUM(CB35+CC35+CD35+CE35+CF35)*I35 -> 0 | DA35: =-SUM(CB35+CC35+CD35+CE35+CF35+CI35+CJ35+CK35)*J35 -> 0 | DB35: =SUM(CB35:DA35) -> 303502.89 | DC35: =ROUND(DB35,0) -> 303503 | DE35: =+DD35-DC35 -> -303503
A36: =500000+B36 -> 509661 | B36: 9661 | C36: CAMPO | D36: CAÑA MARIO CESAR | E36: FEIA | F36: 3 | H36: 61 | K36: Q04 | O36: 24 | P36: =+VLOOKUP(K36,$W$4:$AC$11,5,0) -> 5700.726 | Q36: =+VLOOKUP(K36,$W$4:$Z$11,2,0) -> 19002.42 | R36: =+VLOOKUP(K36,$W$4:$Y$11,3,0) -> 26397.964 | T36: 0 | U36: =+T36 -> 0 | V36: 0 | W36: 0 | X36: 0 | Y36: 0 | Z36: 0 | AA36: 0 | AB36: 0 | AC36: 0 | AD36: 0 | AE36: 0 | AF36: 0 | AG36: 0 | AH36: 0 | AI36: 0 | AJ36: 0 | AK36: 0 | AL36: 0 | AM36: 0 | AN36: 0 | AO36: 0 | AP36: 0 | AQ36: 0 | AR36: 0 | AS36: 0 | AT36: 0 | AU36: =+U36+V36+W36+Y36-Z36-AB36-AC36-AD36-AE36+AF36-AG36+AJ36 -> 0 | AV36: =+Q36*U36 -> 0 | AW36: =+Q36*V36 -> 0 | AX36: =+Q36*W36 -> 0 | AY36: =+Q36*X36 -> 0 | AZ36: =+(Q36*1.0833*Y36)+((P36*O36)/25*Y36) -> 0 | BA36: =-Q36/8*Z36 -> 0 | BB36: =+Q36/8*AA36 -> 0 | BC36: =-Q36*AB36 -> 0 | BD36: =-Q36*AC36 -> 0 | BE36: =-Q36/8*AD36 -> 0 | BF36: =-Q36*AE36 -> 0 | BG36: =+Q36*AF36 -> 0 | BH36: =-Q36*AG36 -> 0 | BI36: =+Q36*AI36 -> 0 | BJ36: =+Q36*AH36 -> 0 | BK36: =+Q36*AJ36 -> 0 | BL36: =+(P36*O36)/25*(U36+V36+W36-Z36-AB36-AC36-AD36-AE36+AF36-AG36) -> 0 | BM36: =+$BM$15/25*(U36+V36+Y36+AF36+AH36+AI36)*0 -> 0 | BP36: =+M36*(AU36+AH36+AI36) -> 0 | BS36: =+$BS$15*AM36 -> 0 | BT36: =+$BT$15*AN36 -> 0 | BU36: =+$BU$15*AO36 -> 0 | BV36: =+$BV$15*AP36 -> 0 | CA36: =+IF(H36>59,+SUM(AV36:BX36)*138.92%,0) -> 0 | CB36: =SUM(AV36:CA36) -> 0 | CE36: =-MIN(CB36,$CC$12)*$CD$15 -> 0 | CF36: =-IF(E36="FOTIA",(CB36-AZ36)*1%,(CB36-AZ36)*1.5%) -> 0 | CI36: =+IF(H36>59,0,(CB36*138.92%)) -> 0 | CJ36: =-MIN(CI36,$CC$12)*$CD$15 -> 0 | CK36: =-IF(E36="FOTIA",(CI36-BE36)*1%,(CI36-BE36)*1.5%) -> 0 | CL36: 0 | CN36: 0 | CZ36: =-SUM(CB36+CC36+CD36+CE36+CF36)*I36 -> 0 | DA36: =-SUM(CB36+CC36+CD36+CE36+CF36+CI36+CJ36+CK36)*J36 -> 0 | DB36: =SUM(CB36:DA36) -> 0 | DC36: =ROUND(DB36,0) -> 0 | DE36: =+DD36-DC36 -> 0
A37: =500000+B37 -> 509662 | B37: 9662 | C37: CAMPO | D37: CARRAZANA VICTOR HUGO | E37: FOTIA | F37: 1 | K37: Q02 | O37: 21 | P37: =+VLOOKUP(K37,$W$4:$AC$11,5,0) -> 5401.236 | Q37: =+VLOOKUP(K37,$W$4:$Z$11,2,0) -> 18004.12 | R37: =+VLOOKUP(K37,$W$4:$Y$11,3,0) -> 25011.121 | T37: 0 | U37: =+T37 -> 0 | V37: 0 | W37: 0 | X37: 0 | Y37: 0 | Z37: 0 | AA37: 0 | AB37: 0 | AC37: 0 | AD37: 0 | AE37: 0 | AF37: 0 | AG37: 0 | AH37: 0 | AI37: 0 | AJ37: 0 | AK37: 0 | AL37: 0 | AM37: 0 | AN37: 0 | AO37: 0 | AP37: 0 | AQ37: 0 | AR37: 0 | AS37: 0 | AT37: 0 | AU37: =+U37+V37+W37+Y37-Z37-AB37-AC37-AD37-AE37+AF37-AG37+AJ37 -> 0 | AV37: =+Q37*U37 -> 0 | AW37: =+Q37*V37 -> 0 | AX37: =+Q37*W37 -> 0 | AY37: =+Q37*X37 -> 0 | AZ37: =+(Q37*1.0833*Y37)+((P37*O37)/25*Y37) -> 0 | BA37: =-Q37/8*Z37 -> 0 | BB37: =+Q37/8*AA37 -> 0 | BC37: =-Q37*AB37 -> 0 | BD37: =-Q37*AC37 -> 0 | BE37: =-Q37/8*AD37 -> 0 | BF37: =-Q37*AE37 -> 0 | BG37: =+Q37*AF37 -> 0 | BH37: =-Q37*AG37 -> 0 | BI37: =+Q37*AI37 -> 0 | BJ37: =+Q37*AH37 -> 0 | BK37: =+Q37*AJ37 -> 0 | BL37: =+(P37*O37)/25*(U37+V37+W37-Z37-AB37-AC37-AD37-AE37+AF37-AG37) -> 0 | BM37: =+$BM$15/25*(U37+V37+Y37+AF37+AH37+AI37)*0 -> 0 | BP37: =+M37*(AU37+AH37+AI37) -> 0 | BS37: =+$BS$15*AM37 -> 0 | BT37: =+$BT$15*AN37 -> 0 | BU37: =+$BU$15*AO37 -> 0 | BV37: =+$BV$15*AP37 -> 0 | CA37: =+IF(H37>59,+SUM(AV37:BX37)*138.92%,0) -> 0 | CB37: =SUM(AV37:CA37) -> 0 | CE37: =-MIN(CB37,$CC$12)*$CD$15 -> 0 | CF37: =-IF(E37="FOTIA",(CB37-AZ37)*1%,(CB37-AZ37)*1.5%) -> 0 | CI37: =+IF(H37>59,0,(CB37*138.92%)) -> 0 | CJ37: =-MIN(CI37,$CC$12)*$CD$15 -> 0 | CK37: =-IF(E37="FOTIA",(CI37-BE37)*1%,(CI37-BE37)*1.5%) -> 0 | CL37: 0 | CN37: 0 | CZ37: =-SUM(CB37+CC37+CD37+CE37+CF37)*I37 -> 0 | DA37: =-SUM(CB37+CC37+CD37+CE37+CF37+CI37+CJ37+CK37)*J37 -> 0 | DB37: =SUM(CB37:DA37) -> 0 | DC37: =ROUND(DB37,0) -> 0 | DE37: =+DD37-DC37 -> 0
A38: =500000+B38 -> 509663 | B38: 9663 | C38: CAMPO | D38: CARRERAS MERCEDES ROSENDO | E38: FEIA | F38: 0 | H38: 65 | K38: Q02 | O38: 19 | P38: =+VLOOKUP(K38,$W$4:$AC$11,5,0) -> 5401.236 | Q38: =+VLOOKUP(K38,$W$4:$Z$11,2,0) -> 18004.12 | R38: =+VLOOKUP(K38,$W$4:$Y$11,3,0) -> 25011.121 | T38: 0 | U38: =+T38 -> 0 | V38: 0 | W38: 0 | X38: 0 | Y38: 0 | Z38: 0 | AA38: 0 | AB38: 0 | AC38: 0 | AD38: 0 | AE38: 0 | AF38: 0 | AG38: 0 | AH38: 0 | AI38: 0 | AJ38: 0 | AK38: 0 | AL38: 0 | AM38: 0 | AN38: 0 | AO38: 0 | AP38: 0 | AQ38: 0 | AR38: 0 | AS38: 0 | AT38: 0 | AU38: =+U38+V38+W38+Y38-Z38-AB38-AC38-AD38-AE38+AF38-AG38+AJ38 -> 0 | AV38: =+Q38*U38 -> 0 | AW38: =+Q38*V38 -> 0 | AX38: =+Q38*W38 -> 0 | AY38: =+Q38*X38 -> 0 | AZ38: =+(Q38*1.0833*Y38)+((P38*O38)/25*Y38) -> 0 | BA38: =-Q38/8*Z38 -> 0 | BB38: =+Q38/8*AA38 -> 0 | BC38: =-Q38*AB38 -> 0 | BD38: =-Q38*AC38 -> 0 | BE38: =-Q38/8*AD38 -> 0 | BF38: =-Q38*AE38 -> 0 | BG38: =+Q38*AF38 -> 0 | BH38: =-Q38*AG38 -> 0 | BI38: =+Q38*AI38 -> 0 | BJ38: =+Q38*AH38 -> 0 | BK38: =+Q38*AJ38 -> 0 | BL38: =+(P38*O38)/25*(U38+V38+W38-Z38-AB38-AC38-AD38-AE38+AF38-AG38) -> 0 | BM38: =+$BM$15/25*(U38+V38+Y38+AF38+AH38+AI38)*0 -> 0 | BP38: =+M38*(AU38+AH38+AI38) -> 0 | BS38: =+$BS$15*AM38 -> 0 | BT38: =+$BT$15*AN38 -> 0 | BU38: =+$BU$15*AO38 -> 0 | BV38: =+$BV$15*AP38 -> 0 | CA38: =+IF(H38>59,+SUM(AV38:BX38)*138.92%,0) -> 0 | CB38: =SUM(AV38:CA38) -> 0 | CE38: =-MIN(CB38,$CC$12)*$CD$15 -> 0 | CF38: =-IF(E38="FOTIA",(CB38-AZ38)*1%,(CB38-AZ38)*1.5%) -> 0 | CI38: =+IF(H38>59,0,(CB38*138.92%)) -> 0 | CJ38: =-MIN(CI38,$CC$12)*$CD$15 -> 0 | CK38: =-IF(E38="FOTIA",(CI38-BE38)*1%,(CI38-BE38)*1.5%) -> 0 | CL38: 0 | CN38: 0 | CZ38: =-SUM(CB38+CC38+CD38+CE38+CF38)*I38 -> 0 | DA38: =-SUM(CB38+CC38+CD38+CE38+CF38+CI38+CJ38+CK38)*J38 -> 0 | DB38: =SUM(CB38:DA38) -> 0 | DC38: =ROUND(DB38,0) -> 0 | DE38: =+DD38-DC38 -> 0
A39: =500000+B39 -> 509857 | B39: 9857 | C39: CAMPO | D39: CASTILLO ROQUE TOMAS | E39: FEIA | F39: 0 | K39: Q04 | O39: 0 | P39: =+VLOOKUP(K39,$W$4:$AC$11,5,0) -> 5700.726 | Q39: =+VLOOKUP(K39,$W$4:$Z$11,2,0) -> 19002.42 | R39: =+VLOOKUP(K39,$W$4:$Y$11,3,0) -> 26397.964 | T39: 0 | U39: =+T39 -> 0 | V39: 0 | W39: 0 | X39: 0 | Y39: 0 | Z39: 0 | AA39: 0 | AB39: 0 | AC39: 0 | AD39: 0 | AE39: 0 | AF39: 0 | AG39: 0 | AH39: 0 | AI39: 0 | AJ39: 0 | AK39: 0 | AL39: 0 | AM39: 0 | AN39: 0 | AO39: 0 | AP39: 0 | AQ39: 0 | AR39: 0 | AS39: 0 | AT39: 0 | AU39: =+U39+V39+W39+Y39-Z39-AB39-AC39-AD39-AE39+AF39-AG39+AJ39 -> 0 | AV39: =+Q39*U39 -> 0 | AW39: =+Q39*V39 -> 0 | AX39: =+Q39*W39 -> 0 | AY39: =+Q39*X39 -> 0 | AZ39: =+(Q39*1.0833*Y39)+((P39*O39)/25*Y39) -> 0 | BA39: =-Q39/8*Z39 -> 0 | BB39: =+Q39/8*AA39 -> 0 | BC39: =-Q39*AB39 -> 0 | BD39: =-Q39*AC39 -> 0 | BE39: =-Q39/8*AD39 -> 0 | BF39: =-Q39*AE39 -> 0 | BG39: =+Q39*AF39 -> 0 | BH39: =-Q39*AG39 -> 0 | BI39: =+Q39*AI39 -> 0 | BJ39: =+Q39*AH39 -> 0 | BK39: =+Q39*AJ39 -> 0 | BL39: =+(P39*O39)/25*(U39+V39+W39-Z39-AB39-AC39-AD39-AE39+AF39-AG39) -> 0 | BM39: =+$BM$15/25*(U39+V39+Y39+AF39+AH39+AI39)*0 -> 0 | BP39: =+M39*(AU39+AH39+AI39) -> 0 | BS39: =+$BS$15*AM39 -> 0 | BT39: =+$BT$15*AN39 -> 0 | BU39: =+$BU$15*AO39 -> 0 | BV39: =+$BV$15*AP39 -> 0 | CA39: =+IF(H39>59,+SUM(AV39:BX39)*138.92%,0) -> 0 | CB39: =SUM(AV39:CA39) -> 0 | CE39: =-MIN(CB39,$CC$12)*$CD$15 -> 0 | CF39: =-IF(E39="FOTIA",(CB39-AZ39)*1%,(CB39-AZ39)*1.5%) -> 0 | CI39: =+IF(H39>59,0,(CB39*138.92%)) -> 0 | CJ39: =-MIN(CI39,$CC$12)*$CD$15 -> 0 | CK39: =-IF(E39="FOTIA",(CI39-BE39)*1%,(CI39-BE39)*1.5%) -> 0 | CL39: 0 | CN39: 0 | CZ39: =-SUM(CB39+CC39+CD39+CE39+CF39)*I39 -> 0 | DA39: =-SUM(CB39+CC39+CD39+CE39+CF39+CI39+CJ39+CK39)*J39 -> 0 | DB39: =SUM(CB39:DA39) -> 0 | DC39: =ROUND(DB39,0) -> 0 | DE39: =+DD39-DC39 -> 0
A40: =500000+B40 -> 509665 | B40: 9665 | C40: CAMPO | D40: CASTRO MIGUEL ALEJANDRO | E40: FEIA | F40: 3 | K40: Q04 | O40: 7 | P40: =+VLOOKUP(K40,$W$4:$AC$11,5,0) -> 5700.726 | Q40: =+VLOOKUP(K40,$W$4:$Z$11,2,0) -> 19002.42 | R40: =+VLOOKUP(K40,$W$4:$Y$11,3,0) -> 26397.964 | T40: 0 | U40: =+T40 -> 0 | V40: 0 | W40: 0 | X40: 0 | Y40: 0 | Z40: 0 | AA40: 0 | AB40: 0 | AC40: 0 | AD40: 0 | AE40: 0 | AF40: 0 | AG40: 0 | AH40: 0 | AI40: 0 | AJ40: 0 | AK40: 0 | AL40: 0 | AM40: 0 | AN40: 0 | AO40: 0 | AP40: 0 | AQ40: 0 | AR40: 0 | AS40: 0 | AT40: 0 | AU40: =+U40+V40+W40+Y40-Z40-AB40-AC40-AD40-AE40+AF40-AG40+AJ40 -> 0 | AV40: =+Q40*U40 -> 0 | AW40: =+Q40*V40 -> 0 | AX40: =+Q40*W40 -> 0 | AY40: =+Q40*X40 -> 0 | AZ40: =+(Q40*1.0833*Y40)+((P40*O40)/25*Y40) -> 0 | BA40: =-Q40/8*Z40 -> 0 | BB40: =+Q40/8*AA40 -> 0 | BC40: =-Q40*AB40 -> 0 | BD40: =-Q40*AC40 -> 0 | BE40: =-Q40/8*AD40 -> 0 | BF40: =-Q40*AE40 -> 0 | BG40: =+Q40*AF40 -> 0 | BH40: =-Q40*AG40 -> 0 | BI40: =+Q40*AI40 -> 0 | BJ40: =+Q40*AH40 -> 0 | BK40: =+Q40*AJ40 -> 0 | BL40: =+(P40*O40)/25*(U40+V40+W40-Z40-AB40-AC40-AD40-AE40+AF40-AG40) -> 0 | BM40: =+$BM$15/25*(U40+V40+Y40+AF40+AH40+AI40)*0 -> 0 | BP40: =+M40*(AU40+AH40+AI40) -> 0 | BS40: =+$BS$15*AM40 -> 0 | BT40: =+$BT$15*AN40 -> 0 | BU40: =+$BU$15*AO40 -> 0 | BV40: =+$BV$15*AP40 -> 0 | CA40: =+IF(H40>59,+SUM(AV40:BX40)*138.92%,0) -> 0 | CB40: =SUM(AV40:CA40) -> 0 | CE40: =-MIN(CB40,$CC$12)*$CD$15 -> 0 | CF40: =-IF(E40="FOTIA",(CB40-AZ40)*1%,(CB40-AZ40)*1.5%) -> 0 | CI40: =+IF(H40>59,0,(CB40*138.92%)) -> 0 | CJ40: =-MIN(CI40,$CC$12)*$CD$15 -> 0 | CK40: =-IF(E40="FOTIA",(CI40-BE40)*1%,(CI40-BE40)*1.5%) -> 0 | CL40: 0 | CN40: 0 | CZ40: =-SUM(CB40+CC40+CD40+CE40+CF40)*I40 -> 0 | DA40: =-SUM(CB40+CC40+CD40+CE40+CF40+CI40+CJ40+CK40)*J40 -> 0 | DB40: =SUM(CB40:DA40) -> 0 | DC40: =ROUND(DB40,0) -> 0 | DE40: =+DD40-DC40 -> 0
A41: =500000+B41 -> 509649 | B41: 9649 | C41: CAMPO | D41: CISNEROS RAMON EXEQUIEL | E41: FOTIA | F41: 3 | K41: Q04 | O41: 8 | P41: =+VLOOKUP(K41,$W$4:$AC$11,5,0) -> 5700.726 | Q41: =+VLOOKUP(K41,$W$4:$Z$11,2,0) -> 19002.42 | R41: =+VLOOKUP(K41,$W$4:$Y$11,3,0) -> 26397.964 | T41: 0 | U41: =+T41 -> 0 | V41: 0 | W41: 0 | X41: 0 | Y41: 0 | Z41: 0 | AA41: 0 | AB41: 0 | AC41: 0 | AD41: 0 | AE41: 0 | AF41: 0 | AG41: 0 | AH41: 0 | AI41: 0 | AJ41: 0 | AK41: 0 | AL41: 0 | AM41: 0 | AN41: 0 | AO41: 0 | AP41: 0 | AQ41: 0 | AR41: 0 | AS41: 0 | AT41: 0 | AU41: =+U41+V41+W41+Y41-Z41-AB41-AC41-AD41-AE41+AF41-AG41+AJ41 -> 0 | AV41: =+Q41*U41 -> 0 | AW41: =+Q41*V41 -> 0 | AX41: =+Q41*W41 -> 0 | AY41: =+Q41*X41 -> 0 | AZ41: =+(Q41*1.0833*Y41)+((P41*O41)/25*Y41) -> 0 | BA41: =-Q41/8*Z41 -> 0 | BB41: =+Q41/8*AA41 -> 0 | BC41: =-Q41*AB41 -> 0 | BD41: =-Q41*AC41 -> 0 | BE41: =-Q41/8*AD41 -> 0 | BF41: =-Q41*AE41 -> 0 | BG41: =+Q41*AF41 -> 0 | BH41: =-Q41*AG41 -> 0 | BI41: =+Q41*AI41 -> 0 | BJ41: =+Q41*AH41 -> 0 | BK41: =+Q41*AJ41 -> 0 | BL41: =+(P41*O41)/25*(U41+V41+W41-Z41-AB41-AC41-AD41-AE41+AF41-AG41) -> 0 | BM41: =+$BM$15/25*(U41+V41+Y41+AF41+AH41+AI41)*0 -> 0 | BP41: =+M41*(AU41+AH41+AI41) -> 0 | BS41: =+$BS$15*AM41 -> 0 | BT41: =+$BT$15*AN41 -> 0 | BU41: =+$BU$15*AO41 -> 0 | BV41: =+$BV$15*AP41 -> 0 | CA41: =+IF(H41>59,+SUM(AV41:BX41)*138.92%,0) -> 0 | CB41: =SUM(AV41:CA41) -> 0 | CE41: =-MIN(CB41,$CC$12)*$CD$15 -> 0 | CF41: =-IF(E41="FOTIA",(CB41-AZ41)*1%,(CB41-AZ41)*1.5%) -> 0 | CI41: =+IF(H41>59,0,(CB41*138.92%)) -> 0 | CJ41: =-MIN(CI41,$CC$12)*$CD$15 -> 0 | CK41: =-IF(E41="FOTIA",(CI41-BE41)*1%,(CI41-BE41)*1.5%) -> 0 | CL41: 0 | CN41: 0 | CZ41: =-SUM(CB41+CC41+CD41+CE41+CF41)*I41 -> 0 | DA41: =-SUM(CB41+CC41+CD41+CE41+CF41+CI41+CJ41+CK41)*J41 -> 0 | DB41: =SUM(CB41:DA41) -> 0 | DC41: =ROUND(DB41,0) -> 0 | DE41: =+DD41-DC41 -> 0
A42: =500000+B42 -> 509748 | B42: 9748 | C42: CAMPO | D42: COSTILLA CARLOS DAMIAN | E42: FOTIA | F42: 0 | K42: Q04 | O42: 2 | P42: =+VLOOKUP(K42,$W$4:$AC$11,5,0) -> 5700.726 | Q42: =+VLOOKUP(K42,$W$4:$Z$11,2,0) -> 19002.42 | R42: =+VLOOKUP(K42,$W$4:$Y$11,3,0) -> 26397.964 | T42: 11 | U42: =+T42 -> 11 | V42: 0 | W42: 1 | X42: 0 | Y42: 0 | Z42: 0 | AA42: 0 | AB42: 0 | AC42: 0 | AD42: 0 | AE42: 0 | AF42: 0 | AG42: 0 | AH42: 0 | AI42: 0 | AJ42: 0 | AK42: 0 | AL42: 0 | AM42: 0 | AN42: 0 | AO42: 0 | AP42: 0 | AQ42: 0 | AR42: 0 | AS42: 0 | AT42: 0 | AU42: =+U42+V42+W42+Y42-Z42-AB42-AC42-AD42-AE42+AF42-AG42+AJ42 -> 12 | AV42: =+Q42*U42 -> 209026.62 | AW42: =+Q42*V42 -> 0 | AX42: =+Q42*W42 -> 19002.42 | AY42: =+Q42*X42 -> 0 | AZ42: =+(Q42*1.0833*Y42)+((P42*O42)/25*Y42) -> 0 | BA42: =-Q42/8*Z42 -> 0 | BB42: =+Q42/8*AA42 -> 0 | BC42: =-Q42*AB42 -> 0 | BD42: =-Q42*AC42 -> 0 | BE42: =-Q42/8*AD42 -> 0 | BF42: =-Q42*AE42 -> 0 | BG42: =+Q42*AF42 -> 0 | BH42: =-Q42*AG42 -> 0 | BI42: =+Q42*AI42 -> 0 | BJ42: =+Q42*AH42 -> 0 | BK42: =+Q42*AJ42 -> 0 | BL42: =+(P42*O42)/25*(U42+V42+W42-Z42-AB42-AC42-AD42-AE42+AF42-AG42) -> 5472.697 | BM42: =+$BM$15/25*(U42+V42+Y42+AF42+AH42+AI42)*0 -> 0 | BP42: =+M42*(AU42+AH42+AI42) -> 0 | BS42: =+$BS$15*AM42 -> 0 | BT42: =+$BT$15*AN42 -> 0 | BU42: =+$BU$15*AO42 -> 0 | BV42: =+$BV$15*AP42 -> 0 | CA42: =+IF(H42>59,+SUM(AV42:BX42)*138.92%,0) -> 0 | CB42: =SUM(AV42:CA42) -> 233501.74 | CE42: =-MIN(CB42,$CC$12)*$CD$15 -> -7005.0521 | CF42: =-IF(E42="FOTIA",(CB42-AZ42)*1%,(CB42-AZ42)*1.5%) -> -2335.0174 | CI42: =+IF(H42>59,0,(CB42*138.92%)) -> 324380.61 | CJ42: =-MIN(CI42,$CC$12)*$CD$15 -> -9731.4184 | CK42: =-IF(E42="FOTIA",(CI42-BE42)*1%,(CI42-BE42)*1.5%) -> -3243.8061 | CL42: 0 | CN42: 0 | CZ42: =-SUM(CB42+CC42+CD42+CE42+CF42)*I42 -> 0 | DA42: =-SUM(CB42+CC42+CD42+CE42+CF42+CI42+CJ42+CK42)*J42 -> 0 | DB42: =SUM(CB42:DA42) -> 535567.06 | DC42: =ROUND(DB42,0) -> 535567 | DE42: =+DD42-DC42 -> -535567
A43: =500000+B43 -> 509749 | B43: 9749 | C43: CAMPO | D43: COSTILLA DANIEL ANTONIO | E43: FOTIA | F43: 0 | K43: Q04 | O43: 0 | P43: =+VLOOKUP(K43,$W$4:$AC$11,5,0) -> 5700.726 | Q43: =+VLOOKUP(K43,$W$4:$Z$11,2,0) -> 19002.42 | R43: =+VLOOKUP(K43,$W$4:$Y$11,3,0) -> 26397.964 | T43: 11 | U43: =+T43 -> 11 | V43: 0 | W43: 1 | X43: 0 | Y43: 0 | Z43: 0 | AA43: 0 | AB43: 0 | AC43: 0 | AD43: 0 | AE43: 0 | AF43: 0 | AG43: 0 | AH43: 0 | AI43: 0 | AJ43: 0 | AK43: 0 | AL43: 0 | AM43: 0 | AN43: 0 | AO43: 0 | AP43: 0 | AQ43: 0 | AR43: 0 | AS43: 0 | AT43: 0 | AU43: =+U43+V43+W43+Y43-Z43-AB43-AC43-AD43-AE43+AF43-AG43+AJ43 -> 12 | AV43: =+Q43*U43 -> 209026.62 | AW43: =+Q43*V43 -> 0 | AX43: =+Q43*W43 -> 19002.42 | AY43: =+Q43*X43 -> 0 | AZ43: =+(Q43*1.0833*Y43)+((P43*O43)/25*Y43) -> 0 | BA43: =-Q43/8*Z43 -> 0 | BB43: =+Q43/8*AA43 -> 0 | BC43: =-Q43*AB43 -> 0 | BD43: =-Q43*AC43 -> 0 | BE43: =-Q43/8*AD43 -> 0 | BF43: =-Q43*AE43 -> 0 | BG43: =+Q43*AF43 -> 0 | BH43: =-Q43*AG43 -> 0 | BI43: =+Q43*AI43 -> 0 | BJ43: =+Q43*AH43 -> 0 | BK43: =+Q43*AJ43 -> 0 | BL43: =+(P43*O43)/25*(U43+V43+W43-Z43-AB43-AC43-AD43-AE43+AF43-AG43) -> 0 | BM43: =+$BM$15/25*(U43+V43+Y43+AF43+AH43+AI43)*0 -> 0 | BP43: =+M43*(AU43+AH43+AI43) -> 0 | BS43: =+$BS$15*AM43 -> 0 | BT43: =+$BT$15*AN43 -> 0 | BU43: =+$BU$15*AO43 -> 0 | BV43: =+$BV$15*AP43 -> 0 | CA43: =+IF(H43>59,+SUM(AV43:BX43)*138.92%,0) -> 0 | CB43: =SUM(AV43:CA43) -> 228029.04 | CE43: =-MIN(CB43,$CC$12)*$CD$15 -> -6840.8712 | CF43: =-IF(E43="FOTIA",(CB43-AZ43)*1%,(CB43-AZ43)*1.5%) -> -2280.2904 | CI43: =+IF(H43>59,0,(CB43*138.92%)) -> 316777.94 | CJ43: =-MIN(CI43,$CC$12)*$CD$15 -> -9503.3383 | CK43: =-IF(E43="FOTIA",(CI43-BE43)*1%,(CI43-BE43)*1.5%) -> -3167.7794 | CL43: 0 | CN43: 0 | CZ43: =-SUM(CB43+CC43+CD43+CE43+CF43)*I43 -> 0 | DA43: =-SUM(CB43+CC43+CD43+CE43+CF43+CI43+CJ43+CK43)*J43 -> 0 | DB43: =SUM(CB43:DA43) -> 523014.7 | DC43: =ROUND(DB43,0) -> 523015 | DE43: =+DD43-DC43 -> -523015
A44: =500000+B44 -> 509669 | B44: 9669 | C44: CAMPO | D44: DIAZ ENRIQUE ANTONIO | E44: FEIA | F44: 0 | K44: Q04 | O44: 15 | P44: =+VLOOKUP(K44,$W$4:$AC$11,5,0) -> 5700.726 | Q44: =+VLOOKUP(K44,$W$4:$Z$11,2,0) -> 19002.42 | R44: =+VLOOKUP(K44,$W$4:$Y$11,3,0) -> 26397.964 | T44: 0 | U44: =+T44 -> 0 | V44: 0 | W44: 0 | X44: 0 | Y44: 0 | Z44: 0 | AA44: 0 | AB44: 0 | AC44: 0 | AD44: 0 | AE44: 0 | AF44: 0 | AG44: 0 | AH44: 0 | AI44: 0 | AJ44: 0 | AK44: 0 | AL44: 0 | AM44: 0 | AN44: 0 | AO44: 0 | AP44: 0 | AQ44: 0 | AR44: 0 | AS44: 0 | AT44: 0 | AU44: =+U44+V44+W44+Y44-Z44-AB44-AC44-AD44-AE44+AF44-AG44+AJ44 -> 0 | AV44: =+Q44*U44 -> 0 | AW44: =+Q44*V44 -> 0 | AX44: =+Q44*W44 -> 0 | AY44: =+Q44*X44 -> 0 | AZ44: =+(Q44*1.0833*Y44)+((P44*O44)/25*Y44) -> 0 | BA44: =-Q44/8*Z44 -> 0 | BB44: =+Q44/8*AA44 -> 0 | BC44: =-Q44*AB44 -> 0 | BD44: =-Q44*AC44 -> 0 | BE44: =-Q44/8*AD44 -> 0 | BF44: =-Q44*AE44 -> 0 | BG44: =+Q44*AF44 -> 0 | BH44: =-Q44*AG44 -> 0 | BI44: =+Q44*AI44 -> 0 | BJ44: =+Q44*AH44 -> 0 | BK44: =+Q44*AJ44 -> 0 | BL44: =+(P44*O44)/25*(U44+V44+W44-Z44-AB44-AC44-AD44-AE44+AF44-AG44) -> 0 | BM44: =+$BM$15/25*(U44+V44+Y44+AF44+AH44+AI44)*0 -> 0 | BP44: =+M44*(AU44+AH44+AI44) -> 0 | BS44: =+$BS$15*AM44 -> 0 | BT44: =+$BT$15*AN44 -> 0 | BU44: =+$BU$15*AO44 -> 0 | BV44: =+$BV$15*AP44 -> 0 | CA44: =+IF(H44>59,+SUM(AV44:BX44)*138.92%,0) -> 0 | CB44: =SUM(AV44:CA44) -> 0 | CE44: =-MIN(CB44,$CC$12)*$CD$15 -> 0 | CF44: =-IF(E44="FOTIA",(CB44-AZ44)*1%,(CB44-AZ44)*1.5%) -> 0 | CI44: =+IF(H44>59,0,(CB44*138.92%)) -> 0 | CJ44: =-MIN(CI44,$CC$12)*$CD$15 -> 0 | CK44: =-IF(E44="FOTIA",(CI44-BE44)*1%,(CI44-BE44)*1.5%) -> 0 | CL44: 0 | CN44: 0 | CZ44: =-SUM(CB44+CC44+CD44+CE44+CF44)*I44 -> 0 | DA44: =-SUM(CB44+CC44+CD44+CE44+CF44+CI44+CJ44+CK44)*J44 -> 0 | DB44: =SUM(CB44:DA44) -> 0 | DC44: =ROUND(DB44,0) -> 0 | DE44: =+DD44-DC44 -> 0
...

Sheet 1°Q 01 V2 CAMPO
W2: Cat. | X2: Basico | Y2: No Rem | Z2: Basico Conf. | AA2: Escalafon | AB2: escalafon NR | AC2: Escalafon Conf.
Q4: =+X4 -> 17212.41 | R4: =+Q4*155% -> 26679.235 | T4: =+R4+S4 -> 26679.235 | U4: =+U114 -> 0 | V4: =+Y4/X4*100 -> 138.91891 | W4: Q01 | X4: 17212.41 | Y4: =+Z4-X4 -> 23911.292 | Z4: 41123.702 | AA4: =+X4*0.3 -> 5163.723 | AB4: =+Y4*0.3 -> 7173.3876 | AC4: =+AA4+AB4 -> 12337.111
U5: =+Q4*218.75% -> 37652.147 | W5: Q02 | X5: 18004.12 | Y5: =+Z5-X5 -> 25011.121 | Z5: 43015.241 | AA5: =+X5*0.3 -> 5401.236 | AB5: =+Y5*0.3 -> 7503.3363 | AC5: =+AA5+AB5 -> 12904.572
Q6: =+Q4+R4 -> 43891.645 | R6: =+T4+Q4 -> 43891.645 | W6: Q03 | X6: 18329.51 | Y6: =+Z6-X6 -> 25463.165 | Z6: 43792.675 | AA6: =+X6*0.3 -> 5498.853 | AB6: =+Y6*0.3 -> 7638.9495 | AC6: =+AA6+AB6 -> 13137.802
R7: =+R6/Q6 -> 1 | W7: Q04 | X7: 19002.42 | Y7: =+Z7-X7 -> 26397.964 | Z7: 45400.384 | AA7: =+X7*0.3 -> 5700.726 | AB7: =+Y7*0.3 -> 7919.3891 | AC7: =+AA7+AB7 -> 13620.115
W8: Q05 | X8: 19415.57 | Y8: =+Z8-X8 -> 26971.888 | Z8: 46387.458 | AA8: =+X8*0.3 -> 5824.671 | AB8: =+Y8*0.3 -> 8091.5664 | AC8: =+AA8+AB8 -> 13916.237
W9: Q06 | X9: 20104.08 | Y9: =+Z9-X9 -> 27928.38 | Z9: 48032.46 | AA9: =+X9*0.3 -> 6031.224 | AB9: =+Y9*0.3 -> 8378.5141 | AC9: =+AA9+AB9 -> 14409.738
W10: Q07 | X10: 20964.69 | Y10: =+Z10-X10 -> 29123.932 | Z10: 50088.622 | AA10: =+X10*0.3 -> 6289.407 | AB10: =+Y10*0.3 -> 8737.1797 | AC10: =+AA10+AB10 -> 15026.587
W11: Q08 | X11: 21549.89 | Y11: =+Z11-X11 -> 29936.867 | Z11: 51486.757 | AA11: =+X11*0.3 -> 6464.967 | AB11: =+Y11*0.3 -> 8981.06 | AC11: =+AA11+AB11 -> 15446.027 | CC11: TOPE
A12: La Corona | CC12: =3645898/2 -> 1822949
X14: =+Y4/X4 -> 1.3891891 | BM14: 24365.48 | BS14: 1022 | BT14: 1023 | BU14: 1025 | BV14: 1026 | CL14: REINTMED | CO14: AYUMED
K15: LIQ | N15: 46037 | T15: 1003 | V15: 1061 | W15: 1009 | Y15: 1030 | Z15: 1072 | AB15: 1065 | AC15: 1066 | AD15: 1073 | AE15: 1304 | AH15: 1041 | AI15: 1007 | AK15: 1018 | AL15: 1019 | AM15: 1022 | AN15: 1023 | AO15: 1025 | AP15: 1026 | AQ15: 1108 | AR15: 1109 | AS15: 1110 | AT15: 1201 | AV15: 30 | AX15: 30 | AY15: 30 | AZ15: 0.01 | BF15: 1.5 | BG15: 2 | BM15: 19290.416 | BS15: 67.134 | BT15: 52.674 | BU15: 1.6226 | BV15: 2.5053 | BW15: 3.1374 | CC15: 0.11 | CD15: 0.03 | CE15: 0.03 | CG15: 0.03 | CL15: 1201 | CM15: 1220 | CN15: 2803 | CP15: 2895 | CQ15: 2896
